Workbook

Sheet Monthly
A1: التقرير الشهري - يختار المستخدم الشهر
A3: الشهر | B3: يناير
A4: عدد الأنشطة | B4: =COUNTIF(Plan!D:D,B3) -> 2
A5: المنفذ | B5: =COUNTIFS(Plan!D:D,B3,Plan!M:M,"منفذ") -> 0
A6: نسبة التنفيذ | B6: =IFERROR(B5/B4,0) -> 0
A7: عدد الحضور | B7: =SUMPRODUCT(--(TEXT(Attendance!D4:D1003,"mmmm")=B3),--(Attendance!H4:H1003="نعم")) -> 0
A8: الإجراءات المفتوحة | B8: =COUNTIF(Needs!K:K,"مفتوح") -> 3

Sheet Dashboard
A1: لوحة مؤشرات الإدارة والجودة
A3: المؤشر | B3: القيمة | C3: المستهدف | D3: الحالة | E3: مصدر البيانات
A4: الموظفون النشطون | B4: =COUNTIF(Employees!G:G,"نشط") -> 3 | C4: كل الموظفين | D4: =IF(B4="","",IF(ISNUMBER(B4),IF(OR(4="0 أو خطة تصحيح",B4>=0),"راجع المؤشر","راجع المؤشر"),"")) -> راجع المؤشر | E4: Employees
A5: الأنشطة المخططة | B5: =COUNTIF(Plan!A:A,"TR-*") -> 13 | C5: حسب الخطة | D5: =IF(B5="","",IF(ISNUMBER(B5),IF(OR(5="0 أو خطة تصحيح",B5>=0),"راجع المؤشر","راجع المؤشر"),"")) -> راجع المؤشر | E5: Plan
A6: الأنشطة المنفذة | B6: =COUNTIF(Plan!M:M,"منفذ") -> 0 | C6: 100% من المستحق | D6: =IF(B6="","",IF(ISNUMBER(B6),IF(OR(6="0 أو خطة تصحيح",B6>=0),"راجع المؤشر","راجع المؤشر"),"")) -> راجع المؤشر | E6: Plan
A7: نسبة تنفيذ الخطة | B7: =IFERROR(B7/B6,0) -> 0 | C7: >=90% | D7: =IF(B7="","",IF(ISNUMBER(B7),IF(OR(7="0 أو خطة تصحيح",B7>=0),"راجع المؤشر","راجع المؤشر"),"")) -> 0 | E7: Plan
A8: سجلات الحضور | B8: =COUNTIF(Attendance!E:E,"EMP-*") -> 0 | C8: حسب الجلسات | D8: =IF(B8="","",IF(ISNUMBER(B8),IF(OR(8="0 أو خطة تصحيح",B8>=0),"راجع المؤشر","راجع المؤشر"),"")) -> راجع المؤشر | E8: Attendance
A9: نسبة الحضور | B9: =IFERROR(COUNTIF(Attendance!H:H,"نعم")/B8,0) -> 0 | C9: >=80% | D9: =IF(B9="","",IF(ISNUMBER(B9),IF(OR(9="0 أو خطة تصحيح",B9>=0),"راجع المؤشر","راجع المؤشر"),"")) -> راجع المؤشر | E9: Attendance
A10: متوسط التقييم البعدي | B10: =IFERROR(AVERAGE(Evaluation!H:H),0) -> 0 | C10: >=70% | D10: =IF(B10="","",IF(ISNUMBER(B10),IF(OR(10="0 أو خطة تصحيح",B10>=0),"راجع المؤشر","راجع المؤشر"),"")) -> راجع المؤشر | E10: Evaluation
A11: حالات إعادة التدريب | B11: =COUNTIF(Evaluation!I:I,"إعادة تدريب") -> 0 | C11: 0 أو خطة تصحيح | D11: =IF(B11="","",IF(ISNUMBER(B11),IF(OR(11="0 أو خطة تصحيح",B11>=0),"راجع المؤشر","راجع المؤشر"),"")) -> راجع المؤشر | E11: Evaluation
A12: أدلة مكتملة | B12: =COUNTIF(Evidence!H:H,"مكتمل") -> 0 | C12: 100% للأنشطة المنفذة | D12: =IF(B12="","",IF(ISNUMBER(B12),IF(OR(12="0 أو خطة تصحيح",B12>=0),"راجع المؤشر","راجع المؤشر"),"")) -> راجع المؤشر | E12: Evidence
A13: كفاءات غير مكتملة | B13: =COUNTIF(Competency!I:I,"غير كفء - إعادة تدريب") -> 0 | C13: 0 أو خطة تصحيح | D13: =IF(B13="","",IF(ISNUMBER(B13),IF(OR(13="0 أو خطة تصحيح",B13>=0),"راجع المؤشر","راجع المؤشر"),"")) -> راجع المؤشر | E13: Competency

Sheet Evidence
A1: سجل الأدلة - اربط كل نشاط بملف يمكن عرضه أثناء المراجعة
A3: كود الدليل | B3: كود النشاط | C3: كود الجلسة | D3: نوع الدليل | E3: اسم الملف/الرابط | F3: المسؤول | G3: تاريخ الحفظ | H3: الحالة | I3: مراجع الجودة | J3: ملاحظات
A4: EVD-001 | B4: TR-001 | C4: SES-001 | D4: مادة تدريب | F4: مسؤول التدريب | G4: 15/01/2026 | H4: مطلوب
A5: EVD-002 | B5: TR-001 | C5: SES-001 | D5: كشف حضور | F5: مسؤول التدريب | G5: 15/01/2026 | H5: مطلوب
A6: EVD-003 | B6: TR-001 | C6: SES-001 | D6: نتائج تقييم وخطة تحسين | F6: مسؤول التدريب | G6: 15/01/2026 | H6: مطلوب

Sheet Competency
A1: مصفوفة الكفاءة - القرار النهائي لكل موظف
A3: كود الموظف | B3: اسم الموظف | C3: القسم | D3: الكفاءة/المهارة | E3: النشاط المرجعي | F3: درجة الكفاءة % | G3: تاريخ التقييم | H3: المقيم | I3: الحالة | J3: موعد إعادة التقييم | K3: إجراء تصحيحي | L3: رابط الدليل
A4: EMP-001 | B4: =IFERROR(VLOOKUP(A4,Employees!A:L,2,FALSE),"") -> يُستكمل | C4: =IFERROR(VLOOKUP(A4,Employees!A:L,3,FALSE),"") -> التمريض | D4: نظافة اليدين | E4: TR-003 | I4: =IF(F4="","لم يقيم",IF(F4>=Setup!B7,"كفء","غير كفء - إعادة تدريب")) -> لم يقيم
A5: EMP-002 | B5: =IFERROR(VLOOKUP(A5,Employees!A:L,2,FALSE),"") -> يُستكمل | C5: =IFERROR(VLOOKUP(A5,Employees!A:L,3,FALSE),"") -> الصيدلية | D5: سلامة الدواء | E5: TR-004 | I5: =IF(F5="","لم يقيم",IF(F5>=Setup!B7,"كفء","غير كفء - إعادة تدريب")) -> لم يقيم
A6: EMP-003 | B6: =IFERROR(VLOOKUP(A6,Employees!A:L,2,FALSE),"") -> يُستكمل | C6: =IFERROR(VLOOKUP(A6,Employees!A:L,3,FALSE),"") -> الاستقبال | D6: حقوق المريض والشكاوى | E6: TR-008 | I6: =IF(F6="","لم يقيم",IF(F6>=Setup!B7,"كفء","غير كفء - إعادة تدريب")) -> لم يقيم
B7: =IFERROR(VLOOKUP(A7,Employees!A:L,2,FALSE),"") | C7: =IFERROR(VLOOKUP(A7,Employees!A:L,3,FALSE),"") | I7: =IF(F7="","لم يقيم",IF(F7>=Setup!B7,"كفء","غير كفء - إعادة تدريب")) -> لم يقيم
B8: =IFERROR(VLOOKUP(A8,Employees!A:L,2,FALSE),"") | C8: =IFERROR(VLOOKUP(A8,Employees!A:L,3,FALSE),"") | I8: =IF(F8="","لم يقيم",IF(F8>=Setup!B7,"كفء","غير كفء - إعادة تدريب")) -> لم يقيم
B9: =IFERROR(VLOOKUP(A9,Employees!A:L,2,FALSE),"") | C9: =IFERROR(VLOOKUP(A9,Employees!A:L,3,FALSE),"") | I9: =IF(F9="","لم يقيم",IF(F9>=Setup!B7,"كفء","غير كفء - إعادة تدريب")) -> لم يقيم
B10: =IFERROR(VLOOKUP(A10,Employees!A:L,2,FALSE),"") | C10: =IFERROR(VLOOKUP(A10,Employees!A:L,3,FALSE),"") | I10: =IF(F10="","لم يقيم",IF(F10>=Setup!B7,"كفء","غير كفء - إعادة تدريب")) -> لم يقيم
B11: =IFERROR(VLOOKUP(A11,Employees!A:L,2,FALSE),"") | C11: =IFERROR(VLOOKUP(A11,Employees!A:L,3,FALSE),"") | I11: =IF(F11="","لم يقيم",IF(F11>=Setup!B7,"كفء","غير كفء - إعادة تدريب")) -> لم يقيم
B12: =IFERROR(VLOOKUP(A12,Employees!A:L,2,FALSE),"") | C12: =IFERROR(VLOOKUP(A12,Employees!A:L,3,FALSE),"") | I12: =IF(F12="","لم يقيم",IF(F12>=Setup!B7,"كفء","غير كفء - إعادة تدريب")) -> لم يقيم
B13: =IFERROR(VLOOKUP(A13,Employees!A:L,2,FALSE),"") | C13: =IFERROR(VLOOKUP(A13,Employees!A:L,3,FALSE),"") | I13: =IF(F13="","لم يقيم",IF(F13>=Setup!B7,"كفء","غير كفء - إعادة تدريب")) -> لم يقيم
B14: =IFERROR(VLOOKUP(A14,Employees!A:L,2,FALSE),"") | C14: =IFERROR(VLOOKUP(A14,Employees!A:L,3,FALSE),"") | I14: =IF(F14="","لم يقيم",IF(F14>=Setup!B7,"كفء","غير كفء - إعادة تدريب")) -> لم يقيم
B15: =IFERROR(VLOOKUP(A15,Employees!A:L,2,FALSE),"") | C15: =IFERROR(VLOOKUP(A15,Employees!A:L,3,FALSE),"") | I15: =IF(F15="","لم يقيم",IF(F15>=Setup!B7,"كفء","غير كفء - إعادة تدريب")) -> لم يقيم
B16: =IFERROR(VLOOKUP(A16,Employees!A:L,2,FALSE),"") | C16: =IFERROR(VLOOKUP(A16,Employees!A:L,3,FALSE),"") | I16: =IF(F16="","لم يقيم",IF(F16>=Setup!B7,"كفء","غير كفء - إعادة تدريب")) -> لم يقيم
B17: =IFERROR(VLOOKUP(A17,Employees!A:L,2,FALSE),"") | C17: =IFERROR(VLOOKUP(A17,Employees!A:L,3,FALSE),"") | I17: =IF(F17="","لم يقيم",IF(F17>=Setup!B7,"كفء","غير كفء - إعادة تدريب")) -> لم يقيم
B18: =IFERROR(VLOOKUP(A18,Employees!A:L,2,FALSE),"") | C18: =IFERROR(VLOOKUP(A18,Employees!A:L,3,FALSE),"") | I18: =IF(F18="","لم يقيم",IF(F18>=Setup!B7,"كفء","غير كفء - إعادة تدريب")) -> لم يقيم
B19: =IFERROR(VLOOKUP(A19,Employees!A:L,2,FALSE),"") | C19: =IFERROR(VLOOKUP(A19,Employees!A:L,3,FALSE),"") | I19: =IF(F19="","لم يقيم",IF(F19>=Setup!B7,"كفء","غير كفء - إعادة تدريب")) -> لم يقيم
B20: =IFERROR(VLOOKUP(A20,Employees!A:L,2,FALSE),"") | C20: =IFERROR(VLOOKUP(A20,Employees!A:L,3,FALSE),"") | I20: =IF(F20="","لم يقيم",IF(F20>=Setup!B7,"كفء","غير كفء - إعادة تدريب")) -> لم يقيم
B21: =IFERROR(VLOOKUP(A21,Employees!A:L,2,FALSE),"") | C21: =IFERROR(VLOOKUP(A21,Employees!A:L,3,FALSE),"") | I21: =IF(F21="","لم يقيم",IF(F21>=Setup!B7,"كفء","غير كفء - إعادة تدريب")) -> لم يقيم
B22: =IFERROR(VLOOKUP(A22,Employees!A:L,2,FALSE),"") | C22: =IFERROR(VLOOKUP(A22,Employees!A:L,3,FALSE),"") | I22: =IF(F22="","لم يقيم",IF(F22>=Setup!B7,"كفء","غير كفء - إعادة تدريب")) -> لم يقيم
B23: =IFERROR(VLOOKUP(A23,Employees!A:L,2,FALSE),"") | C23: =IFERROR(VLOOKUP(A23,Employees!A:L,3,FALSE),"") | I23: =IF(F23="","لم يقيم",IF(F23>=Setup!B7,"كفء","غير كفء - إعادة تدريب")) -> لم يقيم
B24: =IFERROR(VLOOKUP(A24,Employees!A:L,2,FALSE),"") | C24: =IFERROR(VLOOKUP(A24,Employees!A:L,3,FALSE),"") | I24: =IF(F24="","لم يقيم",IF(F24>=Setup!B7,"كفء","غير كفء - إعادة تدريب")) -> لم يقيم
B25: =IFERROR(VLOOKUP(A25,Employees!A:L,2,FALSE),"") | C25: =IFERROR(VLOOKUP(A25,Employees!A:L,3,FALSE),"") | I25: =IF(F25="","لم يقيم",IF(F25>=Setup!B7,"كفء","غير كفء - إعادة تدريب")) -> لم يقيم
B26: =IFERROR(VLOOKUP(A26,Employees!A:L,2,FALSE),"") | C26: =IFERROR(VLOOKUP(A26,Employees!A:L,3,FALSE),"") | I26: =IF(F26="","لم يقيم",IF(F26>=Setup!B7,"كفء","غير كفء - إعادة تدريب")) -> لم يقيم
B27: =IFERROR(VLOOKUP(A27,Employees!A:L,2,FALSE),"") | C27: =IFERROR(VLOOKUP(A27,Employees!A:L,3,FALSE),"") | I27: =IF(F27="","لم يقيم",IF(F27>=Setup!B7,"كفء","غير كفء - إعادة تدريب")) -> لم يقيم
B28: =IFERROR(VLOOKUP(A28,Employees!A:L,2,FALSE),"") | C28: =IFERROR(VLOOKUP(A28,Employees!A:L,3,FALSE),"") | I28: =IF(F28="","لم يقيم",IF(F28>=Setup!B7,"كفء","غير كفء - إعادة تدريب")) -> لم يقيم
B29: =IFERROR(VLOOKUP(A29,Employees!A:L,2,FALSE),"") | C29: =IFERROR(VLOOKUP(A29,Employees!A:L,3,FALSE),"") | I29: =IF(F29="","لم يقيم",IF(F29>=Setup!B7,"كفء","غير كفء - إعادة تدريب")) -> لم يقيم
B30: =IFERROR(VLOOKUP(A30,Employees!A:L,2,FALSE),"") | C30: =IFERROR(VLOOKUP(A30,Employees!A:L,3,FALSE),"") | I30: =IF(F30="","لم يقيم",IF(F30>=Setup!B7,"كفء","غير كفء - إعادة تدريب")) -> لم يقيم
B31: =IFERROR(VLOOKUP(A31,Employees!A:L,2,FALSE),"") | C31: =IFERROR(VLOOKUP(A31,Employees!A:L,3,FALSE),"") | I31: =IF(F31="","لم يقيم",IF(F31>=Setup!B7,"كفء","غير كفء - إعادة تدريب")) -> لم يقيم
B32: =IFERROR(VLOOKUP(A32,Employees!A:L,2,FALSE),"") | C32: =IFERROR(VLOOKUP(A32,Employees!A:L,3,FALSE),"") | I32: =IF(F32="","لم يقيم",IF(F32>=Setup!B7,"كفء","غير كفء - إعادة تدريب")) -> لم يقيم
B33: =IFERROR(VLOOKUP(A33,Employees!A:L,2,FALSE),"") | C33: =IFERROR(VLOOKUP(A33,Employees!A:L,3,FALSE),"") | I33: =IF(F33="","لم يقيم",IF(F33>=Setup!B7,"كفء","غير كفء - إعادة تدريب")) -> لم يقيم
B34: =IFERROR(VLOOKUP(A34,Employees!A:L,2,FALSE),"") | C34: =IFERROR(VLOOKUP(A34,Employees!A:L,3,FALSE),"") | I34: =IF(F34="","لم يقيم",IF(F34>=Setup!B7,"كفء","غير كفء - إعادة تدريب")) -> لم يقيم
B35: =IFERROR(VLOOKUP(A35,Employees!A:L,2,FALSE),"") | C35: =IFERROR(VLOOKUP(A35,Employees!A:L,3,FALSE),"") | I35: =IF(F35="","لم يقيم",IF(F35>=Setup!B7,"كفء","غير كفء - إعادة تدريب")) -> لم يقيم
B36: =IFERROR(VLOOKUP(A36,Employees!A:L,2,FALSE),"") | C36: =IFERROR(VLOOKUP(A36,Employees!A:L,3,FALSE),"") | I36: =IF(F36="","لم يقيم",IF(F36>=Setup!B7,"كفء","غير كفء - إعادة تدريب")) -> لم يقيم
B37: =IFERROR(VLOOKUP(A37,Employees!A:L,2,FALSE),"") | C37: =IFERROR(VLOOKUP(A37,Employees!A:L,3,FALSE),"") | I37: =IF(F37="","لم يقيم",IF(F37>=Setup!B7,"كفء","غير كفء - إعادة تدريب")) -> لم يقيم
B38: =IFERROR(VLOOKUP(A38,Employees!A:L,2,FALSE),"") | C38: =IFERROR(VLOOKUP(A38,Employees!A:L,3,FALSE),"") | I38: =IF(F38="","لم يقيم",IF(F38>=Setup!B7,"كفء","غير كفء - إعادة تدريب")) -> لم يقيم
B39: =IFERROR(VLOOKUP(A39,Employees!A:L,2,FALSE),"") | C39: =IFERROR(VLOOKUP(A39,Employees!A:L,3,FALSE),"") | I39: =IF(F39="","لم يقيم",IF(F39>=Setup!B7,"كفء","غير كفء - إعادة تدريب")) -> لم يقيم
B40: =IFERROR(VLOOKUP(A40,Employees!A:L,2,FALSE),"") | C40: =IFERROR(VLOOKUP(A40,Employees!A:L,3,FALSE),"") | I40: =IF(F40="","لم يقيم",IF(F40>=Setup!B7,"كفء","غير كفء - إعادة تدريب")) -> لم يقيم
B41: =IFERROR(VLOOKUP(A41,Employees!A:L,2,FALSE),"") | C41: =IFERROR(VLOOKUP(A41,Employees!A:L,3,FALSE),"") | I41: =IF(F41="","لم يقيم",IF(F41>=Setup!B7,"كفء","غير كفء - إعادة تدريب")) -> لم يقيم
...

Sheet Evaluation
A1: التقييم - أدخل الدرجات وتظهر النتيجة تلقائيًا
A3: رقم | B3: كود الجلسة | C3: كود النشاط | D3: كود الموظف | E3: اسم الموظف | F3: قبلي % | G3: بعدي % | H3: الدرجة المعتمدة | I3: النتيجة | J3: مقيم الكفاءة | K3: تاريخ التقييم | L3: إجراء التحسين | M3: رابط نموذج التقييم
A4: 1 | C4: =IFERROR(VLOOKUP(B4,Sessions!A:J,2,FALSE),"") | E4: =IFERROR(VLOOKUP(D4,Employees!A:L,2,FALSE),"") | H4: =IF(G4="","",G4) | I4: =IF(H4="","",IF(H4>=Setup!B7,"ناجح","إعادة تدريب"))
A5: 2 | C5: =IFERROR(VLOOKUP(B5,Sessions!A:J,2,FALSE),"") | E5: =IFERROR(VLOOKUP(D5,Employees!A:L,2,FALSE),"") | H5: =IF(G5="","",G5) | I5: =IF(H5="","",IF(H5>=Setup!B7,"ناجح","إعادة تدريب"))
A6: 3 | C6: =IFERROR(VLOOKUP(B6,Sessions!A:J,2,FALSE),"") | E6: =IFERROR(VLOOKUP(D6,Employees!A:L,2,FALSE),"") | H6: =IF(G6="","",G6) | I6: =IF(H6="","",IF(H6>=Setup!B7,"ناجح","إعادة تدريب"))
A7: 4 | C7: =IFERROR(VLOOKUP(B7,Sessions!A:J,2,FALSE),"") | E7: =IFERROR(VLOOKUP(D7,Employees!A:L,2,FALSE),"") | H7: =IF(G7="","",G7) | I7: =IF(H7="","",IF(H7>=Setup!B7,"ناجح","إعادة تدريب"))
A8: 5 | C8: =IFERROR(VLOOKUP(B8,Sessions!A:J,2,FALSE),"") | E8: =IFERROR(VLOOKUP(D8,Employees!A:L,2,FALSE),"") | H8: =IF(G8="","",G8) | I8: =IF(H8="","",IF(H8>=Setup!B7,"ناجح","إعادة تدريب"))
A9: 6 | C9: =IFERROR(VLOOKUP(B9,Sessions!A:J,2,FALSE),"") | E9: =IFERROR(VLOOKUP(D9,Employees!A:L,2,FALSE),"") | H9: =IF(G9="","",G9) | I9: =IF(H9="","",IF(H9>=Setup!B7,"ناجح","إعادة تدريب"))
A10: 7 | C10: =IFERROR(VLOOKUP(B10,Sessions!A:J,2,FALSE),"") | E10: =IFERROR(VLOOKUP(D10,Employees!A:L,2,FALSE),"") | H10: =IF(G10="","",G10) | I10: =IF(H10="","",IF(H10>=Setup!B7,"ناجح","إعادة تدريب"))
A11: 8 | C11: =IFERROR(VLOOKUP(B11,Sessions!A:J,2,FALSE),"") | E11: =IFERROR(VLOOKUP(D11,Employees!A:L,2,FALSE),"") | H11: =IF(G11="","",G11) | I11: =IF(H11="","",IF(H11>=Setup!B7,"ناجح","إعادة تدريب"))
A12: 9 | C12: =IFERROR(VLOOKUP(B12,Sessions!A:J,2,FALSE),"") | E12: =IFERROR(VLOOKUP(D12,Employees!A:L,2,FALSE),"") | H12: =IF(G12="","",G12) | I12: =IF(H12="","",IF(H12>=Setup!B7,"ناجح","إعادة تدريب"))
A13: 10 | C13: =IFERROR(VLOOKUP(B13,Sessions!A:J,2,FALSE),"") | E13: =IFERROR(VLOOKUP(D13,Employees!A:L,2,FALSE),"") | H13: =IF(G13="","",G13) | I13: =IF(H13="","",IF(H13>=Setup!B7,"ناجح","إعادة تدريب"))
A14: 11 | C14: =IFERROR(VLOOKUP(B14,Sessions!A:J,2,FALSE),"") | E14: =IFERROR(VLOOKUP(D14,Employees!A:L,2,FALSE),"") | H14: =IF(G14="","",G14) | I14: =IF(H14="","",IF(H14>=Setup!B7,"ناجح","إعادة تدريب"))
A15: 12 | C15: =IFERROR(VLOOKUP(B15,Sessions!A:J,2,FALSE),"") | E15: =IFERROR(VLOOKUP(D15,Employees!A:L,2,FALSE),"") | H15: =IF(G15="","",G15) | I15: =IF(H15="","",IF(H15>=Setup!B7,"ناجح","إعادة تدريب"))
A16: 13 | C16: =IFERROR(VLOOKUP(B16,Sessions!A:J,2,FALSE),"") | E16: =IFERROR(VLOOKUP(D16,Employees!A:L,2,FALSE),"") | H16: =IF(G16="","",G16) | I16: =IF(H16="","",IF(H16>=Setup!B7,"ناجح","إعادة تدريب"))
A17: 14 | C17: =IFERROR(VLOOKUP(B17,Sessions!A:J,2,FALSE),"") | E17: =IFERROR(VLOOKUP(D17,Employees!A:L,2,FALSE),"") | H17: =IF(G17="","",G17) | I17: =IF(H17="","",IF(H17>=Setup!B7,"ناجح","إعادة تدريب"))
A18: 15 | C18: =IFERROR(VLOOKUP(B18,Sessions!A:J,2,FALSE),"") | E18: =IFERROR(VLOOKUP(D18,Employees!A:L,2,FALSE),"") | H18: =IF(G18="","",G18) | I18: =IF(H18="","",IF(H18>=Setup!B7,"ناجح","إعادة تدريب"))
A19: 16 | C19: =IFERROR(VLOOKUP(B19,Sessions!A:J,2,FALSE),"") | E19: =IFERROR(VLOOKUP(D19,Employees!A:L,2,FALSE),"") | H19: =IF(G19="","",G19) | I19: =IF(H19="","",IF(H19>=Setup!B7,"ناجح","إعادة تدريب"))
A20: 17 | C20: =IFERROR(VLOOKUP(B20,Sessions!A:J,2,FALSE),"") | E20: =IFERROR(VLOOKUP(D20,Employees!A:L,2,FALSE),"") | H20: =IF(G20="","",G20) | I20: =IF(H20="","",IF(H20>=Setup!B7,"ناجح","إعادة تدريب"))
A21: 18 | C21: =IFERROR(VLOOKUP(B21,Sessions!A:J,2,FALSE),"") | E21: =IFERROR(VLOOKUP(D21,Employees!A:L,2,FALSE),"") | H21: =IF(G21="","",G21) | I21: =IF(H21="","",IF(H21>=Setup!B7,"ناجح","إعادة تدريب"))
A22: 19 | C22: =IFERROR(VLOOKUP(B22,Sessions!A:J,2,FALSE),"") | E22: =IFERROR(VLOOKUP(D22,Employees!A:L,2,FALSE),"") | H22: =IF(G22="","",G22) | I22: =IF(H22="","",IF(H22>=Setup!B7,"ناجح","إعادة تدريب"))
A23: 20 | C23: =IFERROR(VLOOKUP(B23,Sessions!A:J,2,FALSE),"") | E23: =IFERROR(VLOOKUP(D23,Employees!A:L,2,FALSE),"") | H23: =IF(G23="","",G23) | I23: =IF(H23="","",IF(H23>=Setup!B7,"ناجح","إعادة تدريب"))
A24: 21 | C24: =IFERROR(VLOOKUP(B24,Sessions!A:J,2,FALSE),"") | E24: =IFERROR(VLOOKUP(D24,Employees!A:L,2,FALSE),"") | H24: =IF(G24="","",G24) | I24: =IF(H24="","",IF(H24>=Setup!B7,"ناجح","إعادة تدريب"))
A25: 22 | C25: =IFERROR(VLOOKUP(B25,Sessions!A:J,2,FALSE),"") | E25: =IFERROR(VLOOKUP(D25,Employees!A:L,2,FALSE),"") | H25: =IF(G25="","",G25) | I25: =IF(H25="","",IF(H25>=Setup!B7,"ناجح","إعادة تدريب"))
A26: 23 | C26: =IFERROR(VLOOKUP(B26,Sessions!A:J,2,FALSE),"") | E26: =IFERROR(VLOOKUP(D26,Employees!A:L,2,FALSE),"") | H26: =IF(G26="","",G26) | I26: =IF(H26="","",IF(H26>=Setup!B7,"ناجح","إعادة تدريب"))
A27: 24 | C27: =IFERROR(VLOOKUP(B27,Sessions!A:J,2,FALSE),"") | E27: =IFERROR(VLOOKUP(D27,Employees!A:L,2,FALSE),"") | H27: =IF(G27="","",G27) | I27: =IF(H27="","",IF(H27>=Setup!B7,"ناجح","إعادة تدريب"))
A28: 25 | C28: =IFERROR(VLOOKUP(B28,Sessions!A:J,2,FALSE),"") | E28: =IFERROR(VLOOKUP(D28,Employees!A:L,2,FALSE),"") | H28: =IF(G28="","",G28) | I28: =IF(H28="","",IF(H28>=Setup!B7,"ناجح","إعادة تدريب"))
A29: 26 | C29: =IFERROR(VLOOKUP(B29,Sessions!A:J,2,FALSE),"") | E29: =IFERROR(VLOOKUP(D29,Employees!A:L,2,FALSE),"") | H29: =IF(G29="","",G29) | I29: =IF(H29="","",IF(H29>=Setup!B7,"ناجح","إعادة تدريب"))
A30: 27 | C30: =IFERROR(VLOOKUP(B30,Sessions!A:J,2,FALSE),"") | E30: =IFERROR(VLOOKUP(D30,Employees!A:L,2,FALSE),"") | H30: =IF(G30="","",G30) | I30: =IF(H30="","",IF(H30>=Setup!B7,"ناجح","إعادة تدريب"))
A31: 28 | C31: =IFERROR(VLOOKUP(B31,Sessions!A:J,2,FALSE),"") | E31: =IFERROR(VLOOKUP(D31,Employees!A:L,2,FALSE),"") | H31: =IF(G31="","",G31) | I31: =IF(H31="","",IF(H31>=Setup!B7,"ناجح","إعادة تدريب"))
A32: 29 | C32: =IFERROR(VLOOKUP(B32,Sessions!A:J,2,FALSE),"") | E32: =IFERROR(VLOOKUP(D32,Employees!A:L,2,FALSE),"") | H32: =IF(G32="","",G32) | I32: =IF(H32="","",IF(H32>=Setup!B7,"ناجح","إعادة تدريب"))
A33: 30 | C33: =IFERROR(VLOOKUP(B33,Sessions!A:J,2,FALSE),"") | E33: =IFERROR(VLOOKUP(D33,Employees!A:L,2,FALSE),"") | H33: =IF(G33="","",G33) | I33: =IF(H33="","",IF(H33>=Setup!B7,"ناجح","إعادة تدريب"))
A34: 31 | C34: =IFERROR(VLOOKUP(B34,Sessions!A:J,2,FALSE),"") | E34: =IFERROR(VLOOKUP(D34,Employees!A:L,2,FALSE),"") | H34: =IF(G34="","",G34) | I34: =IF(H34="","",IF(H34>=Setup!B7,"ناجح","إعادة تدريب"))
A35: 32 | C35: =IFERROR(VLOOKUP(B35,Sessions!A:J,2,FALSE),"") | E35: =IFERROR(VLOOKUP(D35,Employees!A:L,2,FALSE),"") | H35: =IF(G35="","",G35) | I35: =IF(H35="","",IF(H35>=Setup!B7,"ناجح","إعادة تدريب"))
A36: 33 | C36: =IFERROR(VLOOKUP(B36,Sessions!A:J,2,FALSE),"") | E36: =IFERROR(VLOOKUP(D36,Employees!A:L,2,FALSE),"") | H36: =IF(G36="","",G36) | I36: =IF(H36="","",IF(H36>=Setup!B7,"ناجح","إعادة تدريب"))
A37: 34 | C37: =IFERROR(VLOOKUP(B37,Sessions!A:J,2,FALSE),"") | E37: =IFERROR(VLOOKUP(D37,Employees!A:L,2,FALSE),"") | H37: =IF(G37="","",G37) | I37: =IF(H37="","",IF(H37>=Setup!B7,"ناجح","إعادة تدريب"))
A38: 35 | C38: =IFERROR(VLOOKUP(B38,Sessions!A:J,2,FALSE),"") | E38: =IFERROR(VLOOKUP(D38,Employees!A:L,2,FALSE),"") | H38: =IF(G38="","",G38) | I38: =IF(H38="","",IF(H38>=Setup!B7,"ناجح","إعادة تدريب"))
A39: 36 | C39: =IFERROR(VLOOKUP(B39,Sessions!A:J,2,FALSE),"") | E39: =IFERROR(VLOOKUP(D39,Employees!A:L,2,FALSE),"") | H39: =IF(G39="","",G39) | I39: =IF(H39="","",IF(H39>=Setup!B7,"ناجح","إعادة تدريب"))
A40: 37 | C40: =IFERROR(VLOOKUP(B40,Sessions!A:J,2,FALSE),"") | E40: =IFERROR(VLOOKUP(D40,Employees!A:L,2,FALSE),"") | H40: =IF(G40="","",G40) | I40: =IF(H40="","",IF(H40>=Setup!B7,"ناجح","إعادة تدريب"))
A41: 38 | C41: =IFERROR(VLOOKUP(B41,Sessions!A:J,2,FALSE),"") | E41: =IFERROR(VLOOKUP(D41,Employees!A:L,2,FALSE),"") | H41: =IF(G41="","",G41) | I41: =IF(H41="","",IF(H41>=Setup!B7,"ناجح","إعادة تدريب"))
...

Sheet Attendance
A1: الحضور - الإدخال اليومي الوحيد للحضور
A3: رقم | B3: كود الجلسة | C3: كود النشاط | D3: التاريخ | E3: كود الموظف | F3: اسم الموظف | G3: القسم | H3: حضر؟ | I3: وقت الدخول | J3: توقيع/إثبات | K3: حالة السجل | L3: ملاحظات
A4: 1 | C4: =IFERROR(VLOOKUP(B4,Sessions!A:J,2,FALSE),"") | D4: =IFERROR(VLOOKUP(B4,Sessions!A:J,3,FALSE),"") | F4: =IFERROR(VLOOKUP(E4,Employees!A:L,2,FALSE),"") | G4: =IFERROR(VLOOKUP(E4,Employees!A:L,3,FALSE),"") | K4: =IF(B4="","",IF(OR(E4="",H4=""),"ناقص",IF(H4="نعم","مكتمل","غائب")))
A5: 2 | C5: =IFERROR(VLOOKUP(B5,Sessions!A:J,2,FALSE),"") | D5: =IFERROR(VLOOKUP(B5,Sessions!A:J,3,FALSE),"") | F5: =IFERROR(VLOOKUP(E5,Employees!A:L,2,FALSE),"") | G5: =IFERROR(VLOOKUP(E5,Employees!A:L,3,FALSE),"") | K5: =IF(B5="","",IF(OR(E5="",H5=""),"ناقص",IF(H5="نعم","مكتمل","غائب")))
A6: 3 | C6: =IFERROR(VLOOKUP(B6,Sessions!A:J,2,FALSE),"") | D6: =IFERROR(VLOOKUP(B6,Sessions!A:J,3,FALSE),"") | F6: =IFERROR(VLOOKUP(E6,Employees!A:L,2,FALSE),"") | G6: =IFERROR(VLOOKUP(E6,Employees!A:L,3,FALSE),"") | K6: =IF(B6="","",IF(OR(E6="",H6=""),"ناقص",IF(H6="نعم","مكتمل","غائب")))
A7: 4 | C7: =IFERROR(VLOOKUP(B7,Sessions!A:J,2,FALSE),"") | D7: =IFERROR(VLOOKUP(B7,Sessions!A:J,3,FALSE),"") | F7: =IFERROR(VLOOKUP(E7,Employees!A:L,2,FALSE),"") | G7: =IFERROR(VLOOKUP(E7,Employees!A:L,3,FALSE),"") | K7: =IF(B7="","",IF(OR(E7="",H7=""),"ناقص",IF(H7="نعم","مكتمل","غائب")))
A8: 5 | C8: =IFERROR(VLOOKUP(B8,Sessions!A:J,2,FALSE),"") | D8: =IFERROR(VLOOKUP(B8,Sessions!A:J,3,FALSE),"") | F8: =IFERROR(VLOOKUP(E8,Employees!A:L,2,FALSE),"") | G8: =IFERROR(VLOOKUP(E8,Employees!A:L,3,FALSE),"") | K8: =IF(B8="","",IF(OR(E8="",H8=""),"ناقص",IF(H8="نعم","مكتمل","غائب")))
A9: 6 | C9: =IFERROR(VLOOKUP(B9,Sessions!A:J,2,FALSE),"") | D9: =IFERROR(VLOOKUP(B9,Sessions!A:J,3,FALSE),"") | F9: =IFERROR(VLOOKUP(E9,Employees!A:L,2,FALSE),"") | G9: =IFERROR(VLOOKUP(E9,Employees!A:L,3,FALSE),"") | K9: =IF(B9="","",IF(OR(E9="",H9=""),"ناقص",IF(H9="نعم","مكتمل","غائب")))
A10: 7 | C10: =IFERROR(VLOOKUP(B10,Sessions!A:J,2,FALSE),"") | D10: =IFERROR(VLOOKUP(B10,Sessions!A:J,3,FALSE),"") | F10: =IFERROR(VLOOKUP(E10,Employees!A:L,2,FALSE),"") | G10: =IFERROR(VLOOKUP(E10,Employees!A:L,3,FALSE),"") | K10: =IF(B10="","",IF(OR(E10="",H10=""),"ناقص",IF(H10="نعم","مكتمل","غائب")))
A11: 8 | C11: =IFERROR(VLOOKUP(B11,Sessions!A:J,2,FALSE),"") | D11: =IFERROR(VLOOKUP(B11,Sessions!A:J,3,FALSE),"") | F11: =IFERROR(VLOOKUP(E11,Employees!A:L,2,FALSE),"") | G11: =IFERROR(VLOOKUP(E11,Employees!A:L,3,FALSE),"") | K11: =IF(B11="","",IF(OR(E11="",H11=""),"ناقص",IF(H11="نعم","مكتمل","غائب")))
A12: 9 | C12: =IFERROR(VLOOKUP(B12,Sessions!A:J,2,FALSE),"") | D12: =IFERROR(VLOOKUP(B12,Sessions!A:J,3,FALSE),"") | F12: =IFERROR(VLOOKUP(E12,Employees!A:L,2,FALSE),"") | G12: =IFERROR(VLOOKUP(E12,Employees!A:L,3,FALSE),"") | K12: =IF(B12="","",IF(OR(E12="",H12=""),"ناقص",IF(H12="نعم","مكتمل","غائب")))
A13: 10 | C13: =IFERROR(VLOOKUP(B13,Sessions!A:J,2,FALSE),"") | D13: =IFERROR(VLOOKUP(B13,Sessions!A:J,3,FALSE),"") | F13: =IFERROR(VLOOKUP(E13,Employees!A:L,2,FALSE),"") | G13: =IFERROR(VLOOKUP(E13,Employees!A:L,3,FALSE),"") | K13: =IF(B13="","",IF(OR(E13="",H13=""),"ناقص",IF(H13="نعم","مكتمل","غائب")))
A14: 11 | C14: =IFERROR(VLOOKUP(B14,Sessions!A:J,2,FALSE),"") | D14: =IFERROR(VLOOKUP(B14,Sessions!A:J,3,FALSE),"") | F14: =IFERROR(VLOOKUP(E14,Employees!A:L,2,FALSE),"") | G14: =IFERROR(VLOOKUP(E14,Employees!A:L,3,FALSE),"") | K14: =IF(B14="","",IF(OR(E14="",H14=""),"ناقص",IF(H14="نعم","مكتمل","غائب")))
A15: 12 | C15: =IFERROR(VLOOKUP(B15,Sessions!A:J,2,FALSE),"") | D15: =IFERROR(VLOOKUP(B15,Sessions!A:J,3,FALSE),"") | F15: =IFERROR(VLOOKUP(E15,Employees!A:L,2,FALSE),"") | G15: =IFERROR(VLOOKUP(E15,Employees!A:L,3,FALSE),"") | K15: =IF(B15="","",IF(OR(E15="",H15=""),"ناقص",IF(H15="نعم","مكتمل","غائب")))
... A1003: 1000 | C1003: =IFERROR(VLOOKUP(B1003,Sessions!A:J,2,FALSE),"") | D1003: =IFERROR(VLOOKUP(B1003,Sessions!A:J,3,FALSE),"") | F1003: =IFERROR(VLOOKUP(E1003,Employees!A:L,2,FALSE),"") | G1003: =IFERROR(VLOOKUP(E1003,Employees!A:L,3,FALSE),"") | K1003: =IF(B1003="","",IF(OR(E1003="",H1003=""),"ناقص",IF(H1003="نعم","مكتمل","غائب")))

Sheet Sessions
A1: سجل التنفيذ الفعلي - جلسة لكل تنفيذ
A3: كود الجلسة | B3: كود النشاط | C3: التاريخ الفعلي | D3: المكان | E3: المدرب | F3: السعة | G3: عدد الحضور | H3: نسبة الحضور | I3: التكلفة | J3: حالة الجلسة
A4: SES-001 | B4: TR-001 | C4: 15/01/2026 | D4: قاعة التدريب | E4: الموارد البشرية | F4: 25 | G4: =IF(A4="","",COUNTIFS([1]Attendance!B:B,B4,[1]Attendance!J:J,C4,[1]Attendance!F:F,"نعم")) -> #VALUE! | H4: =IFERROR(G4/F4,0) -> 0 | J4: مخطط
A5: SES-002 | B5: TR-002 | C5: 22/01/2026 | D5: قاعة التدريب | E5: الموارد البشرية | F5: 30 | G5: =IF(A5="","",COUNTIFS([1]Attendance!B:B,B5,[1]Attendance!J:J,C5,[1]Attendance!F:F,"نعم")) -> #VALUE! | H5: =IFERROR(G5/F5,0) -> 0 | J5: مخطط
G6: =IF(A6="","",COUNTIFS([1]Attendance!B:B,B6,[1]Attendance!J:J,C6,[1]Attendance!F:F,"نعم")) | H6: =IFERROR(G6/F6,0) -> 0
G7: =IF(A7="","",COUNTIFS([1]Attendance!B:B,B7,[1]Attendance!J:J,C7,[1]Attendance!F:F,"نعم")) | H7: =IFERROR(G7/F7,0) -> 0
G8: =IF(A8="","",COUNTIFS([1]Attendance!B:B,B8,[1]Attendance!J:J,C8,[1]Attendance!F:F,"نعم")) | H8: =IFERROR(G8/F8,0) -> 0
G9: =IF(A9="","",COUNTIFS([1]Attendance!B:B,B9,[1]Attendance!J:J,C9,[1]Attendance!F:F,"نعم")) | H9: =IFERROR(G9/F9,0) -> 0
G10: =IF(A10="","",COUNTIFS([1]Attendance!B:B,B10,[1]Attendance!J:J,C10,[1]Attendance!F:F,"نعم")) | H10: =IFERROR(G10/F10,0) -> 0
G11: =IF(A11="","",COUNTIFS([1]Attendance!B:B,B11,[1]Attendance!J:J,C11,[1]Attendance!F:F,"نعم")) | H11: =IFERROR(G11/F11,0) -> 0
G12: =IF(A12="","",COUNTIFS([1]Attendance!B:B,B12,[1]Attendance!J:J,C12,[1]Attendance!F:F,"نعم")) | H12: =IFERROR(G12/F12,0) -> 0
G13: =IF(A13="","",COUNTIFS([1]Attendance!B:B,B13,[1]Attendance!J:J,C13,[1]Attendance!F:F,"نعم")) | H13: =IFERROR(G13/F13,0) -> 0
G14: =IF(A14="","",COUNTIFS([1]Attendance!B:B,B14,[1]Attendance!J:J,C14,[1]Attendance!F:F,"نعم")) | H14: =IFERROR(G14/F14,0) -> 0
G15: =IF(A15="","",COUNTIFS([1]Attendance!B:B,B15,[1]Attendance!J:J,C15,[1]Attendance!F:F,"نعم")) | H15: =IFERROR(G15/F15,0) -> 0
G16: =IF(A16="","",COUNTIFS([1]Attendance!B:B,B16,[1]Attendance!J:J,C16,[1]Attendance!F:F,"نعم")) | H16: =IFERROR(G16/F16,0) -> 0
G17: =IF(A17="","",COUNTIFS([1]Attendance!B:B,B17,[1]Attendance!J:J,C17,[1]Attendance!F:F,"نعم")) | H17: =IFERROR(G17/F17,0) -> 0
... G203: =IF(A203="","",COUNTIFS([1]Attendance!B:B,B203,[1]Attendance!J:J,C203,[1]Attendance!F:F,"نعم")) | H203: =IFERROR(G203/F203,0) -> 0

Sheet Plan
A1: الخطة السنوية المعتمدة - اربط كل نشاط باحتياج ومحور ودليل
A3: كود النشاط | B3: كود الاحتياج | C3: كود المحور | D3: الشهر | E3: عنوان النشاط | F3: الهدف القابل للقياس | G3: الفئة | H3: نوع النشاط | I3: المسؤول | J3: الساعات | K3: التاريخ المخطط | L3: التاريخ الفعلي | M3: الحالة | N3: عدد الحضور | O3: متوسط التقييم | P3: دليل الإثبات | Q3: ملاحظات التحسين
A4: TR-001 | B4: NEED-001 | C4: HRP | D4: يناير | E4: نظام التدريب ومصفوفة الكفاءة | F4: يسجل المستخدم نشاطًا وموظفًا وتقييمًا دون أخطاء | G4: مسؤولو التدريب | H4: ورشة نظام | I4: الموارد البشرية | J4: 3 | K4: 15/01/2026 | M4: مخطط | N4: =IF(A4="","",COUNTIFS([1]Attendance!B:B,A4,[1]Attendance!F:F,"نعم")) -> #VALUE! | O4: =IFERROR(AVERAGEIF([2]Evaluation!B:B,A4,[2]Evaluation!H:H),"")
A5: TR-002 | B5: NEED-001 | C5: HRP | D5: يناير | E5: حقوق وواجبات العاملين ومدونة السلوك | F5: يشرح العامل 5 حقوق و5 واجبات وقناة إبلاغ | G5: كل العاملين | H5: تعريفي | I5: الموارد البشرية | J5: 2 | K5: 22/01/2026 | M5: مخطط | N5: =IF(A5="","",COUNTIFS([1]Attendance!B:B,A5,[1]Attendance!F:F,"نعم")) -> #VALUE! | O5: =IFERROR(AVERAGEIF([2]Evaluation!B:B,A5,[2]Evaluation!H:H),"")
A6: TR-003 | B6: NEED-002 | C6: IPC | D6: فبراير | E6: نظافة اليدين ومعدات الوقاية | F6: يجتاز العامل قائمة ملاحظة المهارة بنسبة 80% | G6: التمريض والخدمات | H6: عملي | I6: مكافحة العدوى | J6: 4 | K6: 46358 | M6: مخطط | N6: =IF(A6="","",COUNTIFS([1]Attendance!B:B,A6,[1]Attendance!F:F,"نعم")) -> #VALUE! | O6: =IFERROR(AVERAGEIF([2]Evaluation!B:B,A6,[2]Evaluation!H:H),"")
A7: TR-004 | B7: NEED-003 | C7: MMU | D7: مارس | E7: سلامة الدواء والأدوية عالية الخطورة | F7: يطبق خطوات التحقق الخمس في محاكاة | G7: أطباء وتمريض وصيدلة | H7: محاكاة | I7: مدير الصيدلية | J7: 3 | K7: 46298 | M7: مخطط | N7: =IF(A7="","",COUNTIFS([1]Attendance!B:B,A7,[1]Attendance!F:F,"نعم")) -> #VALUE! | O7: =IFERROR(AVERAGEIF([2]Evaluation!B:B,A7,[2]Evaluation!H:H),"")
A8: TR-005 | C8: FMS | D8: مارس | E8: الحريق والإخلاء ونقطة التجمع | F8: يصل الفريق لنقطة التجمع خلال الزمن المستهدف | G8: كل العاملين | H8: تمرين طوارئ | I8: السلامة المهنية | J8: 3 | K8: 24/03/2026 | M8: مخطط | N8: =IF(A8="","",COUNTIFS([1]Attendance!B:B,A8,[1]Attendance!F:F,"نعم")) -> #VALUE! | O8: =IFERROR(AVERAGEIF([2]Evaluation!B:B,A8,[2]Evaluation!H:H),"")
A9: TR-006 | C9: QPS | D9: أبريل | E9: الإبلاغ عن الحوادث وتحليل السبب الجذري | F9: يبني الفريق خطة PDSA لحادثة تدريبية | G9: قادة الأقسام | H9: دراسة حالة | I9: الجودة | J9: 3 | K9: 14/04/2026 | M9: مخطط | N9: =IF(A9="","",COUNTIFS([1]Attendance!B:B,A9,[1]Attendance!F:F,"نعم")) -> #VALUE! | O9: =IFERROR(AVERAGEIF([2]Evaluation!B:B,A9,[2]Evaluation!H:H),"")
A10: TR-007 | C10: HIS | D10: مايو | E10: التوثيق الطبي وسرية المعلومات | F10: يحقق الملف التدريبي 90% في قائمة التدقيق | G10: سريري وسجلات | H10: تطبيقي | I10: السجلات الطبية | J10: 3 | K10: 46361 | M10: مخطط | N10: =IF(A10="","",COUNTIFS([1]Attendance!B:B,A10,[1]Attendance!F:F,"نعم")) -> #VALUE! | O10: =IFERROR(AVERAGEIF([2]Evaluation!B:B,A10,[2]Evaluation!H:H),"")
A11: TR-008 | C11: PFR | D11: يونيو | E11: حقوق المريض والشكاوى والموافقة | F11: يتعامل مع الحالة وفق السياسة دون خرق خصوصية | G11: كل العاملين | H11: لعب أدوار | I11: خدمة العملاء | J11: 2 | K11: 16/06/2026 | M11: مخطط | N11: =IF(A11="","",COUNTIFS([1]Attendance!B:B,A11,[1]Attendance!F:F,"نعم")) -> #VALUE! | O11: =IFERROR(AVERAGEIF([2]Evaluation!B:B,A11,[2]Evaluation!H:H),"")
A12: TR-009 | C12: AOP/COP | D12: يوليو | E12: التقييم الأولي والتصعيد والتسليم SBAR | F12: ينفذ تسليم حالة منظمًا بدرجة 80% | G12: أطباء وتمريض | H12: محاكاة | I12: الإدارة الطبية | J12: 4 | K12: 14/07/2026 | M12: مخطط | N12: =IF(A12="","",COUNTIFS([1]Attendance!B:B,A12,[1]Attendance!F:F,"نعم")) -> #VALUE! | O12: =IFERROR(AVERAGEIF([2]Evaluation!B:B,A12,[2]Evaluation!H:H),"")
A13: TR-010 | C13: FMS | D13: أغسطس | E13: النفايات والمواد الخطرة والتعرض المهني | F13: يفرز وينقل النفايات وفق القائمة المعتمدة | G13: كل الفئات المعنية | H13: عملي | I13: السلامة والعدوى | J13: 2 | K13: 46334 | M13: مخطط | N13: =IF(A13="","",COUNTIFS([1]Attendance!B:B,A13,[1]Attendance!F:F,"نعم")) -> #VALUE! | O13: =IFERROR(AVERAGEIF([2]Evaluation!B:B,A13,[2]Evaluation!H:H),"")
A14: TR-011 | C14: HRP | D14: سبتمبر | E14: تقييم الكفاءة وإعادة التدريب | F14: يحدد المدير فجوة الكفاءة ويضع إجراءً فرديًا | G14: رؤساء الأقسام | H14: تقييم عملي | I14: الموارد البشرية | J14: 4 | K14: 15/09/2026 | M14: مخطط | N14: =IF(A14="","",COUNTIFS([1]Attendance!B:B,A14,[1]Attendance!F:F,"نعم")) -> #VALUE! | O14: =IFERROR(AVERAGEIF([2]Evaluation!B:B,A14,[2]Evaluation!H:H),"")
A15: TR-012 | C15: GLD/QPS | D15: أكتوبر | E15: إدارة الأزمات واستمرارية الأعمال | F15: يحدد الفريق الأدوار ومسارات التصعيد | G15: القيادة والطوارئ | H15: تمرين مكتبي | I15: إدارة المنشأة | J15: 3 | K15: 13/10/2026 | M15: مخطط | N15: =IF(A15="","",COUNTIFS([1]Attendance!B:B,A15,[1]Attendance!F:F,"نعم")) -> #VALUE! | O15: =IFERROR(AVERAGEIF([2]Evaluation!B:B,A15,[2]Evaluation!H:H),"")
A16: TR-013 | C16: QPS/HRP | D16: ديسمبر | E16: المراجعة السنوية وخطة العام القادم | F16: يعرض المسؤول مؤشرات التدريب وخطة تحسين | G16: الإدارة والجودة | H16: مراجعة | I16: الجودة والموارد البشرية | J16: 3 | K16: 46246 | M16: مخطط | N16: =IF(A16="","",COUNTIFS([1]Attendance!B:B,A16,[1]Attendance!F:F,"نعم")) -> #VALUE! | O16: =IFERROR(AVERAGEIF([2]Evaluation!B:B,A16,[2]Evaluation!H:H),"")
N17: =IF(A17="","",COUNTIFS([1]Attendance!B:B,A17,[1]Attendance!F:F,"نعم")) | O17: =IFERROR(AVERAGEIF([2]Evaluation!B:B,A17,[2]Evaluation!H:H),"")
N18: =IF(A18="","",COUNTIFS([1]Attendance!B:B,A18,[1]Attendance!F:F,"نعم")) | O18: =IFERROR(AVERAGEIF([2]Evaluation!B:B,A18,[2]Evaluation!H:H),"")
N19: =IF(A19="","",COUNTIFS([1]Attendance!B:B,A19,[1]Attendance!F:F,"نعم")) | O19: =IFERROR(AVERAGEIF([2]Evaluation!B:B,A19,[2]Evaluation!H:H),"")
N20: =IF(A20="","",COUNTIFS([1]Attendance!B:B,A20,[1]Attendance!F:F,"نعم")) | O20: =IFERROR(AVERAGEIF([2]Evaluation!B:B,A20,[2]Evaluation!H:H),"")
N21: =IF(A21="","",COUNTIFS([1]Attendance!B:B,A21,[1]Attendance!F:F,"نعم")) | O21: =IFERROR(AVERAGEIF([2]Evaluation!B:B,A21,[2]Evaluation!H:H),"")
N22: =IF(A22="","",COUNTIFS([1]Attendance!B:B,A22,[1]Attendance!F:F,"نعم")) | O22: =IFERROR(AVERAGEIF([2]Evaluation!B:B,A22,[2]Evaluation!H:H),"")
N23: =IF(A23="","",COUNTIFS([1]Attendance!B:B,A23,[1]Attendance!F:F,"نعم")) | O23: =IFERROR(AVERAGEIF([2]Evaluation!B:B,A23,[2]Evaluation!H:H),"")
N24: =IF(A24="","",COUNTIFS([1]Attendance!B:B,A24,[1]Attendance!F:F,"نعم")) | O24: =IFERROR(AVERAGEIF([2]Evaluation!B:B,A24,[2]Evaluation!H:H),"")
N25: =IF(A25="","",COUNTIFS([1]Attendance!B:B,A25,[1]Attendance!F:F,"نعم")) | O25: =IFERROR(AVERAGEIF([2]Evaluation!B:B,A25,[2]Evaluation!H:H),"")
N26: =IF(A26="","",COUNTIFS([1]Attendance!B:B,A26,[1]Attendance!F:F,"نعم")) | O26: =IFERROR(AVERAGEIF([2]Evaluation!B:B,A26,[2]Evaluation!H:H),"")
N27: =IF(A27="","",COUNTIFS([1]Attendance!B:B,A27,[1]Attendance!F:F,"نعم")) | O27: =IFERROR(AVERAGEIF([2]Evaluation!B:B,A27,[2]Evaluation!H:H),"")
N28: =IF(A28="","",COUNTIFS([1]Attendance!B:B,A28,[1]Attendance!F:F,"نعم")) | O28: =IFERROR(AVERAGEIF([2]Evaluation!B:B,A28,[2]Evaluation!H:H),"")
... N203: =IF(A203="","",COUNTIFS([1]Attendance!B:B,A203,[1]Attendance!F:F,"نعم")) | O203: =IFERROR(AVERAGEIF([2]Evaluation!B:B,A203,[2]Evaluation!H:H),"")

Sheet Needs
A1: تحليل الاحتياج التدريبي - قبل إعداد الخطة
A3: كود الاحتياج | B3: القسم | C3: الفجوة/الخطر | D3: مصدر الاحتياج | E3: الأثر | F3: الأولوية | G3: الكفاءة المطلوبة | H3: الإجراء التدريبي | I3: المسؤول | J3: موعد الإغلاق | K3: الحالة
A4: NEED-001 | B4: كل الأقسام | C4: عدم اكتمال سجلات التدريب والكفاءة | D4: تدقيق داخلي | E4: مرتفع | F4: عاجل | G4: إدارة التدريب والتوثيق | H4: بناء النظام وتدريب المستخدمين | I4: الموارد البشرية | J4: 31/01/2026 | K4: مفتوح
A5: NEED-002 | B5: التمريض | C5: تفاوت الالتزام بنظافة اليدين | D5: مؤشر مكافحة العدوى | E5: مرتفع | F5: عاجل | G5: مكافحة العدوى | H5: تدريب عملي وتدقيق ملاحظة | I5: مكافحة العدوى | J5: 28/02/2026 | K5: مفتوح
A6: NEED-003 | B6: الأدوية | C6: حاجة إلى توحيد التحقق من الدواء | D6: بلاغات/مخاطر | E6: مرتفع | F6: عاجل | G6: سلامة الدواء | H6: محاكاة واختبار كفاءة | I6: الصيدلية | J6: 31/03/2026 | K6: مفتوح

Sheet Employees
A1: قاعدة بيانات العاملين - الإدخال الأساسي
A3: كود الموظف | B3: الاسم | C3: القسم | D3: المسمى | E3: الفئة | F3: تاريخ التعيين | G3: الحالة | H3: المدير | I3: عدد الأنشطة | J3: نسبة الحضور | K3: متوسط التقييم | L3: حالة التدريب
A4: EMP-001 | B4: يُستكمل | C4: التمريض | D4: ممرض/ة | E4: سريري | F4: 45658 | G4: نشط | H4: رئيس التمريض | I4: =IF(A4="","",COUNTIF([1]Attendance!D:D,A4)) -> #VALUE! | J4: =IFERROR(COUNTIFS([1]Attendance!D:D,A4,[1]Attendance!F:F,"نعم")/I4,0) -> 0 | K4: =IFERROR(AVERAGEIF([2]Evaluation!D:D,A4,[2]Evaluation!H:H),"") | L4: =IF(A4="","",IF(J4<Setup!B8,"حضور غير مكتمل",IF(K4<Setup!B7,"يحتاج إعادة تدريب","مكتمل"))) -> حضور غير مكتمل
A5: EMP-002 | B5: يُستكمل | C5: الصيدلية | D5: صيدلي | E5: سريري | F5: 15/02/2025 | G5: نشط | H5: مدير الصيدلية | I5: =IF(A5="","",COUNTIF([1]Attendance!D:D,A5)) -> #VALUE! | J5: =IFERROR(COUNTIFS([1]Attendance!D:D,A5,[1]Attendance!F:F,"نعم")/I5,0) -> 0 | K5: =IFERROR(AVERAGEIF([2]Evaluation!D:D,A5,[2]Evaluation!H:H),"") | L5: =IF(A5="","",IF(J5<Setup!B8,"حضور غير مكتمل",IF(K5<Setup!B7,"يحتاج إعادة تدريب","مكتمل"))) -> حضور غير مكتمل
A6: EMP-003 | B6: يُستكمل | C6: الاستقبال | D6: موظف استقبال | E6: إداري | F6: 45933 | G6: نشط | H6: مدير الخدمة | I6: =IF(A6="","",COUNTIF([1]Attendance!D:D,A6)) -> #VALUE! | J6: =IFERROR(COUNTIFS([1]Attendance!D:D,A6,[1]Attendance!F:F,"نعم")/I6,0) -> 0 | K6: =IFERROR(AVERAGEIF([2]Evaluation!D:D,A6,[2]Evaluation!H:H),"") | L6: =IF(A6="","",IF(J6<Setup!B8,"حضور غير مكتمل",IF(K6<Setup!B7,"يحتاج إعادة تدريب","مكتمل"))) -> حضور غير مكتمل
I7: =IF(A7="","",COUNTIF([1]Attendance!D:D,A7)) | J7: =IFERROR(COUNTIFS([1]Attendance!D:D,A7,[1]Attendance!F:F,"نعم")/I7,0) -> 0 | K7: =IFERROR(AVERAGEIF([2]Evaluation!D:D,A7,[2]Evaluation!H:H),"") | L7: =IF(A7="","",IF(J7<Setup!B8,"حضور غير مكتمل",IF(K7<Setup!B7,"يحتاج إعادة تدريب","مكتمل")))
I8: =IF(A8="","",COUNTIF([1]Attendance!D:D,A8)) | J8: =IFERROR(COUNTIFS([1]Attendance!D:D,A8,[1]Attendance!F:F,"نعم")/I8,0) -> 0 | K8: =IFERROR(AVERAGEIF([2]Evaluation!D:D,A8,[2]Evaluation!H:H),"") | L8: =IF(A8="","",IF(J8<Setup!B8,"حضور غير مكتمل",IF(K8<Setup!B7,"يحتاج إعادة تدريب","مكتمل")))
I9: =IF(A9="","",COUNTIF([1]Attendance!D:D,A9)) | J9: =IFERROR(COUNTIFS([1]Attendance!D:D,A9,[1]Attendance!F:F,"نعم")/I9,0) -> 0 | K9: =IFERROR(AVERAGEIF([2]Evaluation!D:D,A9,[2]Evaluation!H:H),"") | L9: =IF(A9="","",IF(J9<Setup!B8,"حضور غير مكتمل",IF(K9<Setup!B7,"يحتاج إعادة تدريب","مكتمل")))
I10: =IF(A10="","",COUNTIF([1]Attendance!D:D,A10)) | J10: =IFERROR(COUNTIFS([1]Attendance!D:D,A10,[1]Attendance!F:F,"نعم")/I10,0) -> 0 | K10: =IFERROR(AVERAGEIF([2]Evaluation!D:D,A10,[2]Evaluation!H:H),"") | L10: =IF(A10="","",IF(J10<Setup!B8,"حضور غير مكتمل",IF(K10<Setup!B7,"يحتاج إعادة تدريب","مكتمل")))
I11: =IF(A11="","",COUNTIF([1]Attendance!D:D,A11)) | J11: =IFERROR(COUNTIFS([1]Attendance!D:D,A11,[1]Attendance!F:F,"نعم")/I11,0) -> 0 | K11: =IFERROR(AVERAGEIF([2]Evaluation!D:D,A11,[2]Evaluation!H:H),"") | L11: =IF(A11="","",IF(J11<Setup!B8,"حضور غير مكتمل",IF(K11<Setup!B7,"يحتاج إعادة تدريب","مكتمل")))
I12: =IF(A12="","",COUNTIF([1]Attendance!D:D,A12)) | J12: =IFERROR(COUNTIFS([1]Attendance!D:D,A12,[1]Attendance!F:F,"نعم")/I12,0) -> 0 | K12: =IFERROR(AVERAGEIF([2]Evaluation!D:D,A12,[2]Evaluation!H:H),"") | L12: =IF(A12="","",IF(J12<Setup!B8,"حضور غير مكتمل",IF(K12<Setup!B7,"يحتاج إعادة تدريب","مكتمل")))
I13: =IF(A13="","",COUNTIF([1]Attendance!D:D,A13)) | J13: =IFERROR(COUNTIFS([1]Attendance!D:D,A13,[1]Attendance!F:F,"نعم")/I13,0) -> 0 | K13: =IFERROR(AVERAGEIF([2]Evaluation!D:D,A13,[2]Evaluation!H:H),"") | L13: =IF(A13="","",IF(J13<Setup!B8,"حضور غير مكتمل",IF(K13<Setup!B7,"يحتاج إعادة تدريب","مكتمل")))
I14: =IF(A14="","",COUNTIF([1]Attendance!D:D,A14)) | J14: =IFERROR(COUNTIFS([1]Attendance!D:D,A14,[1]Attendance!F:F,"نعم")/I14,0) -> 0 | K14: =IFERROR(AVERAGEIF([2]Evaluation!D:D,A14,[2]Evaluation!H:H),"") | L14: =IF(A14="","",IF(J14<Setup!B8,"حضور غير مكتمل",IF(K14<Setup!B7,"يحتاج إعادة تدريب","مكتمل")))
I15: =IF(A15="","",COUNTIF([1]Attendance!D:D,A15)) | J15: =IFERROR(COUNTIFS([1]Attendance!D:D,A15,[1]Attendance!F:F,"نعم")/I15,0) -> 0 | K15: =IFERROR(AVERAGEIF([2]Evaluation!D:D,A15,[2]Evaluation!H:H),"") | L15: =IF(A15="","",IF(J15<Setup!B8,"حضور غير مكتمل",IF(K15<Setup!B7,"يحتاج إعادة تدريب","مكتمل")))
I16: =IF(A16="","",COUNTIF([1]Attendance!D:D,A16)) | J16: =IFERROR(COUNTIFS([1]Attendance!D:D,A16,[1]Attendance!F:F,"نعم")/I16,0) -> 0 | K16: =IFERROR(AVERAGEIF([2]Evaluation!D:D,A16,[2]Evaluation!H:H),"") | L16: =IF(A16="","",IF(J16<Setup!B8,"حضور غير مكتمل",IF(K16<Setup!B7,"يحتاج إعادة تدريب","مكتمل")))
I17: =IF(A17="","",COUNTIF([1]Attendance!D:D,A17)) | J17: =IFERROR(COUNTIFS([1]Attendance!D:D,A17,[1]Attendance!F:F,"نعم")/I17,0) -> 0 | K17: =IFERROR(AVERAGEIF([2]Evaluation!D:D,A17,[2]Evaluation!H:H),"") | L17: =IF(A17="","",IF(J17<Setup!B8,"حضور غير مكتمل",IF(K17<Setup!B7,"يحتاج إعادة تدريب","مكتمل")))
I18: =IF(A18="","",COUNTIF([1]Attendance!D:D,A18)) | J18: =IFERROR(COUNTIFS([1]Attendance!D:D,A18,[1]Attendance!F:F,"نعم")/I18,0) -> 0 | K18: =IFERROR(AVERAGEIF([2]Evaluation!D:D,A18,[2]Evaluation!H:H),"") | L18: =IF(A18="","",IF(J18<Setup!B8,"حضور غير مكتمل",IF(K18<Setup!B7,"يحتاج إعادة تدريب","مكتمل")))
I19: =IF(A19="","",COUNTIF([1]Attendance!D:D,A19)) | J19: =IFERROR(COUNTIFS([1]Attendance!D:D,A19,[1]Attendance!F:F,"نعم")/I19,0) -> 0 | K19: =IFERROR(AVERAGEIF([2]Evaluation!D:D,A19,[2]Evaluation!H:H),"") | L19: =IF(A19="","",IF(J19<Setup!B8,"حضور غير مكتمل",IF(K19<Setup!B7,"يحتاج إعادة تدريب","مكتمل")))
I20: =IF(A20="","",COUNTIF([1]Attendance!D:D,A20)) | J20: =IFERROR(COUNTIFS([1]Attendance!D:D,A20,[1]Attendance!F:F,"نعم")/I20,0) -> 0 | K20: =IFERROR(AVERAGEIF([2]Evaluation!D:D,A20,[2]Evaluation!H:H),"") | L20: =IF(A20="","",IF(J20<Setup!B8,"حضور غير مكتمل",IF(K20<Setup!B7,"يحتاج إعادة تدريب","مكتمل")))
I21: =IF(A21="","",COUNTIF([1]Attendance!D:D,A21)) | J21: =IFERROR(COUNTIFS([1]Attendance!D:D,A21,[1]Attendance!F:F,"نعم")/I21,0) -> 0 | K21: =IFERROR(AVERAGEIF([2]Evaluation!D:D,A21,[2]Evaluation!H:H),"") | L21: =IF(A21="","",IF(J21<Setup!B8,"حضور غير مكتمل",IF(K21<Setup!B7,"يحتاج إعادة تدريب","مكتمل")))
I22: =IF(A22="","",COUNTIF([1]Attendance!D:D,A22)) | J22: =IFERROR(COUNTIFS([1]Attendance!D:D,A22,[1]Attendance!F:F,"نعم")/I22,0) -> 0 | K22: =IFERROR(AVERAGEIF([2]Evaluation!D:D,A22,[2]Evaluation!H:H),"") | L22: =IF(A22="","",IF(J22<Setup!B8,"حضور غير مكتمل",IF(K22<Setup!B7,"يحتاج إعادة تدريب","مكتمل")))
I23: =IF(A23="","",COUNTIF([1]Attendance!D:D,A23)) | J23: =IFERROR(COUNTIFS([1]Attendance!D:D,A23,[1]Attendance!F:F,"نعم")/I23,0) -> 0 | K23: =IFERROR(AVERAGEIF([2]Evaluation!D:D,A23,[2]Evaluation!H:H),"") | L23: =IF(A23="","",IF(J23<Setup!B8,"حضور غير مكتمل",IF(K23<Setup!B7,"يحتاج إعادة تدريب","مكتمل")))
I24: =IF(A24="","",COUNTIF([1]Attendance!D:D,A24)) | J24: =IFERROR(COUNTIFS([1]Attendance!D:D,A24,[1]Attendance!F:F,"نعم")/I24,0) -> 0 | K24: =IFERROR(AVERAGEIF([2]Evaluation!D:D,A24,[2]Evaluation!H:H),"") | L24: =IF(A24="","",IF(J24<Setup!B8,"حضور غير مكتمل",IF(K24<Setup!B7,"يحتاج إعادة تدريب","مكتمل")))
I25: =IF(A25="","",COUNTIF([1]Attendance!D:D,A25)) | J25: =IFERROR(COUNTIFS([1]Attendance!D:D,A25,[1]Attendance!F:F,"نعم")/I25,0) -> 0 | K25: =IFERROR(AVERAGEIF([2]Evaluation!D:D,A25,[2]Evaluation!H:H),"") | L25: =IF(A25="","",IF(J25<Setup!B8,"حضور غير مكتمل",IF(K25<Setup!B7,"يحتاج إعادة تدريب","مكتمل")))
I26: =IF(A26="","",COUNTIF([1]Attendance!D:D,A26)) | J26: =IFERROR(COUNTIFS([1]Attendance!D:D,A26,[1]Attendance!F:F,"نعم")/I26,0) -> 0 | K26: =IFERROR(AVERAGEIF([2]Evaluation!D:D,A26,[2]Evaluation!H:H),"") | L26: =IF(A26="","",IF(J26<Setup!B8,"حضور غير مكتمل",IF(K26<Setup!B7,"يحتاج إعادة تدريب","مكتمل")))
I27: =IF(A27="","",COUNTIF([1]Attendance!D:D,A27)) | J27: =IFERROR(COUNTIFS([1]Attendance!D:D,A27,[1]Attendance!F:F,"نعم")/I27,0) -> 0 | K27: =IFERROR(AVERAGEIF([2]Evaluation!D:D,A27,[2]Evaluation!H:H),"") | L27: =IF(A27="","",IF(J27<Setup!B8,"حضور غير مكتمل",IF(K27<Setup!B7,"يحتاج إعادة تدريب","مكتمل")))
I28: =IF(A28="","",COUNTIF([1]Attendance!D:D,A28)) | J28: =IFERROR(COUNTIFS([1]Attendance!D:D,A28,[1]Attendance!F:F,"نعم")/I28,0) -> 0 | K28: =IFERROR(AVERAGEIF([2]Evaluation!D:D,A28,[2]Evaluation!H:H),"") | L28: =IF(A28="","",IF(J28<Setup!B8,"حضور غير مكتمل",IF(K28<Setup!B7,"يحتاج إعادة تدريب","مكتمل")))
I29: =IF(A29="","",COUNTIF([1]Attendance!D:D,A29)) | J29: =IFERROR(COUNTIFS([1]Attendance!D:D,A29,[1]Attendance!F:F,"نعم")/I29,0) -> 0 | K29: =IFERROR(AVERAGEIF([2]Evaluation!D:D,A29,[2]Evaluation!H:H),"") | L29: =IF(A29="","",IF(J29<Setup!B8,"حضور غير مكتمل",IF(K29<Setup!B7,"يحتاج إعادة تدريب","مكتمل")))
I30: =IF(A30="","",COUNTIF([1]Attendance!D:D,A30)) | J30: =IFERROR(COUNTIFS([1]Attendance!D:D,A30,[1]Attendance!F:F,"نعم")/I30,0) -> 0 | K30: =IFERROR(AVERAGEIF([2]Evaluation!D:D,A30,[2]Evaluation!H:H),"") | L30: =IF(A30="","",IF(J30<Setup!B8,"حضور غير مكتمل",IF(K30<Setup!B7,"يحتاج إعادة تدريب","مكتمل")))
I31: =IF(A31="","",COUNTIF([1]Attendance!D:D,A31)) | J31: =IFERROR(COUNTIFS([1]Attendance!D:D,A31,[1]Attendance!F:F,"نعم")/I31,0) -> 0 | K31: =IFERROR(AVERAGEIF([2]Evaluation!D:D,A31,[2]Evaluation!H:H),"") | L31: =IF(A31="","",IF(J31<Setup!B8,"حضور غير مكتمل",IF(K31<Setup!B7,"يحتاج إعادة تدريب","مكتمل")))
I32: =IF(A32="","",COUNTIF([1]Attendance!D:D,A32)) | J32: =IFERROR(COUNTIFS([1]Attendance!D:D,A32,[1]Attendance!F:F,"نعم")/I32,0) -> 0 | K32: =IFERROR(AVERAGEIF([2]Evaluation!D:D,A32,[2]Evaluation!H:H),"") | L32: =IF(A32="","",IF(J32<Setup!B8,"حضور غير مكتمل",IF(K32<Setup!B7,"يحتاج إعادة تدريب","مكتمل")))
I33: =IF(A33="","",COUNTIF([1]Attendance!D:D,A33)) | J33: =IFERROR(COUNTIFS([1]Attendance!D:D,A33,[1]Attendance!F:F,"نعم")/I33,0) -> 0 | K33: =IFERROR(AVERAGEIF([2]Evaluation!D:D,A33,[2]Evaluation!H:H),"") | L33: =IF(A33="","",IF(J33<Setup!B8,"حضور غير مكتمل",IF(K33<Setup!B7,"يحتاج إعادة تدريب","مكتمل")))
I34: =IF(A34="","",COUNTIF([1]Attendance!D:D,A34)) | J34: =IFERROR(COUNTIFS([1]Attendance!D:D,A34,[1]Attendance!F:F,"نعم")/I34,0) -> 0 | K34: =IFERROR(AVERAGEIF([2]Evaluation!D:D,A34,[2]Evaluation!H:H),"") | L34: =IF(A34="","",IF(J34<Setup!B8,"حضور غير مكتمل",IF(K34<Setup!B7,"يحتاج إعادة تدريب","مكتمل")))
I35: =IF(A35="","",COUNTIF([1]Attendance!D:D,A35)) | J35: =IFERROR(COUNTIFS([1]Attendance!D:D,A35,[1]Attendance!F:F,"نعم")/I35,0) -> 0 | K35: =IFERROR(AVERAGEIF([2]Evaluation!D:D,A35,[2]Evaluation!H:H),"") | L35: =IF(A35="","",IF(J35<Setup!B8,"حضور غير مكتمل",IF(K35<Setup!B7,"يحتاج إعادة تدريب","مكتمل")))
I36: =IF(A36="","",COUNTIF([1]Attendance!D:D,A36)) | J36: =IFERROR(COUNTIFS([1]Attendance!D:D,A36,[1]Attendance!F:F,"نعم")/I36,0) -> 0 | K36: =IFERROR(AVERAGEIF([2]Evaluation!D:D,A36,[2]Evaluation!H:H),"") | L36: =IF(A36="","",IF(J36<Setup!B8,"حضور غير مكتمل",IF(K36<Setup!B7,"يحتاج إعادة تدريب","مكتمل")))
I37: =IF(A37="","",COUNTIF([1]Attendance!D:D,A37)) | J37: =IFERROR(COUNTIFS([1]Attendance!D:D,A37,[1]Attendance!F:F,"نعم")/I37,0) -> 0 | K37: =IFERROR(AVERAGEIF([2]Evaluation!D:D,A37,[2]Evaluation!H:H),"") | L37: =IF(A37="","",IF(J37<Setup!B8,"حضور غير مكتمل",IF(K37<Setup!B7,"يحتاج إعادة تدريب","مكتمل")))
I38: =IF(A38="","",COUNTIF([1]Attendance!D:D,A38)) | J38: =IFERROR(COUNTIFS([1]Attendance!D:D,A38,[1]Attendance!F:F,"نعم")/I38,0) -> 0 | K38: =IFERROR(AVERAGEIF([2]Evaluation!D:D,A38,[2]Evaluation!H:H),"") | L38: =IF(A38="","",IF(J38<Setup!B8,"حضور غير مكتمل",IF(K38<Setup!B7,"يحتاج إعادة تدريب","مكتمل")))
I39: =IF(A39="","",COUNTIF([1]Attendance!D:D,A39)) | J39: =IFERROR(COUNTIFS([1]Attendance!D:D,A39,[1]Attendance!F:F,"نعم")/I39,0) -> 0 | K39: =IFERROR(AVERAGEIF([2]Evaluation!D:D,A39,[2]Evaluation!H:H),"") | L39: =IF(A39="","",IF(J39<Setup!B8,"حضور غير مكتمل",IF(K39<Setup!B7,"يحتاج إعادة تدريب","مكتمل")))
I40: =IF(A40="","",COUNTIF([1]Attendance!D:D,A40)) | J40: =IFERROR(COUNTIFS([1]Attendance!D:D,A40,[1]Attendance!F:F,"نعم")/I40,0) -> 0 | K40: =IFERROR(AVERAGEIF([2]Evaluation!D:D,A40,[2]Evaluation!H:H),"") | L40: =IF(A40="","",IF(J40<Setup!B8,"حضور غير مكتمل",IF(K40<Setup!B7,"يحتاج إعادة تدريب","مكتمل")))
I41: =IF(A41="","",COUNTIF([1]Attendance!D:D,A41)) | J41: =IFERROR(COUNTIFS([1]Attendance!D:D,A41,[1]Attendance!F:F,"نعم")/I41,0) -> 0 | K41: =IFERROR(AVERAGEIF([2]Evaluation!D:D,A41,[2]Evaluation!H:H),"") | L41: =IF(A41="","",IF(J41<Setup!B8,"حضور غير مكتمل",IF(K41<Setup!B7,"يحتاج إعادة تدريب","مكتمل")))
...

Sheet Standards
A1: كتالوج محاور ومعايير التدريب - مرجع التخصيص
A3: كود المحور | B3: المحور | C3: موضوع/متطلب التدريب | D3: الفئات المعنية | E3: دليل الإثبات المتوقع | F3: تكرار مقترح | G3: ملاحظات المطابقة
A4: HRP | B4: إدارة الموارد البشرية | C4: التعريف، الوصف الوظيفي، الكفاءة، التقييم وإعادة التدريب | D4: كل العاملين | E4: خطة تدريب، مصفوفة كفاءة، سجلات حضور وتقييم | F4: سنوي/عند التعيين | G4: اربطه بسياسة المنشأة
A5: PFR | B5: حقوق المريض والأسرة | C5: الحقوق، الخصوصية، الموافقة، الشكاوى والتواصل | D5: كل العاملين | E5: مادة، اختبار، حالات تطبيقية، سجل شكاوى | F5: سنوي | G5: تحقق من سياسة حقوق المريض
A6: IPC | B6: مكافحة العدوى | C6: نظافة اليدين، PPE، العزل، النفايات، التعرض المهني | D6: سريري/خدمات معاونة | E6: قائمة ملاحظة، تدريب عملي، نتائج تدقيق | F6: ربع سنوي | G6: حسب تقييم مخاطر العدوى
A7: MMU | B7: إدارة الدواء | C7: التخزين، التحقق، الأدوية عالية الخطورة، الإبلاغ | D7: أطباء/تمريض/صيدلة | E7: محاكاة، اختبار، مراجعة خطأ دوائي | F7: سنوي | G7: حسب قائمة الأدوية الحرجة
A8: FMS | B8: السلامة وإدارة المنشأة | C8: الحريق، الإخلاء، الطوارئ، المواد الخطرة، الأمن | D8: كل العاملين | E8: سيناريو، زمن إخلاء، محضر تمرين | F8: سنوي/نصف سنوي | G8: حسب خطة الطوارئ
A9: QPS | B9: الجودة وسلامة المريض | C9: الإبلاغ، تحليل السبب، مؤشرات الأداء، PDSA | D9: قادة الأقسام والجودة | E9: خطة تحسين، محضر لجنة، مؤشر قبل/بعد | F9: ربع سنوي | G9: اربطه بالمخاطر الفعلية
A10: HIS | B10: المعلومات والسجلات | C10: التوثيق، السرية، الصلاحيات، الأمن السيبراني | D10: سريري/سجلات/IT | E10: تدقيق ملفات، اختبار، سجل صلاحيات | F10: سنوي | G10: طبق سياسة حماية البيانات
A11: GLD | B11: القيادة والحوكمة | C11: المسؤوليات، إدارة المخاطر، استمرارية الأعمال | D11: القيادة ورؤساء الأقسام | E11: محاضر، تمرين، خطة استمرارية | F11: سنوي | G11: وفق هيكل المنشأة

Sheet Setup
A1: إعدادات النظام وتعريف خطة التدريب
A3: البند | B3: القيمة | C3: شرح الاستخدام | D3: مصدر/مسؤول الاعتماد
A4: اسم المنشأة | B4: يُستكمل | C4: الاسم الرسمي للمنشأة | D4: إدارة المنشأة
A5: نوع المنشأة | B5: مستشفى | C5: اختر النوع الفعلي | D5: الجودة
A6: سنة الخطة | B6: 2026 | C6: غيّر السنة عند بدء دورة جديدة | D6: الموارد البشرية
A7: نسبة النجاح | B7: 70 | C7: الحد الأدنى للتقييم البعدي | D7: الجودة والتدريب
A8: نسبة الحضور | B8: 80 | C8: الحد الأدنى لإكمال النشاط | D8: الجودة والتدريب
A9: إصدار الدليل | B9: يُستكمل | C9: سجل رقم وتاريخ آخر دليل GAHAR معتمد | D9: الجودة
A10: تنبيه | B10: هذه أداة تشغيلية وليست بديلًا عن دليل GAHAR الرسمي | C10: طابق البنود مع نطاق المنشأة والإصدار الساري قبل الاعتماد | D10: مسؤول الجودة
