Workbook

Sheet نموذج تقييم
A1: نموذج تقييم دورة تدريبية
A3: اسم النشاط:
A4: كود النشاط:
A5: اسم الموظف:
A6: كود الموظف:
A7: التاريخ:
A8: اسم المقيّم:
A11: البند | B11: الدرجة | C11: الملاحظات
A12: فهم المحتوى
A13: تطبيق المهارة
A14: الالتزام بإجراءات السلامة
A15: التواصل والعمل الجماعي
A16: النتيجة النهائية

Sheet نموذج حضور
A1: نموذج حضور دورة تدريبية
A3: اسم النشاط:
A4: كود النشاط:
A5: التاريخ:
A6: المدرب:
A7: القسم:
A10: م | B10: كود الموظف | C10: اسم الموظف | D10: القسم | E10: حضر؟ | F10: التوقيع | G10: التقييم | H10: ملاحظات
A11: 1
A12: 2
A13: 3
A14: 4
A15: 5
A16: 6
A17: 7
A18: 8
A19: 9
A20: 10
A21: 11
A22: 12
... A40: 30

Sheet لوحة التحكم
A1: لوحة مؤشرات التدريب
A3: المؤشر | B3: القيمة
A4: إجمالي الموظفين | B4: =COUNTIF(الموظفون!G:G,"نشط") -> 3
A5: إجمالي الأنشطة | B5: =COUNTIF(الخطة!A:A,"TR-*") -> 11
A6: الأنشطة المنفذة | B6: =COUNTIF(الخطة!L:L,"منفذ") -> 0
A7: نسبة تنفيذ الخطة | B7: =IFERROR(B6/B5,0) -> 0
A8: إجمالي سجلات الحضور | B8: =COUNTIF(الحضور!D:D,"EMP-*") -> 0
A9: نسبة الحضور | B9: =IFERROR(COUNTIF(الحضور!F:F,"نعم")/B8,0) -> 0
A10: متوسط التقييم البعدي | B10: =IFERROR(AVERAGE(التقييمات!H:H),0) -> 0
A11: عدد الناجحين | B11: =COUNTIF(التقييمات!I:I,"ناجح") -> 0
A12: يحتاجون إعادة تدريب | B12: =COUNTIF(التقييمات!I:I,"يحتاج إعادة تدريب") -> 0

Sheet التقييمات
A1: سجل التقييمات - أدخل الدرجة والنتيجة
A3: رقم التقييم | B3: كود النشاط | C3: موضوع التدريب | D3: كود الموظف | E3: اسم الموظف | F3: تقييم قبلي % | G3: تقييم بعدي % | H3: الدرجة المعتمدة % | I3: النتيجة | J3: المقيّم | K3: تاريخ التقييم | L3: خطة التحسين
A4: 46115 | C4: =IFERROR(VLOOKUP(B4,الخطة!A:O,4,FALSE),"") | E4: =IFERROR(VLOOKUP(D4,الموظفون!A:L,2,FALSE),"") | H4: =IF(G4="","",G4) | I4: =IF(H4="","",IF(H4>=الإعدادات!B7,"ناجح","يحتاج إعادة تدريب"))
A5: 46145 | C5: =IFERROR(VLOOKUP(B5,الخطة!A:O,4,FALSE),"") | E5: =IFERROR(VLOOKUP(D5,الموظفون!A:L,2,FALSE),"") | H5: =IF(G5="","",G5) | I5: =IF(H5="","",IF(H5>=الإعدادات!B7,"ناجح","يحتاج إعادة تدريب"))
A6: 46176 | C6: =IFERROR(VLOOKUP(B6,الخطة!A:O,4,FALSE),"") | E6: =IFERROR(VLOOKUP(D6,الموظفون!A:L,2,FALSE),"") | H6: =IF(G6="","",G6) | I6: =IF(H6="","",IF(H6>=الإعدادات!B7,"ناجح","يحتاج إعادة تدريب"))
A7: 46206 | C7: =IFERROR(VLOOKUP(B7,الخطة!A:O,4,FALSE),"") | E7: =IFERROR(VLOOKUP(D7,الموظفون!A:L,2,FALSE),"") | H7: =IF(G7="","",G7) | I7: =IF(H7="","",IF(H7>=الإعدادات!B7,"ناجح","يحتاج إعادة تدريب"))
A8: 46237 | C8: =IFERROR(VLOOKUP(B8,الخطة!A:O,4,FALSE),"") | E8: =IFERROR(VLOOKUP(D8,الموظفون!A:L,2,FALSE),"") | H8: =IF(G8="","",G8) | I8: =IF(H8="","",IF(H8>=الإعدادات!B7,"ناجح","يحتاج إعادة تدريب"))
A9: 46268 | C9: =IFERROR(VLOOKUP(B9,الخطة!A:O,4,FALSE),"") | E9: =IFERROR(VLOOKUP(D9,الموظفون!A:L,2,FALSE),"") | H9: =IF(G9="","",G9) | I9: =IF(H9="","",IF(H9>=الإعدادات!B7,"ناجح","يحتاج إعادة تدريب"))
A10: 46298 | C10: =IFERROR(VLOOKUP(B10,الخطة!A:O,4,FALSE),"") | E10: =IFERROR(VLOOKUP(D10,الموظفون!A:L,2,FALSE),"") | H10: =IF(G10="","",G10) | I10: =IF(H10="","",IF(H10>=الإعدادات!B7,"ناجح","يحتاج إعادة تدريب"))
A11: 46329 | C11: =IFERROR(VLOOKUP(B11,الخطة!A:O,4,FALSE),"") | E11: =IFERROR(VLOOKUP(D11,الموظفون!A:L,2,FALSE),"") | H11: =IF(G11="","",G11) | I11: =IF(H11="","",IF(H11>=الإعدادات!B7,"ناجح","يحتاج إعادة تدريب"))
A12: 46359 | C12: =IFERROR(VLOOKUP(B12,الخطة!A:O,4,FALSE),"") | E12: =IFERROR(VLOOKUP(D12,الموظفون!A:L,2,FALSE),"") | H12: =IF(G12="","",G12) | I12: =IF(H12="","",IF(H12>=الإعدادات!B7,"ناجح","يحتاج إعادة تدريب"))
A13: 13-3 | C13: =IFERROR(VLOOKUP(B13,الخطة!A:O,4,FALSE),"") | E13: =IFERROR(VLOOKUP(D13,الموظفون!A:L,2,FALSE),"") | H13: =IF(G13="","",G13) | I13: =IF(H13="","",IF(H13>=الإعدادات!B7,"ناجح","يحتاج إعادة تدريب"))
A14: 14-3 | C14: =IFERROR(VLOOKUP(B14,الخطة!A:O,4,FALSE),"") | E14: =IFERROR(VLOOKUP(D14,الموظفون!A:L,2,FALSE),"") | H14: =IF(G14="","",G14) | I14: =IF(H14="","",IF(H14>=الإعدادات!B7,"ناجح","يحتاج إعادة تدريب"))
A15: 15-3 | C15: =IFERROR(VLOOKUP(B15,الخطة!A:O,4,FALSE),"") | E15: =IFERROR(VLOOKUP(D15,الموظفون!A:L,2,FALSE),"") | H15: =IF(G15="","",G15) | I15: =IF(H15="","",IF(H15>=الإعدادات!B7,"ناجح","يحتاج إعادة تدريب"))
A16: 16-3 | C16: =IFERROR(VLOOKUP(B16,الخطة!A:O,4,FALSE),"") | E16: =IFERROR(VLOOKUP(D16,الموظفون!A:L,2,FALSE),"") | H16: =IF(G16="","",G16) | I16: =IF(H16="","",IF(H16>=الإعدادات!B7,"ناجح","يحتاج إعادة تدريب"))
A17: 17-3 | C17: =IFERROR(VLOOKUP(B17,الخطة!A:O,4,FALSE),"") | E17: =IFERROR(VLOOKUP(D17,الموظفون!A:L,2,FALSE),"") | H17: =IF(G17="","",G17) | I17: =IF(H17="","",IF(H17>=الإعدادات!B7,"ناجح","يحتاج إعادة تدريب"))
A18: 18-3 | C18: =IFERROR(VLOOKUP(B18,الخطة!A:O,4,FALSE),"") | E18: =IFERROR(VLOOKUP(D18,الموظفون!A:L,2,FALSE),"") | H18: =IF(G18="","",G18) | I18: =IF(H18="","",IF(H18>=الإعدادات!B7,"ناجح","يحتاج إعادة تدريب"))
A19: 19-3 | C19: =IFERROR(VLOOKUP(B19,الخطة!A:O,4,FALSE),"") | E19: =IFERROR(VLOOKUP(D19,الموظفون!A:L,2,FALSE),"") | H19: =IF(G19="","",G19) | I19: =IF(H19="","",IF(H19>=الإعدادات!B7,"ناجح","يحتاج إعادة تدريب"))
A20: 20-3 | C20: =IFERROR(VLOOKUP(B20,الخطة!A:O,4,FALSE),"") | E20: =IFERROR(VLOOKUP(D20,الموظفون!A:L,2,FALSE),"") | H20: =IF(G20="","",G20) | I20: =IF(H20="","",IF(H20>=الإعدادات!B7,"ناجح","يحتاج إعادة تدريب"))
A21: 21-3 | C21: =IFERROR(VLOOKUP(B21,الخطة!A:O,4,FALSE),"") | E21: =IFERROR(VLOOKUP(D21,الموظفون!A:L,2,FALSE),"") | H21: =IF(G21="","",G21) | I21: =IF(H21="","",IF(H21>=الإعدادات!B7,"ناجح","يحتاج إعادة تدريب"))
A22: 22-3 | C22: =IFERROR(VLOOKUP(B22,الخطة!A:O,4,FALSE),"") | E22: =IFERROR(VLOOKUP(D22,الموظفون!A:L,2,FALSE),"") | H22: =IF(G22="","",G22) | I22: =IF(H22="","",IF(H22>=الإعدادات!B7,"ناجح","يحتاج إعادة تدريب"))
A23: 23-3 | C23: =IFERROR(VLOOKUP(B23,الخطة!A:O,4,FALSE),"") | E23: =IFERROR(VLOOKUP(D23,الموظفون!A:L,2,FALSE),"") | H23: =IF(G23="","",G23) | I23: =IF(H23="","",IF(H23>=الإعدادات!B7,"ناجح","يحتاج إعادة تدريب"))
A24: 24-3 | C24: =IFERROR(VLOOKUP(B24,الخطة!A:O,4,FALSE),"") | E24: =IFERROR(VLOOKUP(D24,الموظفون!A:L,2,FALSE),"") | H24: =IF(G24="","",G24) | I24: =IF(H24="","",IF(H24>=الإعدادات!B7,"ناجح","يحتاج إعادة تدريب"))
A25: 25-3 | C25: =IFERROR(VLOOKUP(B25,الخطة!A:O,4,FALSE),"") | E25: =IFERROR(VLOOKUP(D25,الموظفون!A:L,2,FALSE),"") | H25: =IF(G25="","",G25) | I25: =IF(H25="","",IF(H25>=الإعدادات!B7,"ناجح","يحتاج إعادة تدريب"))
A26: 26-3 | C26: =IFERROR(VLOOKUP(B26,الخطة!A:O,4,FALSE),"") | E26: =IFERROR(VLOOKUP(D26,الموظفون!A:L,2,FALSE),"") | H26: =IF(G26="","",G26) | I26: =IF(H26="","",IF(H26>=الإعدادات!B7,"ناجح","يحتاج إعادة تدريب"))
A27: 27-3 | C27: =IFERROR(VLOOKUP(B27,الخطة!A:O,4,FALSE),"") | E27: =IFERROR(VLOOKUP(D27,الموظفون!A:L,2,FALSE),"") | H27: =IF(G27="","",G27) | I27: =IF(H27="","",IF(H27>=الإعدادات!B7,"ناجح","يحتاج إعادة تدريب"))
A28: 28-3 | C28: =IFERROR(VLOOKUP(B28,الخطة!A:O,4,FALSE),"") | E28: =IFERROR(VLOOKUP(D28,الموظفون!A:L,2,FALSE),"") | H28: =IF(G28="","",G28) | I28: =IF(H28="","",IF(H28>=الإعدادات!B7,"ناجح","يحتاج إعادة تدريب"))
A29: 29-3 | C29: =IFERROR(VLOOKUP(B29,الخطة!A:O,4,FALSE),"") | E29: =IFERROR(VLOOKUP(D29,الموظفون!A:L,2,FALSE),"") | H29: =IF(G29="","",G29) | I29: =IF(H29="","",IF(H29>=الإعدادات!B7,"ناجح","يحتاج إعادة تدريب"))
A30: 30-3 | C30: =IFERROR(VLOOKUP(B30,الخطة!A:O,4,FALSE),"") | E30: =IFERROR(VLOOKUP(D30,الموظفون!A:L,2,FALSE),"") | H30: =IF(G30="","",G30) | I30: =IF(H30="","",IF(H30>=الإعدادات!B7,"ناجح","يحتاج إعادة تدريب"))
A31: 31-3 | C31: =IFERROR(VLOOKUP(B31,الخطة!A:O,4,FALSE),"") | E31: =IFERROR(VLOOKUP(D31,الموظفون!A:L,2,FALSE),"") | H31: =IF(G31="","",G31) | I31: =IF(H31="","",IF(H31>=الإعدادات!B7,"ناجح","يحتاج إعادة تدريب"))
A32: 32-3 | C32: =IFERROR(VLOOKUP(B32,الخطة!A:O,4,FALSE),"") | E32: =IFERROR(VLOOKUP(D32,الموظفون!A:L,2,FALSE),"") | H32: =IF(G32="","",G32) | I32: =IF(H32="","",IF(H32>=الإعدادات!B7,"ناجح","يحتاج إعادة تدريب"))
A33: 33-3 | C33: =IFERROR(VLOOKUP(B33,الخطة!A:O,4,FALSE),"") | E33: =IFERROR(VLOOKUP(D33,الموظفون!A:L,2,FALSE),"") | H33: =IF(G33="","",G33) | I33: =IF(H33="","",IF(H33>=الإعدادات!B7,"ناجح","يحتاج إعادة تدريب"))
A34: 34-3 | C34: =IFERROR(VLOOKUP(B34,الخطة!A:O,4,FALSE),"") | E34: =IFERROR(VLOOKUP(D34,الموظفون!A:L,2,FALSE),"") | H34: =IF(G34="","",G34) | I34: =IF(H34="","",IF(H34>=الإعدادات!B7,"ناجح","يحتاج إعادة تدريب"))
A35: 35-3 | C35: =IFERROR(VLOOKUP(B35,الخطة!A:O,4,FALSE),"") | E35: =IFERROR(VLOOKUP(D35,الموظفون!A:L,2,FALSE),"") | H35: =IF(G35="","",G35) | I35: =IF(H35="","",IF(H35>=الإعدادات!B7,"ناجح","يحتاج إعادة تدريب"))
A36: 36-3 | C36: =IFERROR(VLOOKUP(B36,الخطة!A:O,4,FALSE),"") | E36: =IFERROR(VLOOKUP(D36,الموظفون!A:L,2,FALSE),"") | H36: =IF(G36="","",G36) | I36: =IF(H36="","",IF(H36>=الإعدادات!B7,"ناجح","يحتاج إعادة تدريب"))
A37: 37-3 | C37: =IFERROR(VLOOKUP(B37,الخطة!A:O,4,FALSE),"") | E37: =IFERROR(VLOOKUP(D37,الموظفون!A:L,2,FALSE),"") | H37: =IF(G37="","",G37) | I37: =IF(H37="","",IF(H37>=الإعدادات!B7,"ناجح","يحتاج إعادة تدريب"))
A38: 38-3 | C38: =IFERROR(VLOOKUP(B38,الخطة!A:O,4,FALSE),"") | E38: =IFERROR(VLOOKUP(D38,الموظفون!A:L,2,FALSE),"") | H38: =IF(G38="","",G38) | I38: =IF(H38="","",IF(H38>=الإعدادات!B7,"ناجح","يحتاج إعادة تدريب"))
A39: 39-3 | C39: =IFERROR(VLOOKUP(B39,الخطة!A:O,4,FALSE),"") | E39: =IFERROR(VLOOKUP(D39,الموظفون!A:L,2,FALSE),"") | H39: =IF(G39="","",G39) | I39: =IF(H39="","",IF(H39>=الإعدادات!B7,"ناجح","يحتاج إعادة تدريب"))
A40: 40-3 | C40: =IFERROR(VLOOKUP(B40,الخطة!A:O,4,FALSE),"") | E40: =IFERROR(VLOOKUP(D40,الموظفون!A:L,2,FALSE),"") | H40: =IF(G40="","",G40) | I40: =IF(H40="","",IF(H40>=الإعدادات!B7,"ناجح","يحتاج إعادة تدريب"))
A41: 41-3 | C41: =IFERROR(VLOOKUP(B41,الخطة!A:O,4,FALSE),"") | E41: =IFERROR(VLOOKUP(D41,الموظفون!A:L,2,FALSE),"") | H41: =IF(G41="","",G41) | I41: =IF(H41="","",IF(H41>=الإعدادات!B7,"ناجح","يحتاج إعادة تدريب"))
...

Sheet الحضور
A1: سجل الحضور المركزي - أدخل البيانات هنا
A3: رقم السجل | B3: كود النشاط | C3: موضوع التدريب | D3: كود الموظف | E3: اسم الموظف | F3: حضر؟ | G3: وقت الحضور | H3: التوقيع/الإثبات | I3: المدرب | J3: التاريخ | K3: حالة السجل | L3: ملاحظات
A4: 46115 | C4: =IFERROR(VLOOKUP(B4,الخطة!A:O,4,FALSE),"") | E4: =IFERROR(VLOOKUP(D4,الموظفون!A:L,2,FALSE),"") | K4: =IF(B4="","",IF(OR(D4="",F4=""),"ناقص بيانات",IF(F4="نعم","مكتمل","غائب")))
A5: 46145 | C5: =IFERROR(VLOOKUP(B5,الخطة!A:O,4,FALSE),"") | E5: =IFERROR(VLOOKUP(D5,الموظفون!A:L,2,FALSE),"") | K5: =IF(B5="","",IF(OR(D5="",F5=""),"ناقص بيانات",IF(F5="نعم","مكتمل","غائب")))
A6: 46176 | C6: =IFERROR(VLOOKUP(B6,الخطة!A:O,4,FALSE),"") | E6: =IFERROR(VLOOKUP(D6,الموظفون!A:L,2,FALSE),"") | K6: =IF(B6="","",IF(OR(D6="",F6=""),"ناقص بيانات",IF(F6="نعم","مكتمل","غائب")))
A7: 46206 | C7: =IFERROR(VLOOKUP(B7,الخطة!A:O,4,FALSE),"") | E7: =IFERROR(VLOOKUP(D7,الموظفون!A:L,2,FALSE),"") | K7: =IF(B7="","",IF(OR(D7="",F7=""),"ناقص بيانات",IF(F7="نعم","مكتمل","غائب")))
A8: 46237 | C8: =IFERROR(VLOOKUP(B8,الخطة!A:O,4,FALSE),"") | E8: =IFERROR(VLOOKUP(D8,الموظفون!A:L,2,FALSE),"") | K8: =IF(B8="","",IF(OR(D8="",F8=""),"ناقص بيانات",IF(F8="نعم","مكتمل","غائب")))
A9: 46268 | C9: =IFERROR(VLOOKUP(B9,الخطة!A:O,4,FALSE),"") | E9: =IFERROR(VLOOKUP(D9,الموظفون!A:L,2,FALSE),"") | K9: =IF(B9="","",IF(OR(D9="",F9=""),"ناقص بيانات",IF(F9="نعم","مكتمل","غائب")))
A10: 46298 | C10: =IFERROR(VLOOKUP(B10,الخطة!A:O,4,FALSE),"") | E10: =IFERROR(VLOOKUP(D10,الموظفون!A:L,2,FALSE),"") | K10: =IF(B10="","",IF(OR(D10="",F10=""),"ناقص بيانات",IF(F10="نعم","مكتمل","غائب")))
A11: 46329 | C11: =IFERROR(VLOOKUP(B11,الخطة!A:O,4,FALSE),"") | E11: =IFERROR(VLOOKUP(D11,الموظفون!A:L,2,FALSE),"") | K11: =IF(B11="","",IF(OR(D11="",F11=""),"ناقص بيانات",IF(F11="نعم","مكتمل","غائب")))
A12: 46359 | C12: =IFERROR(VLOOKUP(B12,الخطة!A:O,4,FALSE),"") | E12: =IFERROR(VLOOKUP(D12,الموظفون!A:L,2,FALSE),"") | K12: =IF(B12="","",IF(OR(D12="",F12=""),"ناقص بيانات",IF(F12="نعم","مكتمل","غائب")))
A13: 13-3 | C13: =IFERROR(VLOOKUP(B13,الخطة!A:O,4,FALSE),"") | E13: =IFERROR(VLOOKUP(D13,الموظفون!A:L,2,FALSE),"") | K13: =IF(B13="","",IF(OR(D13="",F13=""),"ناقص بيانات",IF(F13="نعم","مكتمل","غائب")))
A14: 14-3 | C14: =IFERROR(VLOOKUP(B14,الخطة!A:O,4,FALSE),"") | E14: =IFERROR(VLOOKUP(D14,الموظفون!A:L,2,FALSE),"") | K14: =IF(B14="","",IF(OR(D14="",F14=""),"ناقص بيانات",IF(F14="نعم","مكتمل","غائب")))
A15: 15-3 | C15: =IFERROR(VLOOKUP(B15,الخطة!A:O,4,FALSE),"") | E15: =IFERROR(VLOOKUP(D15,الموظفون!A:L,2,FALSE),"") | K15: =IF(B15="","",IF(OR(D15="",F15=""),"ناقص بيانات",IF(F15="نعم","مكتمل","غائب")))
A16: 16-3 | C16: =IFERROR(VLOOKUP(B16,الخطة!A:O,4,FALSE),"") | E16: =IFERROR(VLOOKUP(D16,الموظفون!A:L,2,FALSE),"") | K16: =IF(B16="","",IF(OR(D16="",F16=""),"ناقص بيانات",IF(F16="نعم","مكتمل","غائب")))
A17: 17-3 | C17: =IFERROR(VLOOKUP(B17,الخطة!A:O,4,FALSE),"") | E17: =IFERROR(VLOOKUP(D17,الموظفون!A:L,2,FALSE),"") | K17: =IF(B17="","",IF(OR(D17="",F17=""),"ناقص بيانات",IF(F17="نعم","مكتمل","غائب")))
A18: 18-3 | C18: =IFERROR(VLOOKUP(B18,الخطة!A:O,4,FALSE),"") | E18: =IFERROR(VLOOKUP(D18,الموظفون!A:L,2,FALSE),"") | K18: =IF(B18="","",IF(OR(D18="",F18=""),"ناقص بيانات",IF(F18="نعم","مكتمل","غائب")))
A19: 19-3 | C19: =IFERROR(VLOOKUP(B19,الخطة!A:O,4,FALSE),"") | E19: =IFERROR(VLOOKUP(D19,الموظفون!A:L,2,FALSE),"") | K19: =IF(B19="","",IF(OR(D19="",F19=""),"ناقص بيانات",IF(F19="نعم","مكتمل","غائب")))
A20: 20-3 | C20: =IFERROR(VLOOKUP(B20,الخطة!A:O,4,FALSE),"") | E20: =IFERROR(VLOOKUP(D20,الموظفون!A:L,2,FALSE),"") | K20: =IF(B20="","",IF(OR(D20="",F20=""),"ناقص بيانات",IF(F20="نعم","مكتمل","غائب")))
A21: 21-3 | C21: =IFERROR(VLOOKUP(B21,الخطة!A:O,4,FALSE),"") | E21: =IFERROR(VLOOKUP(D21,الموظفون!A:L,2,FALSE),"") | K21: =IF(B21="","",IF(OR(D21="",F21=""),"ناقص بيانات",IF(F21="نعم","مكتمل","غائب")))
A22: 22-3 | C22: =IFERROR(VLOOKUP(B22,الخطة!A:O,4,FALSE),"") | E22: =IFERROR(VLOOKUP(D22,الموظفون!A:L,2,FALSE),"") | K22: =IF(B22="","",IF(OR(D22="",F22=""),"ناقص بيانات",IF(F22="نعم","مكتمل","غائب")))
A23: 23-3 | C23: =IFERROR(VLOOKUP(B23,الخطة!A:O,4,FALSE),"") | E23: =IFERROR(VLOOKUP(D23,الموظفون!A:L,2,FALSE),"") | K23: =IF(B23="","",IF(OR(D23="",F23=""),"ناقص بيانات",IF(F23="نعم","مكتمل","غائب")))
A24: 24-3 | C24: =IFERROR(VLOOKUP(B24,الخطة!A:O,4,FALSE),"") | E24: =IFERROR(VLOOKUP(D24,الموظفون!A:L,2,FALSE),"") | K24: =IF(B24="","",IF(OR(D24="",F24=""),"ناقص بيانات",IF(F24="نعم","مكتمل","غائب")))
... A503: 503-3 | C503: =IFERROR(VLOOKUP(B503,الخطة!A:O,4,FALSE),"") | E503: =IFERROR(VLOOKUP(D503,الموظفون!A:L,2,FALSE),"") | K503: =IF(B503="","",IF(OR(D503="",F503=""),"ناقص بيانات",IF(F503="نعم","مكتمل","غائب")))

Sheet الخطة
A1: الخطة السنوية للتدريب
A3: كود النشاط | B3: الشهر | C3: محور GAHAR | D3: موضوع التدريب | E3: الفئة المستهدفة | F3: الهدف والكفاءة | G3: نوع التدريب | H3: المسؤول | I3: الساعات | J3: التاريخ المخطط | K3: التاريخ المنفذ | L3: الحالة | M3: عدد الحضور | N3: متوسط التقييم | O3: رابط الدليل
A4: TR-001 | B4: يناير | C4: HRP / GLD | D4: التعريف بالمنشأة وحقوق وواجبات العاملين | E4: جميع العاملين | F4: فهم السياسات ومدونة السلوك وقنوات الإبلاغ | G4: تعريفي | H4: الموارد البشرية | I4: 3 | J4: 15/01 | L4: مخطط | M4: =IF(A4="","",COUNTIFS([1]الحضور!B:B,A4,[1]الحضور!F:F,"نعم")) -> #VALUE! | N4: =IFERROR(AVERAGEIF([2]التقييمات!B:B,A4,[2]التقييمات!H:H),"")
A5: TR-002 | B5: فبراير | C5: IPC | D5: الوقاية من العدوى ومكافحة العدوى | E5: السريريون والخدمات المعاونة | F5: تطبيق نظافة اليدين ومعدات الوقاية والعزل | G5: عملي | H5: فريق مكافحة العدوى | I5: 4 | J5: 46358 | L5: مخطط | M5: =IF(A5="","",COUNTIFS([1]الحضور!B:B,A5,[1]الحضور!F:F,"نعم")) -> #VALUE! | N5: =IFERROR(AVERAGEIF([2]التقييمات!B:B,A5,[2]التقييمات!H:H),"")
A6: TR-003 | B6: مارس | C6: MMU | D6: سلامة الدواء والإبلاغ عن الأخطاء | E6: الأطباء والتمريض والصيدلة | F6: تطبيق التحقق الآمن من الدواء والإبلاغ | G6: محاكاة | H6: مدير الصيدلية | I6: 3 | J6: 46298 | L6: مخطط | M6: =IF(A6="","",COUNTIFS([1]الحضور!B:B,A6,[1]الحضور!F:F,"نعم")) -> #VALUE! | N6: =IFERROR(AVERAGEIF([2]التقييمات!B:B,A6,[2]التقييمات!H:H),"")
A7: TR-004 | B7: مارس | C7: FMS | D7: السلامة من الحريق والإخلاء | E7: جميع العاملين | F7: تنفيذ الإنذار والإخلاء واستخدام الطفاية | G7: تمرين | H7: السلامة المهنية | I7: 3 | J7: 24/03 | L7: مخطط | M7: =IF(A7="","",COUNTIFS([1]الحضور!B:B,A7,[1]الحضور!F:F,"نعم")) -> #VALUE! | N7: =IFERROR(AVERAGEIF([2]التقييمات!B:B,A7,[2]التقييمات!H:H),"")
A8: TR-005 | B8: مايو | C8: QPS | D8: سلامة المريض والتحسين المستمر | E8: قادة الوحدات والجودة | F8: تحليل السبب الجذري وبناء خطة PDSA | G8: دراسة حالة | H8: إدارة الجودة | I8: 3 | J8: 46361 | L8: مخطط | M8: =IF(A8="","",COUNTIFS([1]الحضور!B:B,A8,[1]الحضور!F:F,"نعم")) -> #VALUE! | N8: =IFERROR(AVERAGEIF([2]التقييمات!B:B,A8,[2]التقييمات!H:H),"")
A9: TR-006 | B9: يونيو | C9: HIS | D9: التوثيق الطبي وسرية المعلومات | E9: الأطباء والتمريض والسجلات | F9: تسجيل دقيق وحماية البيانات والصلاحيات | G9: تطبيقي | H9: السجلات الطبية | I9: 3 | J9: 16/06 | L9: مخطط | M9: =IF(A9="","",COUNTIFS([1]الحضور!B:B,A9,[1]الحضور!F:F,"نعم")) -> #VALUE! | N9: =IFERROR(AVERAGEIF([2]التقييمات!B:B,A9,[2]التقييمات!H:H),"")
A10: TR-007 | B10: يوليو | C10: AOP / COP | D10: التقييم الأولي والتصعيد السريري | E10: الأطباء والتمريض والاستقبال | F10: اكتشاف التدهور والتواصل المنظم SBAR | G10: محاكاة | H10: الإدارة الطبية | I10: 4 | J10: 14/07 | L10: مخطط | M10: =IF(A10="","",COUNTIFS([1]الحضور!B:B,A10,[1]الحضور!F:F,"نعم")) -> #VALUE! | N10: =IFERROR(AVERAGEIF([2]التقييمات!B:B,A10,[2]التقييمات!H:H),"")
A11: TR-008 | B11: سبتمبر | C11: PFR / QPS | D11: تجربة المريض والشكاوى | E11: الاستقبال وخدمة العملاء | F11: استقبال الشكوى والرد والتحسين | G11: لعب أدوار | H11: خدمة العملاء | I11: 2 | J11: 15/09 | L11: مخطط | M11: =IF(A11="","",COUNTIFS([1]الحضور!B:B,A11,[1]الحضور!F:F,"نعم")) -> #VALUE! | N11: =IFERROR(AVERAGEIF([2]التقييمات!B:B,A11,[2]التقييمات!H:H),"")
A12: TR-009 | B12: أكتوبر | C12: HRP | D12: تقييم الكفاءة وإعادة التأهيل | E12: جميع الفئات | F12: إثبات الكفاءة وتحديد فجوات الأداء | G12: تقييم عملي | H12: الموارد البشرية | I12: 4 | J12: 13/10 | L12: مخطط | M12: =IF(A12="","",COUNTIFS([1]الحضور!B:B,A12,[1]الحضور!F:F,"نعم")) -> #VALUE! | N12: =IFERROR(AVERAGEIF([2]التقييمات!B:B,A12,[2]التقييمات!H:H),"")
A13: TR-010 | B13: نوفمبر | C13: GLD / QPS | D13: إدارة الأزمات واستمرارية الأعمال | E13: لجنة الطوارئ وقادة الوحدات | F13: تنفيذ الاستجابة واستمرارية الخدمات | G13: تمرين مكتبي | H13: إدارة المنشأة | I13: 3 | J13: 17/11 | L13: مخطط | M13: =IF(A13="","",COUNTIFS([1]الحضور!B:B,A13,[1]الحضور!F:F,"نعم")) -> #VALUE! | N13: =IFERROR(AVERAGEIF([2]التقييمات!B:B,A13,[2]التقييمات!H:H),"")
A14: TR-011 | B14: ديسمبر | C14: QPS / HRP | D14: المراجعة السنوية وخطة العام القادم | E14: الإدارة ورؤساء الأقسام | F14: تحليل مؤشرات التدريب وخطة التحسين | G14: مراجعة | H14: الجودة والموارد البشرية | I14: 3 | J14: 46246 | L14: مخطط | M14: =IF(A14="","",COUNTIFS([1]الحضور!B:B,A14,[1]الحضور!F:F,"نعم")) -> #VALUE! | N14: =IFERROR(AVERAGEIF([2]التقييمات!B:B,A14,[2]التقييمات!H:H),"")
M15: =IF(A15="","",COUNTIFS([1]الحضور!B:B,A15,[1]الحضور!F:F,"نعم")) | N15: =IFERROR(AVERAGEIF([2]التقييمات!B:B,A15,[2]التقييمات!H:H),"")
M16: =IF(A16="","",COUNTIFS([1]الحضور!B:B,A16,[1]الحضور!F:F,"نعم")) | N16: =IFERROR(AVERAGEIF([2]التقييمات!B:B,A16,[2]التقييمات!H:H),"")
M17: =IF(A17="","",COUNTIFS([1]الحضور!B:B,A17,[1]الحضور!F:F,"نعم")) | N17: =IFERROR(AVERAGEIF([2]التقييمات!B:B,A17,[2]التقييمات!H:H),"")
M18: =IF(A18="","",COUNTIFS([1]الحضور!B:B,A18,[1]الحضور!F:F,"نعم")) | N18: =IFERROR(AVERAGEIF([2]التقييمات!B:B,A18,[2]التقييمات!H:H),"")
M19: =IF(A19="","",COUNTIFS([1]الحضور!B:B,A19,[1]الحضور!F:F,"نعم")) | N19: =IFERROR(AVERAGEIF([2]التقييمات!B:B,A19,[2]التقييمات!H:H),"")
M20: =IF(A20="","",COUNTIFS([1]الحضور!B:B,A20,[1]الحضور!F:F,"نعم")) | N20: =IFERROR(AVERAGEIF([2]التقييمات!B:B,A20,[2]التقييمات!H:H),"")
M21: =IF(A21="","",COUNTIFS([1]الحضور!B:B,A21,[1]الحضور!F:F,"نعم")) | N21: =IFERROR(AVERAGEIF([2]التقييمات!B:B,A21,[2]التقييمات!H:H),"")
M22: =IF(A22="","",COUNTIFS([1]الحضور!B:B,A22,[1]الحضور!F:F,"نعم")) | N22: =IFERROR(AVERAGEIF([2]التقييمات!B:B,A22,[2]التقييمات!H:H),"")
M23: =IF(A23="","",COUNTIFS([1]الحضور!B:B,A23,[1]الحضور!F:F,"نعم")) | N23: =IFERROR(AVERAGEIF([2]التقييمات!B:B,A23,[2]التقييمات!H:H),"")
M24: =IF(A24="","",COUNTIFS([1]الحضور!B:B,A24,[1]الحضور!F:F,"نعم")) | N24: =IFERROR(AVERAGEIF([2]التقييمات!B:B,A24,[2]التقييمات!H:H),"")
M25: =IF(A25="","",COUNTIFS([1]الحضور!B:B,A25,[1]الحضور!F:F,"نعم")) | N25: =IFERROR(AVERAGEIF([2]التقييمات!B:B,A25,[2]التقييمات!H:H),"")
M26: =IF(A26="","",COUNTIFS([1]الحضور!B:B,A26,[1]الحضور!F:F,"نعم")) | N26: =IFERROR(AVERAGEIF([2]التقييمات!B:B,A26,[2]التقييمات!H:H),"")
... M103: =IF(A103="","",COUNTIFS([1]الحضور!B:B,A103,[1]الحضور!F:F,"نعم")) | N103: =IFERROR(AVERAGEIF([2]التقييمات!B:B,A103,[2]التقييمات!H:H),"")

Sheet الموظفون
A1: قاعدة بيانات الموظفين
A3: كود الموظف | B3: اسم الموظف | C3: القسم | D3: المسمى الوظيفي | E3: نوع التعاقد | F3: تاريخ التعيين | G3: حالة الموظف | H3: المدير المباشر | I3: الهاتف/البريد | J3: عدد الأنشطة | K3: نسبة الإكمال | L3: ملاحظات
A4: EMP-001 | B4: أحمد محمد | C4: التمريض | D4: ممرض/ة | E4: دوام كامل | F4: 45658 | G4: نشط | H4: رئيس التمريض | J4: =COUNTIF([1]الحضور!D:D,A4) -> #VALUE! | K4: =IFERROR(COUNTIFS([1]الحضور!D:D,A4,[1]الحضور!F:F,"نعم")/J4,0) -> 0
A5: EMP-002 | B5: سارة علي | C5: الصيدلية | D5: صيدلي | E5: دوام كامل | F5: 15/02/2025 | G5: نشط | H5: مدير الصيدلية | J5: =COUNTIF([1]الحضور!D:D,A5) -> #VALUE! | K5: =IFERROR(COUNTIFS([1]الحضور!D:D,A5,[1]الحضور!F:F,"نعم")/J5,0) -> 0
A6: EMP-003 | B6: محمود حسن | C6: الاستقبال | D6: موظف استقبال | E6: دوام كامل | F6: 45933 | G6: نشط | H6: مدير خدمة العملاء | J6: =COUNTIF([1]الحضور!D:D,A6) -> #VALUE! | K6: =IFERROR(COUNTIFS([1]الحضور!D:D,A6,[1]الحضور!F:F,"نعم")/J6,0) -> 0
J7: =IF(A7="","",COUNTIF([1]الحضور!D:D,A7)) | K7: =IFERROR(COUNTIFS([1]الحضور!D:D,A7,[1]الحضور!F:F,"نعم")/J7,0) -> 0
J8: =IF(A8="","",COUNTIF([1]الحضور!D:D,A8)) | K8: =IFERROR(COUNTIFS([1]الحضور!D:D,A8,[1]الحضور!F:F,"نعم")/J8,0) -> 0
J9: =IF(A9="","",COUNTIF([1]الحضور!D:D,A9)) | K9: =IFERROR(COUNTIFS([1]الحضور!D:D,A9,[1]الحضور!F:F,"نعم")/J9,0) -> 0
J10: =IF(A10="","",COUNTIF([1]الحضور!D:D,A10)) | K10: =IFERROR(COUNTIFS([1]الحضور!D:D,A10,[1]الحضور!F:F,"نعم")/J10,0) -> 0
J11: =IF(A11="","",COUNTIF([1]الحضور!D:D,A11)) | K11: =IFERROR(COUNTIFS([1]الحضور!D:D,A11,[1]الحضور!F:F,"نعم")/J11,0) -> 0
J12: =IF(A12="","",COUNTIF([1]الحضور!D:D,A12)) | K12: =IFERROR(COUNTIFS([1]الحضور!D:D,A12,[1]الحضور!F:F,"نعم")/J12,0) -> 0
J13: =IF(A13="","",COUNTIF([1]الحضور!D:D,A13)) | K13: =IFERROR(COUNTIFS([1]الحضور!D:D,A13,[1]الحضور!F:F,"نعم")/J13,0) -> 0
J14: =IF(A14="","",COUNTIF([1]الحضور!D:D,A14)) | K14: =IFERROR(COUNTIFS([1]الحضور!D:D,A14,[1]الحضور!F:F,"نعم")/J14,0) -> 0
J15: =IF(A15="","",COUNTIF([1]الحضور!D:D,A15)) | K15: =IFERROR(COUNTIFS([1]الحضور!D:D,A15,[1]الحضور!F:F,"نعم")/J15,0) -> 0
J16: =IF(A16="","",COUNTIF([1]الحضور!D:D,A16)) | K16: =IFERROR(COUNTIFS([1]الحضور!D:D,A16,[1]الحضور!F:F,"نعم")/J16,0) -> 0
J17: =IF(A17="","",COUNTIF([1]الحضور!D:D,A17)) | K17: =IFERROR(COUNTIFS([1]الحضور!D:D,A17,[1]الحضور!F:F,"نعم")/J17,0) -> 0
J18: =IF(A18="","",COUNTIF([1]الحضور!D:D,A18)) | K18: =IFERROR(COUNTIFS([1]الحضور!D:D,A18,[1]الحضور!F:F,"نعم")/J18,0) -> 0
... J103: =IF(A103="","",COUNTIF([1]الحضور!D:D,A103)) | K103: =IFERROR(COUNTIFS([1]الحضور!D:D,A103,[1]الحضور!F:F,"نعم")/J103,0) -> 0

Sheet الإعدادات
A1: نظام خطة التدريب والتقييم المترابط
A3: البند | B3: القيمة
A4: اسم المنشأة | B4: يُستكمل
A5: نوع المنشأة | B5: مستشفى / مركز طبي
A6: سنة الخطة | B6: 2026
A7: حد النجاح % | B7: 70
A8: حد الحضور % | B8: 80
A9: مسؤول التدريب | B9: يُستكمل
A10: ملاحظة | B10: راجع آخر إصدار رسمي من دليل GAHAR ونطاق المنشأة قبل الاعتماد.
