Workbook

Sheet التقرير الشهري الديناميكي
A1: التقرير الشهري التفاعلي للتدريب والأداء
A3: اختر الشهر: | B3: يناير
A5: المؤشر الشهري | B5: القيمة المحققة بالشهر | C5: ملاحظات التقييم الشهري
A6: عدد البرامج المخططة بالشهر | B6: =COUNTIF('الخطة التدريبية المعتمدة'!L:L,B3) -> 3
A7: عدد الجلسات المنفذة بالشهر | B7: =COUNTIFS('جدول الجلسات التدريبية'!D:D,">=2026-01-01",'جدول الجلسات التدريبية'!J:J,"منفذة") -> 2
A8: إجمالي الحضور الفعلي بالشهر | B8: =COUNTIFS('سجل الحضور والتنفيذ'!H:H,"حاضر") -> 4
A9: متوسط درجة الاختبار البعدي بالشهر | B9: =IFERROR(AVERAGE('سجل الحضور والتنفيذ'!J:J),0) -> 7.75
A10: عدد حالات تقييم الكفاءة المنجزة بالشهر | B10: =COUNTIF('مصفوفة التقييم العملي للكفاءة'!I:I,">=2026-01-01") -> 3

Sheet لوحة المؤشرات والقيادة
A1: لوحة المؤشرات التنفيذية والاستراتيجية للتدريب والكفاءة
A3: المؤشر القياسي | B3: القيمة المحققة | C3: المستهدف القياسي | D3: الحالة والتقييم | E3: المصدر والمعادلة | F3: مرجع جهار
A4: إجمالي العاملين المسجلين | B4: =COUNTA('سجل الموظفين والكفاءة'!C4:C203) -> 10 | C4: كل الكادر | D4: مستوفى | E4: شيت الموظفين | F4: WFM.04
A5: نسبة استكمال التقييم السنوي | B5: =COUNTIF('سجل الموظفين والكفاءة'!I:I,"مُقيَّم")/B4 -> 0.9 | C5: 1 | D5: =IF(B5>=C5,"مطابق","غير مطابق - يوجد فجوة") -> غير مطابق - يوجد فجوة | E5: شيت الموظفين | F5: WFM.07
A6: إجمالي البرامج التخصصية بالخطة | B6: =COUNTA('الخطة التدريبية المعتمدة'!A4:A103) -> 20 | C6: حسب الاحتياج | D6: مكتمل | E6: شيت الخطة | F6: WFM.06
A7: نسبة تنفيذ الخطة التدريبية | B7: =COUNTIF('الخطة التدريبية المعتمدة'!R:R,"مستوفى بالكامل")/B6 -> 0 | C7: 0.9 | D7: =IF(B7>=C7,"مطابق","قيد التنفيذ") -> قيد التنفيذ | E7: شيت الخطة | F7: WFM.06
A8: إجمالي سجلات الحضور المنجزة | B8: =COUNTIF('سجل الحضور والتنفيذ'!H:H,"حاضر") -> 4 | C8: حسب المستهدف | D8: مستوفى | E8: شيت الحضور | F8: WFM.06
A9: نسبة الحضور الفعلي بالبرامج | B9: =IFERROR(B8/SUM('الخطة التدريبية المعتمدة'!F4:F103),0) -> 0.08 | C9: 0.85 | D9: =IF(B9>=C9,"مطابق","يحتاج تحسين") -> يحتاج تحسين | E9: شيت الحضور والخطة | F9: WFM.06
A10: متوسط التقييم المعرفي البعدي | B10: =IFERROR(AVERAGE('سجل الحضور والتنفيذ'!J:J)/10,0) -> 0.775 | C10: 0.7 | D10: =IF(B10>=C10,"مطابق ممتاز","يحتاج إعادة اختبار") -> مطابق ممتاز | E10: شيت الحضور | F10: WFM.06
A11: نسبة اجتياز التقييم العملي للمهارة | B11: =IFERROR(COUNTIF('مصفوفة التقييم العملي للكفاءة'!H:H,"كفء ومستوفى عملياً")/COUNTA('مصفوفة التقييم العملي للكفاءة'!A4:A203),0) -> 0.66666667 | C11: 0.8 | D11: =IF(B11>=C11,"مطابق كفء","يوجد حالات إعادة تدريب") -> يوجد حالات إعادة تدريب | E11: شيت الكفاءة العملية | F11: WFM.07
A12: عدد حالات إعادة التدريب الميداني | B12: =COUNTIF('مصفوفة التقييم العملي للكفاءة'!H:H,"غير كفء - يلزم تدريب ميداني إضافي") -> 1 | C12: 0 | D12: =IF(B12=0,"ممتاز - صفر إخفاق","يوجد حالات قيد المعالجة") -> يوجد حالات قيد المعالجة | E12: شيت الكفاءة العملية | F12: WFM.07
A13: نسبة الأدلة المكتملة والمراجعة | B13: =IFERROR(COUNTIF('سجل الأدلة وجاهزية جهار'!H:H,"مكتمل")/COUNTA('سجل الأدلة وجاهزية جهار'!A4:A203),0) -> 0.8 | C13: 1 | D13: =IF(B13>=C13,"جاهز لمسح جهار","غير جاهز لمسح جهار") -> غير جاهز لمسح جهار | E13: شيت الأدلة | F13: WFM.06

Sheet سجل الأدلة وجاهزية جهار
A1: سجل الأدلة والوثائق التدريبية الجاهزة للمراجعة والمسح الميداني
A3: كود الدليل | B3: كود البرنامج | C3: كود الجلسة | D3: نوع الدليل المطلوب | E3: اسم الملف / الرابط الإلكتروني | F3: المسؤول عن الحفظ | G3: تاريخ الحفظ | H3: حالة الدليل | I3: نتيجة مراجعة الجودة | J3: تاريخ المراجعة | K3: ملاحظات فريق المسح
A4: EVD-01 | B4: PSY-OR-01 | C4: SES-2026-01 | D4: وثيقة الخطة المعتمدة والتوجيه التعريفي | E4: Doc_Orientation_2026.pdf | F4: الموارد البشرية | G4: 46038 | H4: مكتمل | I4: معتمد ومطابق | J4: 46040
A5: EVD-02 | B5: PSY-OR-01 | C5: SES-2026-01 | D5: كشف الحضور الأصلي ونماذج التقييم | E5: Att_SES_2026_01.pdf | F5: منسق التدريب | G5: 46038 | H5: مكتمل | I5: معتمد ومطابق | J5: 46040
A6: EVD-03 | B6: PSY-01 | C6: SES-2026-02 | D6: المادة التدريبية واختبارات المعرفة C-SSRS | E6: Material_PSY_01.pdf | F6: إدارة الجودة | G6: 46043 | H6: مكتمل | I6: معتمد ومطابق | J6: 46045
A7: EVD-04 | B7: PSY-01 | C7: SES-2026-02 | D7: استمارات التقييم العملي الميداني لكفاءة الانتحار | E7: Comp_PSY_01_Eval.pdf | F7: المدير الطبي | G7: 46045 | H7: مكتمل | I7: معتمد ومطابق | J7: 46047
A8: EVD-05 | B8: PSY-02 | C8: SES-2026-03 | D8: مادة التدريب وتقرير سيناريو خفض التصعيد | F8: مسؤول السلامة والتمريض | H8: قيد التجميع | I8: تحت المراجعة

Sheet مصفوفة التقييم العملي للكفاءة
A1: مصفوفة التقييم العملي الميداني للكفاءة السريرية والتشغيلية
A3: رقم التقييم | B3: كود الموظف | C3: اسم الموظف | D3: الفئة الوظيفية | E3: اسم الكفاءة الميدانية | F3: البرنامج المرتبط | G3: درجة التقييم العملي % | H3: النتيجة العملية | I3: تاريخ التقييم | J3: المقيم المعتمد | K3: موعد إعادة التقييم | L3: الإجراء التصحيحي عند الإخفاق | M3: رابط نموذج التقييم
A4: CMP-001 | B4: EMP-101 | C4: =IFERROR(VLOOKUP(B4,'سجل الموظفين والكفاءة'!B:C,2,FALSE),"") -> أحمد محمود علي | D4: =IFERROR(VLOOKUP(B4,'سجل الموظفين والكفاءة'!B:E,4,FALSE),"") -> أطباء | E4: تقييم مخاطر الانتحار C-SSRS وتطبيق خطة الأمان | F4: PSY-01 | G4: 0.9 | H4: =IF(G4="","",IF(G4>='الإعدادات والمستهدفات'!B6,"كفء ومستوفى عملياً","غير كفء - يلزم تدريب ميداني إضافي")) -> كفء ومستوفى عملياً | I4: 46044 | J4: استشاري الطب النفسي | K4: =IF(G4="","",IF(G4<'الإعدادات والمستهدفات'!B6,I4+14,"—")) -> — | L4: =IF(G4="","",IF(G4<'الإعدادات والمستهدفات'!B6,"إعادة تدريب ميداني خلال 14 يوم ومراجعة مع المشرف","لا يوجد")) -> لا يوجد
A5: CMP-002 | B5: EMP-103 | C5: =IFERROR(VLOOKUP(B5,'سجل الموظفين والكفاءة'!B:C,2,FALSE),"") -> محمد حسن عبدالرحمن | D5: =IFERROR(VLOOKUP(B5,'سجل الموظفين والكفاءة'!B:E,4,FALSE),"") -> تمريض | E5: تقييم مخاطر الانتحار C-SSRS وتطبيق خطة الأمان | F5: PSY-01 | G5: 0.85 | H5: =IF(G5="","",IF(G5>='الإعدادات والمستهدفات'!B6,"كفء ومستوفى عملياً","غير كفء - يلزم تدريب ميداني إضافي")) -> كفء ومستوفى عملياً | I5: 46044 | J5: استشاري الطب النفسي | K5: =IF(G5="","",IF(G5<'الإعدادات والمستهدفات'!B6,I5+14,"—")) -> — | L5: =IF(G5="","",IF(G5<'الإعدادات والمستهدفات'!B6,"إعادة تدريب ميداني خلال 14 يوم ومراجعة مع المشرف","لا يوجد")) -> لا يوجد
A6: CMP-003 | B6: EMP-104 | C6: =IFERROR(VLOOKUP(B6,'سجل الموظفين والكفاءة'!B:C,2,FALSE),"") -> سارة خالد مصطفى | D6: =IFERROR(VLOOKUP(B6,'سجل الموظفين والكفاءة'!B:E,4,FALSE),"") -> تمريض | E6: تقنيات خفض التصعيد والسيطرة الآمنة De-escalation | F6: PSY-02 | G6: 0.65 | H6: =IF(G6="","",IF(G6>='الإعدادات والمستهدفات'!B6,"كفء ومستوفى عملياً","غير كفء - يلزم تدريب ميداني إضافي")) -> غير كفء - يلزم تدريب ميداني إضافي | I6: 46048 | J6: رئيس التمريض | K6: =IF(G6="","",IF(G6<'الإعدادات والمستهدفات'!B6,I6+14,"—")) -> 46062 | L6: =IF(G6="","",IF(G6<'الإعدادات والمستهدفات'!B6,"إعادة تدريب ميداني خلال 14 يوم ومراجعة مع المشرف","لا يوجد")) -> إعادة تدريب ميداني خلال 14 يوم ومراجعة مع المشرف
C7: =IFERROR(VLOOKUP(B7,'سجل الموظفين والكفاءة'!B:C,2,FALSE),"") | D7: =IFERROR(VLOOKUP(B7,'سجل الموظفين والكفاءة'!B:E,4,FALSE),"") | H7: =IF(G7="","",IF(G7>='الإعدادات والمستهدفات'!B6,"كفء ومستوفى عملياً","غير كفء - يلزم تدريب ميداني إضافي")) | K7: =IF(G7="","",IF(G7<'الإعدادات والمستهدفات'!B6,I7+14,"—")) | L7: =IF(G7="","",IF(G7<'الإعدادات والمستهدفات'!B6,"إعادة تدريب ميداني خلال 14 يوم ومراجعة مع المشرف","لا يوجد"))
C8: =IFERROR(VLOOKUP(B8,'سجل الموظفين والكفاءة'!B:C,2,FALSE),"") | D8: =IFERROR(VLOOKUP(B8,'سجل الموظفين والكفاءة'!B:E,4,FALSE),"") | H8: =IF(G8="","",IF(G8>='الإعدادات والمستهدفات'!B6,"كفء ومستوفى عملياً","غير كفء - يلزم تدريب ميداني إضافي")) | K8: =IF(G8="","",IF(G8<'الإعدادات والمستهدفات'!B6,I8+14,"—")) | L8: =IF(G8="","",IF(G8<'الإعدادات والمستهدفات'!B6,"إعادة تدريب ميداني خلال 14 يوم ومراجعة مع المشرف","لا يوجد"))
C9: =IFERROR(VLOOKUP(B9,'سجل الموظفين والكفاءة'!B:C,2,FALSE),"") | D9: =IFERROR(VLOOKUP(B9,'سجل الموظفين والكفاءة'!B:E,4,FALSE),"") | H9: =IF(G9="","",IF(G9>='الإعدادات والمستهدفات'!B6,"كفء ومستوفى عملياً","غير كفء - يلزم تدريب ميداني إضافي")) | K9: =IF(G9="","",IF(G9<'الإعدادات والمستهدفات'!B6,I9+14,"—")) | L9: =IF(G9="","",IF(G9<'الإعدادات والمستهدفات'!B6,"إعادة تدريب ميداني خلال 14 يوم ومراجعة مع المشرف","لا يوجد"))
C10: =IFERROR(VLOOKUP(B10,'سجل الموظفين والكفاءة'!B:C,2,FALSE),"") | D10: =IFERROR(VLOOKUP(B10,'سجل الموظفين والكفاءة'!B:E,4,FALSE),"") | H10: =IF(G10="","",IF(G10>='الإعدادات والمستهدفات'!B6,"كفء ومستوفى عملياً","غير كفء - يلزم تدريب ميداني إضافي")) | K10: =IF(G10="","",IF(G10<'الإعدادات والمستهدفات'!B6,I10+14,"—")) | L10: =IF(G10="","",IF(G10<'الإعدادات والمستهدفات'!B6,"إعادة تدريب ميداني خلال 14 يوم ومراجعة مع المشرف","لا يوجد"))
C11: =IFERROR(VLOOKUP(B11,'سجل الموظفين والكفاءة'!B:C,2,FALSE),"") | D11: =IFERROR(VLOOKUP(B11,'سجل الموظفين والكفاءة'!B:E,4,FALSE),"") | H11: =IF(G11="","",IF(G11>='الإعدادات والمستهدفات'!B6,"كفء ومستوفى عملياً","غير كفء - يلزم تدريب ميداني إضافي")) | K11: =IF(G11="","",IF(G11<'الإعدادات والمستهدفات'!B6,I11+14,"—")) | L11: =IF(G11="","",IF(G11<'الإعدادات والمستهدفات'!B6,"إعادة تدريب ميداني خلال 14 يوم ومراجعة مع المشرف","لا يوجد"))
C12: =IFERROR(VLOOKUP(B12,'سجل الموظفين والكفاءة'!B:C,2,FALSE),"") | D12: =IFERROR(VLOOKUP(B12,'سجل الموظفين والكفاءة'!B:E,4,FALSE),"") | H12: =IF(G12="","",IF(G12>='الإعدادات والمستهدفات'!B6,"كفء ومستوفى عملياً","غير كفء - يلزم تدريب ميداني إضافي")) | K12: =IF(G12="","",IF(G12<'الإعدادات والمستهدفات'!B6,I12+14,"—")) | L12: =IF(G12="","",IF(G12<'الإعدادات والمستهدفات'!B6,"إعادة تدريب ميداني خلال 14 يوم ومراجعة مع المشرف","لا يوجد"))
C13: =IFERROR(VLOOKUP(B13,'سجل الموظفين والكفاءة'!B:C,2,FALSE),"") | D13: =IFERROR(VLOOKUP(B13,'سجل الموظفين والكفاءة'!B:E,4,FALSE),"") | H13: =IF(G13="","",IF(G13>='الإعدادات والمستهدفات'!B6,"كفء ومستوفى عملياً","غير كفء - يلزم تدريب ميداني إضافي")) | K13: =IF(G13="","",IF(G13<'الإعدادات والمستهدفات'!B6,I13+14,"—")) | L13: =IF(G13="","",IF(G13<'الإعدادات والمستهدفات'!B6,"إعادة تدريب ميداني خلال 14 يوم ومراجعة مع المشرف","لا يوجد"))
C14: =IFERROR(VLOOKUP(B14,'سجل الموظفين والكفاءة'!B:C,2,FALSE),"") | D14: =IFERROR(VLOOKUP(B14,'سجل الموظفين والكفاءة'!B:E,4,FALSE),"") | H14: =IF(G14="","",IF(G14>='الإعدادات والمستهدفات'!B6,"كفء ومستوفى عملياً","غير كفء - يلزم تدريب ميداني إضافي")) | K14: =IF(G14="","",IF(G14<'الإعدادات والمستهدفات'!B6,I14+14,"—")) | L14: =IF(G14="","",IF(G14<'الإعدادات والمستهدفات'!B6,"إعادة تدريب ميداني خلال 14 يوم ومراجعة مع المشرف","لا يوجد"))
C15: =IFERROR(VLOOKUP(B15,'سجل الموظفين والكفاءة'!B:C,2,FALSE),"") | D15: =IFERROR(VLOOKUP(B15,'سجل الموظفين والكفاءة'!B:E,4,FALSE),"") | H15: =IF(G15="","",IF(G15>='الإعدادات والمستهدفات'!B6,"كفء ومستوفى عملياً","غير كفء - يلزم تدريب ميداني إضافي")) | K15: =IF(G15="","",IF(G15<'الإعدادات والمستهدفات'!B6,I15+14,"—")) | L15: =IF(G15="","",IF(G15<'الإعدادات والمستهدفات'!B6,"إعادة تدريب ميداني خلال 14 يوم ومراجعة مع المشرف","لا يوجد"))
C16: =IFERROR(VLOOKUP(B16,'سجل الموظفين والكفاءة'!B:C,2,FALSE),"") | D16: =IFERROR(VLOOKUP(B16,'سجل الموظفين والكفاءة'!B:E,4,FALSE),"") | H16: =IF(G16="","",IF(G16>='الإعدادات والمستهدفات'!B6,"كفء ومستوفى عملياً","غير كفء - يلزم تدريب ميداني إضافي")) | K16: =IF(G16="","",IF(G16<'الإعدادات والمستهدفات'!B6,I16+14,"—")) | L16: =IF(G16="","",IF(G16<'الإعدادات والمستهدفات'!B6,"إعادة تدريب ميداني خلال 14 يوم ومراجعة مع المشرف","لا يوجد"))
C17: =IFERROR(VLOOKUP(B17,'سجل الموظفين والكفاءة'!B:C,2,FALSE),"") | D17: =IFERROR(VLOOKUP(B17,'سجل الموظفين والكفاءة'!B:E,4,FALSE),"") | H17: =IF(G17="","",IF(G17>='الإعدادات والمستهدفات'!B6,"كفء ومستوفى عملياً","غير كفء - يلزم تدريب ميداني إضافي")) | K17: =IF(G17="","",IF(G17<'الإعدادات والمستهدفات'!B6,I17+14,"—")) | L17: =IF(G17="","",IF(G17<'الإعدادات والمستهدفات'!B6,"إعادة تدريب ميداني خلال 14 يوم ومراجعة مع المشرف","لا يوجد"))
C18: =IFERROR(VLOOKUP(B18,'سجل الموظفين والكفاءة'!B:C,2,FALSE),"") | D18: =IFERROR(VLOOKUP(B18,'سجل الموظفين والكفاءة'!B:E,4,FALSE),"") | H18: =IF(G18="","",IF(G18>='الإعدادات والمستهدفات'!B6,"كفء ومستوفى عملياً","غير كفء - يلزم تدريب ميداني إضافي")) | K18: =IF(G18="","",IF(G18<'الإعدادات والمستهدفات'!B6,I18+14,"—")) | L18: =IF(G18="","",IF(G18<'الإعدادات والمستهدفات'!B6,"إعادة تدريب ميداني خلال 14 يوم ومراجعة مع المشرف","لا يوجد"))
C19: =IFERROR(VLOOKUP(B19,'سجل الموظفين والكفاءة'!B:C,2,FALSE),"") | D19: =IFERROR(VLOOKUP(B19,'سجل الموظفين والكفاءة'!B:E,4,FALSE),"") | H19: =IF(G19="","",IF(G19>='الإعدادات والمستهدفات'!B6,"كفء ومستوفى عملياً","غير كفء - يلزم تدريب ميداني إضافي")) | K19: =IF(G19="","",IF(G19<'الإعدادات والمستهدفات'!B6,I19+14,"—")) | L19: =IF(G19="","",IF(G19<'الإعدادات والمستهدفات'!B6,"إعادة تدريب ميداني خلال 14 يوم ومراجعة مع المشرف","لا يوجد"))
C20: =IFERROR(VLOOKUP(B20,'سجل الموظفين والكفاءة'!B:C,2,FALSE),"") | D20: =IFERROR(VLOOKUP(B20,'سجل الموظفين والكفاءة'!B:E,4,FALSE),"") | H20: =IF(G20="","",IF(G20>='الإعدادات والمستهدفات'!B6,"كفء ومستوفى عملياً","غير كفء - يلزم تدريب ميداني إضافي")) | K20: =IF(G20="","",IF(G20<'الإعدادات والمستهدفات'!B6,I20+14,"—")) | L20: =IF(G20="","",IF(G20<'الإعدادات والمستهدفات'!B6,"إعادة تدريب ميداني خلال 14 يوم ومراجعة مع المشرف","لا يوجد"))
C21: =IFERROR(VLOOKUP(B21,'سجل الموظفين والكفاءة'!B:C,2,FALSE),"") | D21: =IFERROR(VLOOKUP(B21,'سجل الموظفين والكفاءة'!B:E,4,FALSE),"") | H21: =IF(G21="","",IF(G21>='الإعدادات والمستهدفات'!B6,"كفء ومستوفى عملياً","غير كفء - يلزم تدريب ميداني إضافي")) | K21: =IF(G21="","",IF(G21<'الإعدادات والمستهدفات'!B6,I21+14,"—")) | L21: =IF(G21="","",IF(G21<'الإعدادات والمستهدفات'!B6,"إعادة تدريب ميداني خلال 14 يوم ومراجعة مع المشرف","لا يوجد"))
C22: =IFERROR(VLOOKUP(B22,'سجل الموظفين والكفاءة'!B:C,2,FALSE),"") | D22: =IFERROR(VLOOKUP(B22,'سجل الموظفين والكفاءة'!B:E,4,FALSE),"") | H22: =IF(G22="","",IF(G22>='الإعدادات والمستهدفات'!B6,"كفء ومستوفى عملياً","غير كفء - يلزم تدريب ميداني إضافي")) | K22: =IF(G22="","",IF(G22<'الإعدادات والمستهدفات'!B6,I22+14,"—")) | L22: =IF(G22="","",IF(G22<'الإعدادات والمستهدفات'!B6,"إعادة تدريب ميداني خلال 14 يوم ومراجعة مع المشرف","لا يوجد"))
C23: =IFERROR(VLOOKUP(B23,'سجل الموظفين والكفاءة'!B:C,2,FALSE),"") | D23: =IFERROR(VLOOKUP(B23,'سجل الموظفين والكفاءة'!B:E,4,FALSE),"") | H23: =IF(G23="","",IF(G23>='الإعدادات والمستهدفات'!B6,"كفء ومستوفى عملياً","غير كفء - يلزم تدريب ميداني إضافي")) | K23: =IF(G23="","",IF(G23<'الإعدادات والمستهدفات'!B6,I23+14,"—")) | L23: =IF(G23="","",IF(G23<'الإعدادات والمستهدفات'!B6,"إعادة تدريب ميداني خلال 14 يوم ومراجعة مع المشرف","لا يوجد"))
C24: =IFERROR(VLOOKUP(B24,'سجل الموظفين والكفاءة'!B:C,2,FALSE),"") | D24: =IFERROR(VLOOKUP(B24,'سجل الموظفين والكفاءة'!B:E,4,FALSE),"") | H24: =IF(G24="","",IF(G24>='الإعدادات والمستهدفات'!B6,"كفء ومستوفى عملياً","غير كفء - يلزم تدريب ميداني إضافي")) | K24: =IF(G24="","",IF(G24<'الإعدادات والمستهدفات'!B6,I24+14,"—")) | L24: =IF(G24="","",IF(G24<'الإعدادات والمستهدفات'!B6,"إعادة تدريب ميداني خلال 14 يوم ومراجعة مع المشرف","لا يوجد"))
C25: =IFERROR(VLOOKUP(B25,'سجل الموظفين والكفاءة'!B:C,2,FALSE),"") | D25: =IFERROR(VLOOKUP(B25,'سجل الموظفين والكفاءة'!B:E,4,FALSE),"") | H25: =IF(G25="","",IF(G25>='الإعدادات والمستهدفات'!B6,"كفء ومستوفى عملياً","غير كفء - يلزم تدريب ميداني إضافي")) | K25: =IF(G25="","",IF(G25<'الإعدادات والمستهدفات'!B6,I25+14,"—")) | L25: =IF(G25="","",IF(G25<'الإعدادات والمستهدفات'!B6,"إعادة تدريب ميداني خلال 14 يوم ومراجعة مع المشرف","لا يوجد"))
C26: =IFERROR(VLOOKUP(B26,'سجل الموظفين والكفاءة'!B:C,2,FALSE),"") | D26: =IFERROR(VLOOKUP(B26,'سجل الموظفين والكفاءة'!B:E,4,FALSE),"") | H26: =IF(G26="","",IF(G26>='الإعدادات والمستهدفات'!B6,"كفء ومستوفى عملياً","غير كفء - يلزم تدريب ميداني إضافي")) | K26: =IF(G26="","",IF(G26<'الإعدادات والمستهدفات'!B6,I26+14,"—")) | L26: =IF(G26="","",IF(G26<'الإعدادات والمستهدفات'!B6,"إعادة تدريب ميداني خلال 14 يوم ومراجعة مع المشرف","لا يوجد"))
C27: =IFERROR(VLOOKUP(B27,'سجل الموظفين والكفاءة'!B:C,2,FALSE),"") | D27: =IFERROR(VLOOKUP(B27,'سجل الموظفين والكفاءة'!B:E,4,FALSE),"") | H27: =IF(G27="","",IF(G27>='الإعدادات والمستهدفات'!B6,"كفء ومستوفى عملياً","غير كفء - يلزم تدريب ميداني إضافي")) | K27: =IF(G27="","",IF(G27<'الإعدادات والمستهدفات'!B6,I27+14,"—")) | L27: =IF(G27="","",IF(G27<'الإعدادات والمستهدفات'!B6,"إعادة تدريب ميداني خلال 14 يوم ومراجعة مع المشرف","لا يوجد"))
C28: =IFERROR(VLOOKUP(B28,'سجل الموظفين والكفاءة'!B:C,2,FALSE),"") | D28: =IFERROR(VLOOKUP(B28,'سجل الموظفين والكفاءة'!B:E,4,FALSE),"") | H28: =IF(G28="","",IF(G28>='الإعدادات والمستهدفات'!B6,"كفء ومستوفى عملياً","غير كفء - يلزم تدريب ميداني إضافي")) | K28: =IF(G28="","",IF(G28<'الإعدادات والمستهدفات'!B6,I28+14,"—")) | L28: =IF(G28="","",IF(G28<'الإعدادات والمستهدفات'!B6,"إعادة تدريب ميداني خلال 14 يوم ومراجعة مع المشرف","لا يوجد"))
C29: =IFERROR(VLOOKUP(B29,'سجل الموظفين والكفاءة'!B:C,2,FALSE),"") | D29: =IFERROR(VLOOKUP(B29,'سجل الموظفين والكفاءة'!B:E,4,FALSE),"") | H29: =IF(G29="","",IF(G29>='الإعدادات والمستهدفات'!B6,"كفء ومستوفى عملياً","غير كفء - يلزم تدريب ميداني إضافي")) | K29: =IF(G29="","",IF(G29<'الإعدادات والمستهدفات'!B6,I29+14,"—")) | L29: =IF(G29="","",IF(G29<'الإعدادات والمستهدفات'!B6,"إعادة تدريب ميداني خلال 14 يوم ومراجعة مع المشرف","لا يوجد"))
C30: =IFERROR(VLOOKUP(B30,'سجل الموظفين والكفاءة'!B:C,2,FALSE),"") | D30: =IFERROR(VLOOKUP(B30,'سجل الموظفين والكفاءة'!B:E,4,FALSE),"") | H30: =IF(G30="","",IF(G30>='الإعدادات والمستهدفات'!B6,"كفء ومستوفى عملياً","غير كفء - يلزم تدريب ميداني إضافي")) | K30: =IF(G30="","",IF(G30<'الإعدادات والمستهدفات'!B6,I30+14,"—")) | L30: =IF(G30="","",IF(G30<'الإعدادات والمستهدفات'!B6,"إعادة تدريب ميداني خلال 14 يوم ومراجعة مع المشرف","لا يوجد"))
C31: =IFERROR(VLOOKUP(B31,'سجل الموظفين والكفاءة'!B:C,2,FALSE),"") | D31: =IFERROR(VLOOKUP(B31,'سجل الموظفين والكفاءة'!B:E,4,FALSE),"") | H31: =IF(G31="","",IF(G31>='الإعدادات والمستهدفات'!B6,"كفء ومستوفى عملياً","غير كفء - يلزم تدريب ميداني إضافي")) | K31: =IF(G31="","",IF(G31<'الإعدادات والمستهدفات'!B6,I31+14,"—")) | L31: =IF(G31="","",IF(G31<'الإعدادات والمستهدفات'!B6,"إعادة تدريب ميداني خلال 14 يوم ومراجعة مع المشرف","لا يوجد"))
C32: =IFERROR(VLOOKUP(B32,'سجل الموظفين والكفاءة'!B:C,2,FALSE),"") | D32: =IFERROR(VLOOKUP(B32,'سجل الموظفين والكفاءة'!B:E,4,FALSE),"") | H32: =IF(G32="","",IF(G32>='الإعدادات والمستهدفات'!B6,"كفء ومستوفى عملياً","غير كفء - يلزم تدريب ميداني إضافي")) | K32: =IF(G32="","",IF(G32<'الإعدادات والمستهدفات'!B6,I32+14,"—")) | L32: =IF(G32="","",IF(G32<'الإعدادات والمستهدفات'!B6,"إعادة تدريب ميداني خلال 14 يوم ومراجعة مع المشرف","لا يوجد"))
C33: =IFERROR(VLOOKUP(B33,'سجل الموظفين والكفاءة'!B:C,2,FALSE),"") | D33: =IFERROR(VLOOKUP(B33,'سجل الموظفين والكفاءة'!B:E,4,FALSE),"") | H33: =IF(G33="","",IF(G33>='الإعدادات والمستهدفات'!B6,"كفء ومستوفى عملياً","غير كفء - يلزم تدريب ميداني إضافي")) | K33: =IF(G33="","",IF(G33<'الإعدادات والمستهدفات'!B6,I33+14,"—")) | L33: =IF(G33="","",IF(G33<'الإعدادات والمستهدفات'!B6,"إعادة تدريب ميداني خلال 14 يوم ومراجعة مع المشرف","لا يوجد"))
C34: =IFERROR(VLOOKUP(B34,'سجل الموظفين والكفاءة'!B:C,2,FALSE),"") | D34: =IFERROR(VLOOKUP(B34,'سجل الموظفين والكفاءة'!B:E,4,FALSE),"") | H34: =IF(G34="","",IF(G34>='الإعدادات والمستهدفات'!B6,"كفء ومستوفى عملياً","غير كفء - يلزم تدريب ميداني إضافي")) | K34: =IF(G34="","",IF(G34<'الإعدادات والمستهدفات'!B6,I34+14,"—")) | L34: =IF(G34="","",IF(G34<'الإعدادات والمستهدفات'!B6,"إعادة تدريب ميداني خلال 14 يوم ومراجعة مع المشرف","لا يوجد"))
C35: =IFERROR(VLOOKUP(B35,'سجل الموظفين والكفاءة'!B:C,2,FALSE),"") | D35: =IFERROR(VLOOKUP(B35,'سجل الموظفين والكفاءة'!B:E,4,FALSE),"") | H35: =IF(G35="","",IF(G35>='الإعدادات والمستهدفات'!B6,"كفء ومستوفى عملياً","غير كفء - يلزم تدريب ميداني إضافي")) | K35: =IF(G35="","",IF(G35<'الإعدادات والمستهدفات'!B6,I35+14,"—")) | L35: =IF(G35="","",IF(G35<'الإعدادات والمستهدفات'!B6,"إعادة تدريب ميداني خلال 14 يوم ومراجعة مع المشرف","لا يوجد"))
C36: =IFERROR(VLOOKUP(B36,'سجل الموظفين والكفاءة'!B:C,2,FALSE),"") | D36: =IFERROR(VLOOKUP(B36,'سجل الموظفين والكفاءة'!B:E,4,FALSE),"") | H36: =IF(G36="","",IF(G36>='الإعدادات والمستهدفات'!B6,"كفء ومستوفى عملياً","غير كفء - يلزم تدريب ميداني إضافي")) | K36: =IF(G36="","",IF(G36<'الإعدادات والمستهدفات'!B6,I36+14,"—")) | L36: =IF(G36="","",IF(G36<'الإعدادات والمستهدفات'!B6,"إعادة تدريب ميداني خلال 14 يوم ومراجعة مع المشرف","لا يوجد"))
C37: =IFERROR(VLOOKUP(B37,'سجل الموظفين والكفاءة'!B:C,2,FALSE),"") | D37: =IFERROR(VLOOKUP(B37,'سجل الموظفين والكفاءة'!B:E,4,FALSE),"") | H37: =IF(G37="","",IF(G37>='الإعدادات والمستهدفات'!B6,"كفء ومستوفى عملياً","غير كفء - يلزم تدريب ميداني إضافي")) | K37: =IF(G37="","",IF(G37<'الإعدادات والمستهدفات'!B6,I37+14,"—")) | L37: =IF(G37="","",IF(G37<'الإعدادات والمستهدفات'!B6,"إعادة تدريب ميداني خلال 14 يوم ومراجعة مع المشرف","لا يوجد"))
C38: =IFERROR(VLOOKUP(B38,'سجل الموظفين والكفاءة'!B:C,2,FALSE),"") | D38: =IFERROR(VLOOKUP(B38,'سجل الموظفين والكفاءة'!B:E,4,FALSE),"") | H38: =IF(G38="","",IF(G38>='الإعدادات والمستهدفات'!B6,"كفء ومستوفى عملياً","غير كفء - يلزم تدريب ميداني إضافي")) | K38: =IF(G38="","",IF(G38<'الإعدادات والمستهدفات'!B6,I38+14,"—")) | L38: =IF(G38="","",IF(G38<'الإعدادات والمستهدفات'!B6,"إعادة تدريب ميداني خلال 14 يوم ومراجعة مع المشرف","لا يوجد"))
C39: =IFERROR(VLOOKUP(B39,'سجل الموظفين والكفاءة'!B:C,2,FALSE),"") | D39: =IFERROR(VLOOKUP(B39,'سجل الموظفين والكفاءة'!B:E,4,FALSE),"") | H39: =IF(G39="","",IF(G39>='الإعدادات والمستهدفات'!B6,"كفء ومستوفى عملياً","غير كفء - يلزم تدريب ميداني إضافي")) | K39: =IF(G39="","",IF(G39<'الإعدادات والمستهدفات'!B6,I39+14,"—")) | L39: =IF(G39="","",IF(G39<'الإعدادات والمستهدفات'!B6,"إعادة تدريب ميداني خلال 14 يوم ومراجعة مع المشرف","لا يوجد"))
C40: =IFERROR(VLOOKUP(B40,'سجل الموظفين والكفاءة'!B:C,2,FALSE),"") | D40: =IFERROR(VLOOKUP(B40,'سجل الموظفين والكفاءة'!B:E,4,FALSE),"") | H40: =IF(G40="","",IF(G40>='الإعدادات والمستهدفات'!B6,"كفء ومستوفى عملياً","غير كفء - يلزم تدريب ميداني إضافي")) | K40: =IF(G40="","",IF(G40<'الإعدادات والمستهدفات'!B6,I40+14,"—")) | L40: =IF(G40="","",IF(G40<'الإعدادات والمستهدفات'!B6,"إعادة تدريب ميداني خلال 14 يوم ومراجعة مع المشرف","لا يوجد"))
C41: =IFERROR(VLOOKUP(B41,'سجل الموظفين والكفاءة'!B:C,2,FALSE),"") | D41: =IFERROR(VLOOKUP(B41,'سجل الموظفين والكفاءة'!B:E,4,FALSE),"") | H41: =IF(G41="","",IF(G41>='الإعدادات والمستهدفات'!B6,"كفء ومستوفى عملياً","غير كفء - يلزم تدريب ميداني إضافي")) | K41: =IF(G41="","",IF(G41<'الإعدادات والمستهدفات'!B6,I41+14,"—")) | L41: =IF(G41="","",IF(G41<'الإعدادات والمستهدفات'!B6,"إعادة تدريب ميداني خلال 14 يوم ومراجعة مع المشرف","لا يوجد"))
...

Sheet سجل الحضور والتنفيذ
A1: سجل الحضور اليومي والاختبارات - ربط كود الجلسة بكود الموظف
A3: كود البرنامج | B3: كود الجلسة | C3: اسم البرنامج التدريبي | D3: تاريخ الجلسة | E3: كود الموظف | F3: اسم الموظف | G3: ساعات البرنامج | H3: حالة الحضور | I3: الاختبار القبلي (10) | J3: الاختبار البعدي (10) | K3: نسبة التحسن % | L3: نتيجة المعرفة | M3: تقييم المتدرب (5) | N3: ملاحظات المدرب
A4: =IFERROR(VLOOKUP(B4,'جدول الجلسات التدريبية'!A:B,2,FALSE),"") -> PSY-OR-01 | B4: SES-2026-01 | C4: =IFERROR(VLOOKUP(A4,'الخطة التدريبية المعتمدة'!A:C,3,FALSE),"") -> البرنامج التعريفي الشامل للموظفين الجدد (WFM.05) | D4: =IFERROR(VLOOKUP(B4,'جدول الجلسات التدريبية'!A:D,4,FALSE),"") -> 46037 | E4: EMP-110 | F4: =IFERROR(VLOOKUP(E4,'سجل الموظفين والكفاءة'!B:C,2,FALSE),"") -> ياسمين شريف العبد | G4: =IFERROR(VLOOKUP(A4,'الخطة التدريبية المعتمدة'!A:J,10,FALSE),0) -> 6 | H4: حاضر | I4: 4 | J4: 8 | K4: =IF(OR(I4="",J4="",I4=0),"",(J4-I4)/I4) -> 1 | L4: =IF(J4="","",IF(J4/10>='الإعدادات والمستهدفات'!B5,"ناجح ومستوفى","ضعيف - يلزم إعادة اختبار")) -> ناجح ومستوفى | M4: 4
A5: =IFERROR(VLOOKUP(B5,'جدول الجلسات التدريبية'!A:B,2,FALSE),"") -> PSY-01 | B5: SES-2026-02 | C5: =IFERROR(VLOOKUP(A5,'الخطة التدريبية المعتمدة'!A:C,3,FALSE),"") -> تقييم وإدارة مخاطر الانتحار وإيذاء النفس وخطة الأمان | D5: =IFERROR(VLOOKUP(B5,'جدول الجلسات التدريبية'!A:D,4,FALSE),"") -> 46042 | E5: EMP-101 | F5: =IFERROR(VLOOKUP(E5,'سجل الموظفين والكفاءة'!B:C,2,FALSE),"") -> أحمد محمود علي | G5: =IFERROR(VLOOKUP(A5,'الخطة التدريبية المعتمدة'!A:J,10,FALSE),0) -> 4 | H5: حاضر | I5: 5 | J5: 9 | K5: =IF(OR(I5="",J5="",I5=0),"",(J5-I5)/I5) -> 0.8 | L5: =IF(J5="","",IF(J5/10>='الإعدادات والمستهدفات'!B5,"ناجح ومستوفى","ضعيف - يلزم إعادة اختبار")) -> ناجح ومستوفى | M5: 5
A6: =IFERROR(VLOOKUP(B6,'جدول الجلسات التدريبية'!A:B,2,FALSE),"") -> PSY-01 | B6: SES-2026-02 | C6: =IFERROR(VLOOKUP(A6,'الخطة التدريبية المعتمدة'!A:C,3,FALSE),"") -> تقييم وإدارة مخاطر الانتحار وإيذاء النفس وخطة الأمان | D6: =IFERROR(VLOOKUP(B6,'جدول الجلسات التدريبية'!A:D,4,FALSE),"") -> 46042 | E6: EMP-103 | F6: =IFERROR(VLOOKUP(E6,'سجل الموظفين والكفاءة'!B:C,2,FALSE),"") -> محمد حسن عبدالرحمن | G6: =IFERROR(VLOOKUP(A6,'الخطة التدريبية المعتمدة'!A:J,10,FALSE),0) -> 4 | H6: حاضر | I6: 4 | J6: 8 | K6: =IF(OR(I6="",J6="",I6=0),"",(J6-I6)/I6) -> 1 | L6: =IF(J6="","",IF(J6/10>='الإعدادات والمستهدفات'!B5,"ناجح ومستوفى","ضعيف - يلزم إعادة اختبار")) -> ناجح ومستوفى | M6: 5
A7: =IFERROR(VLOOKUP(B7,'جدول الجلسات التدريبية'!A:B,2,FALSE),"") -> PSY-01 | B7: SES-2026-02 | C7: =IFERROR(VLOOKUP(A7,'الخطة التدريبية المعتمدة'!A:C,3,FALSE),"") -> تقييم وإدارة مخاطر الانتحار وإيذاء النفس وخطة الأمان | D7: =IFERROR(VLOOKUP(B7,'جدول الجلسات التدريبية'!A:D,4,FALSE),"") -> 46042 | E7: EMP-104 | F7: =IFERROR(VLOOKUP(E7,'سجل الموظفين والكفاءة'!B:C,2,FALSE),"") -> سارة خالد مصطفى | G7: =IFERROR(VLOOKUP(A7,'الخطة التدريبية المعتمدة'!A:J,10,FALSE),0) -> 4 | H7: حاضر | I7: 3 | J7: 6 | K7: =IF(OR(I7="",J7="",I7=0),"",(J7-I7)/I7) -> 1 | L7: =IF(J7="","",IF(J7/10>='الإعدادات والمستهدفات'!B5,"ناجح ومستوفى","ضعيف - يلزم إعادة اختبار")) -> ضعيف - يلزم إعادة اختبار | M7: 3
A8: =IFERROR(VLOOKUP(B8,'جدول الجلسات التدريبية'!A:B,2,FALSE),"") | C8: =IFERROR(VLOOKUP(A8,'الخطة التدريبية المعتمدة'!A:C,3,FALSE),"") | D8: =IFERROR(VLOOKUP(B8,'جدول الجلسات التدريبية'!A:D,4,FALSE),"") | F8: =IFERROR(VLOOKUP(E8,'سجل الموظفين والكفاءة'!B:C,2,FALSE),"") | G8: =IFERROR(VLOOKUP(A8,'الخطة التدريبية المعتمدة'!A:J,10,FALSE),0) -> 0 | K8: =IF(OR(I8="",J8="",I8=0),"",(J8-I8)/I8) | L8: =IF(J8="","",IF(J8/10>='الإعدادات والمستهدفات'!B5,"ناجح ومستوفى","ضعيف - يلزم إعادة اختبار"))
A9: =IFERROR(VLOOKUP(B9,'جدول الجلسات التدريبية'!A:B,2,FALSE),"") | C9: =IFERROR(VLOOKUP(A9,'الخطة التدريبية المعتمدة'!A:C,3,FALSE),"") | D9: =IFERROR(VLOOKUP(B9,'جدول الجلسات التدريبية'!A:D,4,FALSE),"") | F9: =IFERROR(VLOOKUP(E9,'سجل الموظفين والكفاءة'!B:C,2,FALSE),"") | G9: =IFERROR(VLOOKUP(A9,'الخطة التدريبية المعتمدة'!A:J,10,FALSE),0) -> 0 | K9: =IF(OR(I9="",J9="",I9=0),"",(J9-I9)/I9) | L9: =IF(J9="","",IF(J9/10>='الإعدادات والمستهدفات'!B5,"ناجح ومستوفى","ضعيف - يلزم إعادة اختبار"))
A10: =IFERROR(VLOOKUP(B10,'جدول الجلسات التدريبية'!A:B,2,FALSE),"") | C10: =IFERROR(VLOOKUP(A10,'الخطة التدريبية المعتمدة'!A:C,3,FALSE),"") | D10: =IFERROR(VLOOKUP(B10,'جدول الجلسات التدريبية'!A:D,4,FALSE),"") | F10: =IFERROR(VLOOKUP(E10,'سجل الموظفين والكفاءة'!B:C,2,FALSE),"") | G10: =IFERROR(VLOOKUP(A10,'الخطة التدريبية المعتمدة'!A:J,10,FALSE),0) -> 0 | K10: =IF(OR(I10="",J10="",I10=0),"",(J10-I10)/I10) | L10: =IF(J10="","",IF(J10/10>='الإعدادات والمستهدفات'!B5,"ناجح ومستوفى","ضعيف - يلزم إعادة اختبار"))
A11: =IFERROR(VLOOKUP(B11,'جدول الجلسات التدريبية'!A:B,2,FALSE),"") | C11: =IFERROR(VLOOKUP(A11,'الخطة التدريبية المعتمدة'!A:C,3,FALSE),"") | D11: =IFERROR(VLOOKUP(B11,'جدول الجلسات التدريبية'!A:D,4,FALSE),"") | F11: =IFERROR(VLOOKUP(E11,'سجل الموظفين والكفاءة'!B:C,2,FALSE),"") | G11: =IFERROR(VLOOKUP(A11,'الخطة التدريبية المعتمدة'!A:J,10,FALSE),0) -> 0 | K11: =IF(OR(I11="",J11="",I11=0),"",(J11-I11)/I11) | L11: =IF(J11="","",IF(J11/10>='الإعدادات والمستهدفات'!B5,"ناجح ومستوفى","ضعيف - يلزم إعادة اختبار"))
A12: =IFERROR(VLOOKUP(B12,'جدول الجلسات التدريبية'!A:B,2,FALSE),"") | C12: =IFERROR(VLOOKUP(A12,'الخطة التدريبية المعتمدة'!A:C,3,FALSE),"") | D12: =IFERROR(VLOOKUP(B12,'جدول الجلسات التدريبية'!A:D,4,FALSE),"") | F12: =IFERROR(VLOOKUP(E12,'سجل الموظفين والكفاءة'!B:C,2,FALSE),"") | G12: =IFERROR(VLOOKUP(A12,'الخطة التدريبية المعتمدة'!A:J,10,FALSE),0) -> 0 | K12: =IF(OR(I12="",J12="",I12=0),"",(J12-I12)/I12) | L12: =IF(J12="","",IF(J12/10>='الإعدادات والمستهدفات'!B5,"ناجح ومستوفى","ضعيف - يلزم إعادة اختبار"))
A13: =IFERROR(VLOOKUP(B13,'جدول الجلسات التدريبية'!A:B,2,FALSE),"") | C13: =IFERROR(VLOOKUP(A13,'الخطة التدريبية المعتمدة'!A:C,3,FALSE),"") | D13: =IFERROR(VLOOKUP(B13,'جدول الجلسات التدريبية'!A:D,4,FALSE),"") | F13: =IFERROR(VLOOKUP(E13,'سجل الموظفين والكفاءة'!B:C,2,FALSE),"") | G13: =IFERROR(VLOOKUP(A13,'الخطة التدريبية المعتمدة'!A:J,10,FALSE),0) -> 0 | K13: =IF(OR(I13="",J13="",I13=0),"",(J13-I13)/I13) | L13: =IF(J13="","",IF(J13/10>='الإعدادات والمستهدفات'!B5,"ناجح ومستوفى","ضعيف - يلزم إعادة اختبار"))
A14: =IFERROR(VLOOKUP(B14,'جدول الجلسات التدريبية'!A:B,2,FALSE),"") | C14: =IFERROR(VLOOKUP(A14,'الخطة التدريبية المعتمدة'!A:C,3,FALSE),"") | D14: =IFERROR(VLOOKUP(B14,'جدول الجلسات التدريبية'!A:D,4,FALSE),"") | F14: =IFERROR(VLOOKUP(E14,'سجل الموظفين والكفاءة'!B:C,2,FALSE),"") | G14: =IFERROR(VLOOKUP(A14,'الخطة التدريبية المعتمدة'!A:J,10,FALSE),0) -> 0 | K14: =IF(OR(I14="",J14="",I14=0),"",(J14-I14)/I14) | L14: =IF(J14="","",IF(J14/10>='الإعدادات والمستهدفات'!B5,"ناجح ومستوفى","ضعيف - يلزم إعادة اختبار"))
A15: =IFERROR(VLOOKUP(B15,'جدول الجلسات التدريبية'!A:B,2,FALSE),"") | C15: =IFERROR(VLOOKUP(A15,'الخطة التدريبية المعتمدة'!A:C,3,FALSE),"") | D15: =IFERROR(VLOOKUP(B15,'جدول الجلسات التدريبية'!A:D,4,FALSE),"") | F15: =IFERROR(VLOOKUP(E15,'سجل الموظفين والكفاءة'!B:C,2,FALSE),"") | G15: =IFERROR(VLOOKUP(A15,'الخطة التدريبية المعتمدة'!A:J,10,FALSE),0) -> 0 | K15: =IF(OR(I15="",J15="",I15=0),"",(J15-I15)/I15) | L15: =IF(J15="","",IF(J15/10>='الإعدادات والمستهدفات'!B5,"ناجح ومستوفى","ضعيف - يلزم إعادة اختبار"))
A16: =IFERROR(VLOOKUP(B16,'جدول الجلسات التدريبية'!A:B,2,FALSE),"") | C16: =IFERROR(VLOOKUP(A16,'الخطة التدريبية المعتمدة'!A:C,3,FALSE),"") | D16: =IFERROR(VLOOKUP(B16,'جدول الجلسات التدريبية'!A:D,4,FALSE),"") | F16: =IFERROR(VLOOKUP(E16,'سجل الموظفين والكفاءة'!B:C,2,FALSE),"") | G16: =IFERROR(VLOOKUP(A16,'الخطة التدريبية المعتمدة'!A:J,10,FALSE),0) -> 0 | K16: =IF(OR(I16="",J16="",I16=0),"",(J16-I16)/I16) | L16: =IF(J16="","",IF(J16/10>='الإعدادات والمستهدفات'!B5,"ناجح ومستوفى","ضعيف - يلزم إعادة اختبار"))
A17: =IFERROR(VLOOKUP(B17,'جدول الجلسات التدريبية'!A:B,2,FALSE),"") | C17: =IFERROR(VLOOKUP(A17,'الخطة التدريبية المعتمدة'!A:C,3,FALSE),"") | D17: =IFERROR(VLOOKUP(B17,'جدول الجلسات التدريبية'!A:D,4,FALSE),"") | F17: =IFERROR(VLOOKUP(E17,'سجل الموظفين والكفاءة'!B:C,2,FALSE),"") | G17: =IFERROR(VLOOKUP(A17,'الخطة التدريبية المعتمدة'!A:J,10,FALSE),0) -> 0 | K17: =IF(OR(I17="",J17="",I17=0),"",(J17-I17)/I17) | L17: =IF(J17="","",IF(J17/10>='الإعدادات والمستهدفات'!B5,"ناجح ومستوفى","ضعيف - يلزم إعادة اختبار"))
A18: =IFERROR(VLOOKUP(B18,'جدول الجلسات التدريبية'!A:B,2,FALSE),"") | C18: =IFERROR(VLOOKUP(A18,'الخطة التدريبية المعتمدة'!A:C,3,FALSE),"") | D18: =IFERROR(VLOOKUP(B18,'جدول الجلسات التدريبية'!A:D,4,FALSE),"") | F18: =IFERROR(VLOOKUP(E18,'سجل الموظفين والكفاءة'!B:C,2,FALSE),"") | G18: =IFERROR(VLOOKUP(A18,'الخطة التدريبية المعتمدة'!A:J,10,FALSE),0) -> 0 | K18: =IF(OR(I18="",J18="",I18=0),"",(J18-I18)/I18) | L18: =IF(J18="","",IF(J18/10>='الإعدادات والمستهدفات'!B5,"ناجح ومستوفى","ضعيف - يلزم إعادة اختبار"))
A19: =IFERROR(VLOOKUP(B19,'جدول الجلسات التدريبية'!A:B,2,FALSE),"") | C19: =IFERROR(VLOOKUP(A19,'الخطة التدريبية المعتمدة'!A:C,3,FALSE),"") | D19: =IFERROR(VLOOKUP(B19,'جدول الجلسات التدريبية'!A:D,4,FALSE),"") | F19: =IFERROR(VLOOKUP(E19,'سجل الموظفين والكفاءة'!B:C,2,FALSE),"") | G19: =IFERROR(VLOOKUP(A19,'الخطة التدريبية المعتمدة'!A:J,10,FALSE),0) -> 0 | K19: =IF(OR(I19="",J19="",I19=0),"",(J19-I19)/I19) | L19: =IF(J19="","",IF(J19/10>='الإعدادات والمستهدفات'!B5,"ناجح ومستوفى","ضعيف - يلزم إعادة اختبار"))
A20: =IFERROR(VLOOKUP(B20,'جدول الجلسات التدريبية'!A:B,2,FALSE),"") | C20: =IFERROR(VLOOKUP(A20,'الخطة التدريبية المعتمدة'!A:C,3,FALSE),"") | D20: =IFERROR(VLOOKUP(B20,'جدول الجلسات التدريبية'!A:D,4,FALSE),"") | F20: =IFERROR(VLOOKUP(E20,'سجل الموظفين والكفاءة'!B:C,2,FALSE),"") | G20: =IFERROR(VLOOKUP(A20,'الخطة التدريبية المعتمدة'!A:J,10,FALSE),0) -> 0 | K20: =IF(OR(I20="",J20="",I20=0),"",(J20-I20)/I20) | L20: =IF(J20="","",IF(J20/10>='الإعدادات والمستهدفات'!B5,"ناجح ومستوفى","ضعيف - يلزم إعادة اختبار"))
A21: =IFERROR(VLOOKUP(B21,'جدول الجلسات التدريبية'!A:B,2,FALSE),"") | C21: =IFERROR(VLOOKUP(A21,'الخطة التدريبية المعتمدة'!A:C,3,FALSE),"") | D21: =IFERROR(VLOOKUP(B21,'جدول الجلسات التدريبية'!A:D,4,FALSE),"") | F21: =IFERROR(VLOOKUP(E21,'سجل الموظفين والكفاءة'!B:C,2,FALSE),"") | G21: =IFERROR(VLOOKUP(A21,'الخطة التدريبية المعتمدة'!A:J,10,FALSE),0) -> 0 | K21: =IF(OR(I21="",J21="",I21=0),"",(J21-I21)/I21) | L21: =IF(J21="","",IF(J21/10>='الإعدادات والمستهدفات'!B5,"ناجح ومستوفى","ضعيف - يلزم إعادة اختبار"))
A22: =IFERROR(VLOOKUP(B22,'جدول الجلسات التدريبية'!A:B,2,FALSE),"") | C22: =IFERROR(VLOOKUP(A22,'الخطة التدريبية المعتمدة'!A:C,3,FALSE),"") | D22: =IFERROR(VLOOKUP(B22,'جدول الجلسات التدريبية'!A:D,4,FALSE),"") | F22: =IFERROR(VLOOKUP(E22,'سجل الموظفين والكفاءة'!B:C,2,FALSE),"") | G22: =IFERROR(VLOOKUP(A22,'الخطة التدريبية المعتمدة'!A:J,10,FALSE),0) -> 0 | K22: =IF(OR(I22="",J22="",I22=0),"",(J22-I22)/I22) | L22: =IF(J22="","",IF(J22/10>='الإعدادات والمستهدفات'!B5,"ناجح ومستوفى","ضعيف - يلزم إعادة اختبار"))
A23: =IFERROR(VLOOKUP(B23,'جدول الجلسات التدريبية'!A:B,2,FALSE),"") | C23: =IFERROR(VLOOKUP(A23,'الخطة التدريبية المعتمدة'!A:C,3,FALSE),"") | D23: =IFERROR(VLOOKUP(B23,'جدول الجلسات التدريبية'!A:D,4,FALSE),"") | F23: =IFERROR(VLOOKUP(E23,'سجل الموظفين والكفاءة'!B:C,2,FALSE),"") | G23: =IFERROR(VLOOKUP(A23,'الخطة التدريبية المعتمدة'!A:J,10,FALSE),0) -> 0 | K23: =IF(OR(I23="",J23="",I23=0),"",(J23-I23)/I23) | L23: =IF(J23="","",IF(J23/10>='الإعدادات والمستهدفات'!B5,"ناجح ومستوفى","ضعيف - يلزم إعادة اختبار"))
A24: =IFERROR(VLOOKUP(B24,'جدول الجلسات التدريبية'!A:B,2,FALSE),"") | C24: =IFERROR(VLOOKUP(A24,'الخطة التدريبية المعتمدة'!A:C,3,FALSE),"") | D24: =IFERROR(VLOOKUP(B24,'جدول الجلسات التدريبية'!A:D,4,FALSE),"") | F24: =IFERROR(VLOOKUP(E24,'سجل الموظفين والكفاءة'!B:C,2,FALSE),"") | G24: =IFERROR(VLOOKUP(A24,'الخطة التدريبية المعتمدة'!A:J,10,FALSE),0) -> 0 | K24: =IF(OR(I24="",J24="",I24=0),"",(J24-I24)/I24) | L24: =IF(J24="","",IF(J24/10>='الإعدادات والمستهدفات'!B5,"ناجح ومستوفى","ضعيف - يلزم إعادة اختبار"))
A25: =IFERROR(VLOOKUP(B25,'جدول الجلسات التدريبية'!A:B,2,FALSE),"") | C25: =IFERROR(VLOOKUP(A25,'الخطة التدريبية المعتمدة'!A:C,3,FALSE),"") | D25: =IFERROR(VLOOKUP(B25,'جدول الجلسات التدريبية'!A:D,4,FALSE),"") | F25: =IFERROR(VLOOKUP(E25,'سجل الموظفين والكفاءة'!B:C,2,FALSE),"") | G25: =IFERROR(VLOOKUP(A25,'الخطة التدريبية المعتمدة'!A:J,10,FALSE),0) -> 0 | K25: =IF(OR(I25="",J25="",I25=0),"",(J25-I25)/I25) | L25: =IF(J25="","",IF(J25/10>='الإعدادات والمستهدفات'!B5,"ناجح ومستوفى","ضعيف - يلزم إعادة اختبار"))
A26: =IFERROR(VLOOKUP(B26,'جدول الجلسات التدريبية'!A:B,2,FALSE),"") | C26: =IFERROR(VLOOKUP(A26,'الخطة التدريبية المعتمدة'!A:C,3,FALSE),"") | D26: =IFERROR(VLOOKUP(B26,'جدول الجلسات التدريبية'!A:D,4,FALSE),"") | F26: =IFERROR(VLOOKUP(E26,'سجل الموظفين والكفاءة'!B:C,2,FALSE),"") | G26: =IFERROR(VLOOKUP(A26,'الخطة التدريبية المعتمدة'!A:J,10,FALSE),0) -> 0 | K26: =IF(OR(I26="",J26="",I26=0),"",(J26-I26)/I26) | L26: =IF(J26="","",IF(J26/10>='الإعدادات والمستهدفات'!B5,"ناجح ومستوفى","ضعيف - يلزم إعادة اختبار"))
A27: =IFERROR(VLOOKUP(B27,'جدول الجلسات التدريبية'!A:B,2,FALSE),"") | C27: =IFERROR(VLOOKUP(A27,'الخطة التدريبية المعتمدة'!A:C,3,FALSE),"") | D27: =IFERROR(VLOOKUP(B27,'جدول الجلسات التدريبية'!A:D,4,FALSE),"") | F27: =IFERROR(VLOOKUP(E27,'سجل الموظفين والكفاءة'!B:C,2,FALSE),"") | G27: =IFERROR(VLOOKUP(A27,'الخطة التدريبية المعتمدة'!A:J,10,FALSE),0) -> 0 | K27: =IF(OR(I27="",J27="",I27=0),"",(J27-I27)/I27) | L27: =IF(J27="","",IF(J27/10>='الإعدادات والمستهدفات'!B5,"ناجح ومستوفى","ضعيف - يلزم إعادة اختبار"))
A28: =IFERROR(VLOOKUP(B28,'جدول الجلسات التدريبية'!A:B,2,FALSE),"") | C28: =IFERROR(VLOOKUP(A28,'الخطة التدريبية المعتمدة'!A:C,3,FALSE),"") | D28: =IFERROR(VLOOKUP(B28,'جدول الجلسات التدريبية'!A:D,4,FALSE),"") | F28: =IFERROR(VLOOKUP(E28,'سجل الموظفين والكفاءة'!B:C,2,FALSE),"") | G28: =IFERROR(VLOOKUP(A28,'الخطة التدريبية المعتمدة'!A:J,10,FALSE),0) -> 0 | K28: =IF(OR(I28="",J28="",I28=0),"",(J28-I28)/I28) | L28: =IF(J28="","",IF(J28/10>='الإعدادات والمستهدفات'!B5,"ناجح ومستوفى","ضعيف - يلزم إعادة اختبار"))
A29: =IFERROR(VLOOKUP(B29,'جدول الجلسات التدريبية'!A:B,2,FALSE),"") | C29: =IFERROR(VLOOKUP(A29,'الخطة التدريبية المعتمدة'!A:C,3,FALSE),"") | D29: =IFERROR(VLOOKUP(B29,'جدول الجلسات التدريبية'!A:D,4,FALSE),"") | F29: =IFERROR(VLOOKUP(E29,'سجل الموظفين والكفاءة'!B:C,2,FALSE),"") | G29: =IFERROR(VLOOKUP(A29,'الخطة التدريبية المعتمدة'!A:J,10,FALSE),0) -> 0 | K29: =IF(OR(I29="",J29="",I29=0),"",(J29-I29)/I29) | L29: =IF(J29="","",IF(J29/10>='الإعدادات والمستهدفات'!B5,"ناجح ومستوفى","ضعيف - يلزم إعادة اختبار"))
A30: =IFERROR(VLOOKUP(B30,'جدول الجلسات التدريبية'!A:B,2,FALSE),"") | C30: =IFERROR(VLOOKUP(A30,'الخطة التدريبية المعتمدة'!A:C,3,FALSE),"") | D30: =IFERROR(VLOOKUP(B30,'جدول الجلسات التدريبية'!A:D,4,FALSE),"") | F30: =IFERROR(VLOOKUP(E30,'سجل الموظفين والكفاءة'!B:C,2,FALSE),"") | G30: =IFERROR(VLOOKUP(A30,'الخطة التدريبية المعتمدة'!A:J,10,FALSE),0) -> 0 | K30: =IF(OR(I30="",J30="",I30=0),"",(J30-I30)/I30) | L30: =IF(J30="","",IF(J30/10>='الإعدادات والمستهدفات'!B5,"ناجح ومستوفى","ضعيف - يلزم إعادة اختبار"))
A31: =IFERROR(VLOOKUP(B31,'جدول الجلسات التدريبية'!A:B,2,FALSE),"") | C31: =IFERROR(VLOOKUP(A31,'الخطة التدريبية المعتمدة'!A:C,3,FALSE),"") | D31: =IFERROR(VLOOKUP(B31,'جدول الجلسات التدريبية'!A:D,4,FALSE),"") | F31: =IFERROR(VLOOKUP(E31,'سجل الموظفين والكفاءة'!B:C,2,FALSE),"") | G31: =IFERROR(VLOOKUP(A31,'الخطة التدريبية المعتمدة'!A:J,10,FALSE),0) -> 0 | K31: =IF(OR(I31="",J31="",I31=0),"",(J31-I31)/I31) | L31: =IF(J31="","",IF(J31/10>='الإعدادات والمستهدفات'!B5,"ناجح ومستوفى","ضعيف - يلزم إعادة اختبار"))
A32: =IFERROR(VLOOKUP(B32,'جدول الجلسات التدريبية'!A:B,2,FALSE),"") | C32: =IFERROR(VLOOKUP(A32,'الخطة التدريبية المعتمدة'!A:C,3,FALSE),"") | D32: =IFERROR(VLOOKUP(B32,'جدول الجلسات التدريبية'!A:D,4,FALSE),"") | F32: =IFERROR(VLOOKUP(E32,'سجل الموظفين والكفاءة'!B:C,2,FALSE),"") | G32: =IFERROR(VLOOKUP(A32,'الخطة التدريبية المعتمدة'!A:J,10,FALSE),0) -> 0 | K32: =IF(OR(I32="",J32="",I32=0),"",(J32-I32)/I32) | L32: =IF(J32="","",IF(J32/10>='الإعدادات والمستهدفات'!B5,"ناجح ومستوفى","ضعيف - يلزم إعادة اختبار"))
A33: =IFERROR(VLOOKUP(B33,'جدول الجلسات التدريبية'!A:B,2,FALSE),"") | C33: =IFERROR(VLOOKUP(A33,'الخطة التدريبية المعتمدة'!A:C,3,FALSE),"") | D33: =IFERROR(VLOOKUP(B33,'جدول الجلسات التدريبية'!A:D,4,FALSE),"") | F33: =IFERROR(VLOOKUP(E33,'سجل الموظفين والكفاءة'!B:C,2,FALSE),"") | G33: =IFERROR(VLOOKUP(A33,'الخطة التدريبية المعتمدة'!A:J,10,FALSE),0) -> 0 | K33: =IF(OR(I33="",J33="",I33=0),"",(J33-I33)/I33) | L33: =IF(J33="","",IF(J33/10>='الإعدادات والمستهدفات'!B5,"ناجح ومستوفى","ضعيف - يلزم إعادة اختبار"))
A34: =IFERROR(VLOOKUP(B34,'جدول الجلسات التدريبية'!A:B,2,FALSE),"") | C34: =IFERROR(VLOOKUP(A34,'الخطة التدريبية المعتمدة'!A:C,3,FALSE),"") | D34: =IFERROR(VLOOKUP(B34,'جدول الجلسات التدريبية'!A:D,4,FALSE),"") | F34: =IFERROR(VLOOKUP(E34,'سجل الموظفين والكفاءة'!B:C,2,FALSE),"") | G34: =IFERROR(VLOOKUP(A34,'الخطة التدريبية المعتمدة'!A:J,10,FALSE),0) -> 0 | K34: =IF(OR(I34="",J34="",I34=0),"",(J34-I34)/I34) | L34: =IF(J34="","",IF(J34/10>='الإعدادات والمستهدفات'!B5,"ناجح ومستوفى","ضعيف - يلزم إعادة اختبار"))
A35: =IFERROR(VLOOKUP(B35,'جدول الجلسات التدريبية'!A:B,2,FALSE),"") | C35: =IFERROR(VLOOKUP(A35,'الخطة التدريبية المعتمدة'!A:C,3,FALSE),"") | D35: =IFERROR(VLOOKUP(B35,'جدول الجلسات التدريبية'!A:D,4,FALSE),"") | F35: =IFERROR(VLOOKUP(E35,'سجل الموظفين والكفاءة'!B:C,2,FALSE),"") | G35: =IFERROR(VLOOKUP(A35,'الخطة التدريبية المعتمدة'!A:J,10,FALSE),0) -> 0 | K35: =IF(OR(I35="",J35="",I35=0),"",(J35-I35)/I35) | L35: =IF(J35="","",IF(J35/10>='الإعدادات والمستهدفات'!B5,"ناجح ومستوفى","ضعيف - يلزم إعادة اختبار"))
A36: =IFERROR(VLOOKUP(B36,'جدول الجلسات التدريبية'!A:B,2,FALSE),"") | C36: =IFERROR(VLOOKUP(A36,'الخطة التدريبية المعتمدة'!A:C,3,FALSE),"") | D36: =IFERROR(VLOOKUP(B36,'جدول الجلسات التدريبية'!A:D,4,FALSE),"") | F36: =IFERROR(VLOOKUP(E36,'سجل الموظفين والكفاءة'!B:C,2,FALSE),"") | G36: =IFERROR(VLOOKUP(A36,'الخطة التدريبية المعتمدة'!A:J,10,FALSE),0) -> 0 | K36: =IF(OR(I36="",J36="",I36=0),"",(J36-I36)/I36) | L36: =IF(J36="","",IF(J36/10>='الإعدادات والمستهدفات'!B5,"ناجح ومستوفى","ضعيف - يلزم إعادة اختبار"))
A37: =IFERROR(VLOOKUP(B37,'جدول الجلسات التدريبية'!A:B,2,FALSE),"") | C37: =IFERROR(VLOOKUP(A37,'الخطة التدريبية المعتمدة'!A:C,3,FALSE),"") | D37: =IFERROR(VLOOKUP(B37,'جدول الجلسات التدريبية'!A:D,4,FALSE),"") | F37: =IFERROR(VLOOKUP(E37,'سجل الموظفين والكفاءة'!B:C,2,FALSE),"") | G37: =IFERROR(VLOOKUP(A37,'الخطة التدريبية المعتمدة'!A:J,10,FALSE),0) -> 0 | K37: =IF(OR(I37="",J37="",I37=0),"",(J37-I37)/I37) | L37: =IF(J37="","",IF(J37/10>='الإعدادات والمستهدفات'!B5,"ناجح ومستوفى","ضعيف - يلزم إعادة اختبار"))
A38: =IFERROR(VLOOKUP(B38,'جدول الجلسات التدريبية'!A:B,2,FALSE),"") | C38: =IFERROR(VLOOKUP(A38,'الخطة التدريبية المعتمدة'!A:C,3,FALSE),"") | D38: =IFERROR(VLOOKUP(B38,'جدول الجلسات التدريبية'!A:D,4,FALSE),"") | F38: =IFERROR(VLOOKUP(E38,'سجل الموظفين والكفاءة'!B:C,2,FALSE),"") | G38: =IFERROR(VLOOKUP(A38,'الخطة التدريبية المعتمدة'!A:J,10,FALSE),0) -> 0 | K38: =IF(OR(I38="",J38="",I38=0),"",(J38-I38)/I38) | L38: =IF(J38="","",IF(J38/10>='الإعدادات والمستهدفات'!B5,"ناجح ومستوفى","ضعيف - يلزم إعادة اختبار"))
A39: =IFERROR(VLOOKUP(B39,'جدول الجلسات التدريبية'!A:B,2,FALSE),"") | C39: =IFERROR(VLOOKUP(A39,'الخطة التدريبية المعتمدة'!A:C,3,FALSE),"") | D39: =IFERROR(VLOOKUP(B39,'جدول الجلسات التدريبية'!A:D,4,FALSE),"") | F39: =IFERROR(VLOOKUP(E39,'سجل الموظفين والكفاءة'!B:C,2,FALSE),"") | G39: =IFERROR(VLOOKUP(A39,'الخطة التدريبية المعتمدة'!A:J,10,FALSE),0) -> 0 | K39: =IF(OR(I39="",J39="",I39=0),"",(J39-I39)/I39) | L39: =IF(J39="","",IF(J39/10>='الإعدادات والمستهدفات'!B5,"ناجح ومستوفى","ضعيف - يلزم إعادة اختبار"))
A40: =IFERROR(VLOOKUP(B40,'جدول الجلسات التدريبية'!A:B,2,FALSE),"") | C40: =IFERROR(VLOOKUP(A40,'الخطة التدريبية المعتمدة'!A:C,3,FALSE),"") | D40: =IFERROR(VLOOKUP(B40,'جدول الجلسات التدريبية'!A:D,4,FALSE),"") | F40: =IFERROR(VLOOKUP(E40,'سجل الموظفين والكفاءة'!B:C,2,FALSE),"") | G40: =IFERROR(VLOOKUP(A40,'الخطة التدريبية المعتمدة'!A:J,10,FALSE),0) -> 0 | K40: =IF(OR(I40="",J40="",I40=0),"",(J40-I40)/I40) | L40: =IF(J40="","",IF(J40/10>='الإعدادات والمستهدفات'!B5,"ناجح ومستوفى","ضعيف - يلزم إعادة اختبار"))
A41: =IFERROR(VLOOKUP(B41,'جدول الجلسات التدريبية'!A:B,2,FALSE),"") | C41: =IFERROR(VLOOKUP(A41,'الخطة التدريبية المعتمدة'!A:C,3,FALSE),"") | D41: =IFERROR(VLOOKUP(B41,'جدول الجلسات التدريبية'!A:D,4,FALSE),"") | F41: =IFERROR(VLOOKUP(E41,'سجل الموظفين والكفاءة'!B:C,2,FALSE),"") | G41: =IFERROR(VLOOKUP(A41,'الخطة التدريبية المعتمدة'!A:J,10,FALSE),0) -> 0 | K41: =IF(OR(I41="",J41="",I41=0),"",(J41-I41)/I41) | L41: =IF(J41="","",IF(J41/10>='الإعدادات والمستهدفات'!B5,"ناجح ومستوفى","ضعيف - يلزم إعادة اختبار"))
...

Sheet جدول الجلسات التدريبية
A1: سجل الجلسات المنفذة والمفتوحة - الكود المستقل للجلسة
A3: كود الجلسة | B3: كود البرنامج | C3: اسم البرنامج التدريبي | D3: تاريخ الجلسة | E3: الوقت والمكان | F3: المدرب المسؤول | G3: السعة القسوى | H3: عدد الحضور الفعلي | I3: نسبة الحضور % | J3: حالة الجلسة | K3: ملاحظات التنفيذ
A4: SES-2026-01 | B4: PSY-OR-01 | C4: =IFERROR(VLOOKUP(B4,'الخطة التدريبية المعتمدة'!A:C,3,FALSE),"") -> البرنامج التعريفي الشامل للموظفين الجدد (WFM.05) | D4: 46037 | E4: قاعة التدريب الرئيسية | F4: إدارة الموارد البشرية | G4: 25 | H4: =IF(A4="","",COUNTIFS('[2]سجل الحضور والتنفيذ'!B:B,A4,'[2]سجل الحضور والتنفيذ'!H:H,"حاضر")) -> #VALUE! | I4: =IF(OR(A4="",G4=0),"",H4/G4) -> #VALUE! | J4: منفذة
A5: SES-2026-02 | B5: PSY-01 | C5: =IFERROR(VLOOKUP(B5,'الخطة التدريبية المعتمدة'!A:C,3,FALSE),"") -> تقييم وإدارة مخاطر الانتحار وإيذاء النفس وخطة الأمان | D5: 46042 | E5: قاعة الاجتماعات الإكلينيكية | F5: استشاري الطب النفسي | G5: 20 | H5: =IF(A5="","",COUNTIFS('[2]سجل الحضور والتنفيذ'!B:B,A5,'[2]سجل الحضور والتنفيذ'!H:H,"حاضر")) -> #VALUE! | I5: =IF(OR(A5="",G5=0),"",H5/G5) -> #VALUE! | J5: منفذة
A6: SES-2026-03 | B6: PSY-02 | C6: =IFERROR(VLOOKUP(B6,'الخطة التدريبية المعتمدة'!A:C,3,FALSE),"") -> تقنيات خفض التصعيد والسيطرة الآمنة De-escalation | D6: 46047 | E6: قاعة المحاكاة والميدان | F6: فريق السلامة والتمريض | G6: 25 | H6: =IF(A6="","",COUNTIFS('[2]سجل الحضور والتنفيذ'!B:B,A6,'[2]سجل الحضور والتنفيذ'!H:H,"حاضر")) -> #VALUE! | I6: =IF(OR(A6="",G6=0),"",H6/G6) -> #VALUE! | J6: مجدولة
A7: SES-2026-04 | B7: PSY-03 | C7: =IFERROR(VLOOKUP(B7,'الخطة التدريبية المعتمدة'!A:C,3,FALSE),"") -> سياسات وضوابط التقييد الحركي والعزل الطبقي | D7: 46063 | E7: قسم الإدمان الداخلي | F7: فريق الجودة والتمريض | G7: 20 | H7: =IF(A7="","",COUNTIFS('[2]سجل الحضور والتنفيذ'!B:B,A7,'[2]سجل الحضور والتنفيذ'!H:H,"حاضر")) -> #VALUE! | I7: =IF(OR(A7="",G7=0),"",H7/G7) -> #VALUE! | J7: مجدولة
C8: =IFERROR(VLOOKUP(B8,'الخطة التدريبية المعتمدة'!A:C,3,FALSE),"") | H8: =IF(A8="","",COUNTIFS('[2]سجل الحضور والتنفيذ'!B:B,A8,'[2]سجل الحضور والتنفيذ'!H:H,"حاضر")) | I8: =IF(OR(A8="",G8=0),"",H8/G8)
C9: =IFERROR(VLOOKUP(B9,'الخطة التدريبية المعتمدة'!A:C,3,FALSE),"") | H9: =IF(A9="","",COUNTIFS('[2]سجل الحضور والتنفيذ'!B:B,A9,'[2]سجل الحضور والتنفيذ'!H:H,"حاضر")) | I9: =IF(OR(A9="",G9=0),"",H9/G9)
C10: =IFERROR(VLOOKUP(B10,'الخطة التدريبية المعتمدة'!A:C,3,FALSE),"") | H10: =IF(A10="","",COUNTIFS('[2]سجل الحضور والتنفيذ'!B:B,A10,'[2]سجل الحضور والتنفيذ'!H:H,"حاضر")) | I10: =IF(OR(A10="",G10=0),"",H10/G10)
C11: =IFERROR(VLOOKUP(B11,'الخطة التدريبية المعتمدة'!A:C,3,FALSE),"") | H11: =IF(A11="","",COUNTIFS('[2]سجل الحضور والتنفيذ'!B:B,A11,'[2]سجل الحضور والتنفيذ'!H:H,"حاضر")) | I11: =IF(OR(A11="",G11=0),"",H11/G11)
C12: =IFERROR(VLOOKUP(B12,'الخطة التدريبية المعتمدة'!A:C,3,FALSE),"") | H12: =IF(A12="","",COUNTIFS('[2]سجل الحضور والتنفيذ'!B:B,A12,'[2]سجل الحضور والتنفيذ'!H:H,"حاضر")) | I12: =IF(OR(A12="",G12=0),"",H12/G12)
C13: =IFERROR(VLOOKUP(B13,'الخطة التدريبية المعتمدة'!A:C,3,FALSE),"") | H13: =IF(A13="","",COUNTIFS('[2]سجل الحضور والتنفيذ'!B:B,A13,'[2]سجل الحضور والتنفيذ'!H:H,"حاضر")) | I13: =IF(OR(A13="",G13=0),"",H13/G13)
C14: =IFERROR(VLOOKUP(B14,'الخطة التدريبية المعتمدة'!A:C,3,FALSE),"") | H14: =IF(A14="","",COUNTIFS('[2]سجل الحضور والتنفيذ'!B:B,A14,'[2]سجل الحضور والتنفيذ'!H:H,"حاضر")) | I14: =IF(OR(A14="",G14=0),"",H14/G14)
C15: =IFERROR(VLOOKUP(B15,'الخطة التدريبية المعتمدة'!A:C,3,FALSE),"") | H15: =IF(A15="","",COUNTIFS('[2]سجل الحضور والتنفيذ'!B:B,A15,'[2]سجل الحضور والتنفيذ'!H:H,"حاضر")) | I15: =IF(OR(A15="",G15=0),"",H15/G15)
C16: =IFERROR(VLOOKUP(B16,'الخطة التدريبية المعتمدة'!A:C,3,FALSE),"") | H16: =IF(A16="","",COUNTIFS('[2]سجل الحضور والتنفيذ'!B:B,A16,'[2]سجل الحضور والتنفيذ'!H:H,"حاضر")) | I16: =IF(OR(A16="",G16=0),"",H16/G16)
C17: =IFERROR(VLOOKUP(B17,'الخطة التدريبية المعتمدة'!A:C,3,FALSE),"") | H17: =IF(A17="","",COUNTIFS('[2]سجل الحضور والتنفيذ'!B:B,A17,'[2]سجل الحضور والتنفيذ'!H:H,"حاضر")) | I17: =IF(OR(A17="",G17=0),"",H17/G17)
C18: =IFERROR(VLOOKUP(B18,'الخطة التدريبية المعتمدة'!A:C,3,FALSE),"") | H18: =IF(A18="","",COUNTIFS('[2]سجل الحضور والتنفيذ'!B:B,A18,'[2]سجل الحضور والتنفيذ'!H:H,"حاضر")) | I18: =IF(OR(A18="",G18=0),"",H18/G18)
C19: =IFERROR(VLOOKUP(B19,'الخطة التدريبية المعتمدة'!A:C,3,FALSE),"") | H19: =IF(A19="","",COUNTIFS('[2]سجل الحضور والتنفيذ'!B:B,A19,'[2]سجل الحضور والتنفيذ'!H:H,"حاضر")) | I19: =IF(OR(A19="",G19=0),"",H19/G19)
... C203: =IFERROR(VLOOKUP(B203,'الخطة التدريبية المعتمدة'!A:C,3,FALSE),"") | H203: =IF(A203="","",COUNTIFS('[2]سجل الحضور والتنفيذ'!B:B,A203,'[2]سجل الحضور والتنفيذ'!H:H,"حاضر")) | I203: =IF(OR(A203="",G203=0),"",H203/G203)

Sheet الخطة التدريبية المعتمدة
A1: الخطة السنوية المعتمدة للتدريب والتأهيل - مستشفى صحة نفسية وعلاج إدمان 2026
A3: كود البرنامج | B3: المحور الرئيسي (GAHAR) | C3: اسم البرنامج التدريبي التخصصي | D3: الهدف القابل للقياس | E3: الفئة المستهدفة | F3: عدد المستهدفين | G3: نوع التدريب | H3: أسلوب التقييم | I3: المدرب / الجهة | J3: الساعات | K3: التكرار | L3: الشهر المخطط | M3: حالة الخطة | N3: عدد الجلسات المخططة | O3: إجمالي الساعات المخططة | P3: سجلات الحضور الفعلية | Q3: نسبة التغطية % | R3: حالة الاستيفاء
A4: PSY-01 | B4: 1. الرعاية النفسية والإدمان المتخصصة | C4: تقييم وإدارة مخاطر الانتحار وإيذاء النفس وخطة الأمان | D4: إتقان نموذج C-SSRS ووضع خطة أمان بنسبة 100% | E4: أطباء وتمريض وأخصائيون | F4: =IF(A4="","",IF(E4="جميع العاملين بالمنشأة",COUNTIF('سجل الموظفين والكفاءة'!G:G,"موظف قائم")+COUNTIF('سجل الموظفين والكفاءة'!G:G,"موظف جديد " & 'الإعدادات والمستهدفات'!B4),COUNTIF('سجل الموظفين والكفاءة'!E:E,E4))) -> 0 | G4: ورشة عمل ومحاكاة | H4: اختبار وتطبيق عملي | I4: استشاري الطب النفسي | J4: 4 | K4: نصف سنوي | L4: يناير | M4: مخطط | N4: =IF(A4="","",ROUNDUP(F4/'الإعدادات والمستهدفات'!B12,0)) -> 0 | O4: =IF(A4="","",F4*J4) -> 0 | P4: =IF(A4="","",COUNTIFS('[2]سجل الحضور والتنفيذ'!A:A,A4,'[2]سجل الحضور والتنفيذ'!H:H,"حاضر")) -> #VALUE! | Q4: =IF(OR(A4="",F4=0),"",P4/F4) | R4: =IF(A4="","",IF(F4=0,"لا ينطبق",IF(P4=0,"لم يبدأ",IF(Q4>='الإعدادات والمستهدفات'!B7,"مستوفى بالكامل","قيد الاستيفاء")))) -> لا ينطبق
A5: PSY-02 | B5: 1. الرعاية النفسية والإدمان المتخصصة | C5: تقنيات خفض التصعيد والسيطرة الآمنة De-escalation | D5: خفض إصابات الهياج بنسبة 50% وتطبيق السيطرة آمنًا | E5: تمريض وأمن وأطباء | F5: =IF(A5="","",IF(E5="جميع العاملين بالمنشأة",COUNTIF('سجل الموظفين والكفاءة'!G:G,"موظف قائم")+COUNTIF('سجل الموظفين والكفاءة'!G:G,"موظف جديد " & 'الإعدادات والمستهدفات'!B4),COUNTIF('سجل الموظفين والكفاءة'!E:E,E5))) -> 0 | G5: تدريب عملي ميداني | H5: ملاحظة مهارية | I5: فريق السلامة والتمريض | J5: 4 | K5: ربع سنوي | L5: يناير | M5: مخطط | N5: =IF(A5="","",ROUNDUP(F5/'الإعدادات والمستهدفات'!B12,0)) -> 0 | O5: =IF(A5="","",F5*J5) -> 0 | P5: =IF(A5="","",COUNTIFS('[2]سجل الحضور والتنفيذ'!A:A,A5,'[2]سجل الحضور والتنفيذ'!H:H,"حاضر")) -> #VALUE! | Q5: =IF(OR(A5="",F5=0),"",P5/F5) | R5: =IF(A5="","",IF(F5=0,"لا ينطبق",IF(P5=0,"لم يبدأ",IF(Q5>='الإعدادات والمستهدفات'!B7,"مستوفى بالكامل","قيد الاستيفاء")))) -> لا ينطبق
A6: PSY-03 | B6: 1. الرعاية النفسية والإدمان المتخصصة | C6: سياسات وضوابط التقييد الحركي والعزل الطبقي | D6: التطبيق المعتمد 100% للتقييد والتسلّم والتوثيق | E6: تمريض وأطباء قسم الإدمان | F6: =IF(A6="","",IF(E6="جميع العاملين بالمنشأة",COUNTIF('سجل الموظفين والكفاءة'!G:G,"موظف قائم")+COUNTIF('سجل الموظفين والكفاءة'!G:G,"موظف جديد " & 'الإعدادات والمستهدفات'!B4),COUNTIF('سجل الموظفين والكفاءة'!E:E,E6))) -> 0 | G6: محاكاة سيناريو | H6: تقييم نموذج التوثيق | I6: فريق الجودة والتمريض | J6: 3 | K6: نصف سنوي | L6: فبراير | M6: مخطط | N6: =IF(A6="","",ROUNDUP(F6/'الإعدادات والمستهدفات'!B12,0)) -> 0 | O6: =IF(A6="","",F6*J6) -> 0 | P6: =IF(A6="","",COUNTIFS('[2]سجل الحضور والتنفيذ'!A:A,A6,'[2]سجل الحضور والتنفيذ'!H:H,"حاضر")) -> #VALUE! | Q6: =IF(OR(A6="",F6=0),"",P6/F6) | R6: =IF(A6="","",IF(F6=0,"لا ينطبق",IF(P6=0,"لم يبدأ",IF(Q6>='الإعدادات والمستهدفات'!B7,"مستوفى بالكامل","قيد الاستيفاء")))) -> لا ينطبق
A7: PSY-04 | B7: 1. الرعاية النفسية والإدمان المتخصصة | C7: إدارة الأدوية النفسية عالية الخطورة ورصد الأعراض الجانبية | D7: رخص التعامل والجرعات والرصد المبكر للسمية | E7: أطباء وتمريض وصيدلة | F7: =IF(A7="","",IF(E7="جميع العاملين بالمنشأة",COUNTIF('سجل الموظفين والكفاءة'!G:G,"موظف قائم")+COUNTIF('سجل الموظفين والكفاءة'!G:G,"موظف جديد " & 'الإعدادات والمستهدفات'!B4),COUNTIF('سجل الموظفين والكفاءة'!E:E,E7))) -> 0 | G7: محاضرة واختبار حالات | H7: اختبار تحصيلي | I7: الصيدلي الأول والإكلينيكي | J7: 3 | K7: سنوي | L7: فبراير | M7: مخطط | N7: =IF(A7="","",ROUNDUP(F7/'الإعدادات والمستهدفات'!B12,0)) -> 0 | O7: =IF(A7="","",F7*J7) -> 0 | P7: =IF(A7="","",COUNTIFS('[2]سجل الحضور والتنفيذ'!A:A,A7,'[2]سجل الحضور والتنفيذ'!H:H,"حاضر")) -> #VALUE! | Q7: =IF(OR(A7="",F7=0),"",P7/F7) | R7: =IF(A7="","",IF(F7=0,"لا ينطبق",IF(P7=0,"لم يبدأ",IF(Q7>='الإعدادات والمستهدفات'!B7,"مستوفى بالكامل","قيد الاستيفاء")))) -> لا ينطبق
A8: PSY-05 | B8: 1. الرعاية النفسية والإدمان المتخصصة | C8: طوارئ علاج الإدمان: أعراض الانسحاب، الجرعات الزائدة والتسمم | D8: الاستجابة الفورية لأزمات التسمم والانسحاب الحاد | E8: أطباء وتمريض طوارئ إدمان | F8: =IF(A8="","",IF(E8="جميع العاملين بالمنشأة",COUNTIF('سجل الموظفين والكفاءة'!G:G,"موظف قائم")+COUNTIF('سجل الموظفين والكفاءة'!G:G,"موظف جديد " & 'الإعدادات والمستهدفات'!B4),COUNTIF('سجل الموظفين والكفاءة'!E:E,E8))) -> 0 | G8: سيناريو طوارئ حقيقي | H8: تقييم أداء الطوارئ | I8: رئيس قسم علاج الإدمان | J8: 4 | K8: نصف سنوي | L8: مارس | M8: مخطط | N8: =IF(A8="","",ROUNDUP(F8/'الإعدادات والمستهدفات'!B12,0)) -> 0 | O8: =IF(A8="","",F8*J8) -> 0 | P8: =IF(A8="","",COUNTIFS('[2]سجل الحضور والتنفيذ'!A:A,A8,'[2]سجل الحضور والتنفيذ'!H:H,"حاضر")) -> #VALUE! | Q8: =IF(OR(A8="",F8=0),"",P8/F8) | R8: =IF(A8="","",IF(F8=0,"لا ينطبق",IF(P8=0,"لم يبدأ",IF(Q8>='الإعدادات والمستهدفات'!B7,"مستوفى بالكامل","قيد الاستيفاء")))) -> لا ينطبق
A9: PSY-06 | B9: 1. الرعاية النفسية والإدمان المتخصصة | C9: التقييم النفسي الأولي وصياغة خطة العلاج الفردية | D9: توثيق خطة علاجية تكاملية لكل مريض خلال 24 ساعة | E9: أطباء وأخصائيون نفسيون | F9: =IF(A9="","",IF(E9="جميع العاملين بالمنشأة",COUNTIF('سجل الموظفين والكفاءة'!G:G,"موظف قائم")+COUNTIF('سجل الموظفين والكفاءة'!G:G,"موظف جديد " & 'الإعدادات والمستهدفات'!B4),COUNTIF('سجل الموظفين والكفاءة'!E:E,E9))) -> 0 | G9: ورشة مراجعة ملفات | H9: تدقيق ملفات مرجعي | I9: المدير الطبي | J9: 3 | K9: سنوي | L9: مارس | M9: مخطط | N9: =IF(A9="","",ROUNDUP(F9/'الإعدادات والمستهدفات'!B12,0)) -> 0 | O9: =IF(A9="","",F9*J9) -> 0 | P9: =IF(A9="","",COUNTIFS('[2]سجل الحضور والتنفيذ'!A:A,A9,'[2]سجل الحضور والتنفيذ'!H:H,"حاضر")) -> #VALUE! | Q9: =IF(OR(A9="",F9=0),"",P9/F9) | R9: =IF(A9="","",IF(F9=0,"لا ينطبق",IF(P9=0,"لم يبدأ",IF(Q9>='الإعدادات والمستهدفات'!B7,"مستوفى بالكامل","قيد الاستيفاء")))) -> لا ينطبق
A10: PSY-07 | B10: 1. الرعاية النفسية والإدمان المتخصصة | C10: الشرعة الاخلاقية وحقوق المريض النفسي وتقليل الوصمة | D10: صفر شكاوى حول خرق خصوصية أو معاملة حاطة | E10: جميع العاملين بالمنشأة | F10: =IF(A10="","",IF(E10="جميع العاملين بالمنشأة",COUNTIF('سجل الموظفين والكفاءة'!G:G,"موظف قائم")+COUNTIF('سجل الموظفين والكفاءة'!G:G,"موظف جديد " & 'الإعدادات والمستهدفات'!B4),COUNTIF('سجل الموظفين والكفاءة'!E:E,E10))) -> 10 | G10: تفاعلي ولعب أدوار | H10: استبيان واختبار | I10: مسؤول حقوق المرضى | J10: 2 | K10: سنوي | L10: أبريل | M10: مخطط | N10: =IF(A10="","",ROUNDUP(F10/'الإعدادات والمستهدفات'!B12,0)) -> 1 | O10: =IF(A10="","",F10*J10) -> 20 | P10: =IF(A10="","",COUNTIFS('[2]سجل الحضور والتنفيذ'!A:A,A10,'[2]سجل الحضور والتنفيذ'!H:H,"حاضر")) -> #VALUE! | Q10: =IF(OR(A10="",F10=0),"",P10/F10) -> #VALUE! | R10: =IF(A10="","",IF(F10=0,"لا ينطبق",IF(P10=0,"لم يبدأ",IF(Q10>='الإعدادات والمستهدفات'!B7,"مستوفى بالكامل","قيد الاستيفاء")))) -> #VALUE!
A11: PSY-08 | B11: 1. الرعاية النفسية والإدمان المتخصصة | C11: حماية المرضى النفسيين من الإساءة والإهمال والاستغلال | D11: الإبلاغ الفوري عن أي شبهة إساءة وحماية المريض | E11: جميع العاملين بالمنشأة | F11: =IF(A11="","",IF(E11="جميع العاملين بالمنشأة",COUNTIF('سجل الموظفين والكفاءة'!G:G,"موظف قائم")+COUNTIF('سجل الموظفين والكفاءة'!G:G,"موظف جديد " & 'الإعدادات والمستهدفات'!B4),COUNTIF('سجل الموظفين والكفاءة'!E:E,E11))) -> 10 | G11: توعوي وتطبيقي | H11: اختبار حالات | I11: مسؤول الحوكمة والجودة | J11: 2 | K11: سنوي | L11: أبريل | M11: مخطط | N11: =IF(A11="","",ROUNDUP(F11/'الإعدادات والمستهدفات'!B12,0)) -> 1 | O11: =IF(A11="","",F11*J11) -> 20 | P11: =IF(A11="","",COUNTIFS('[2]سجل الحضور والتنفيذ'!A:A,A11,'[2]سجل الحضور والتنفيذ'!H:H,"حاضر")) -> #VALUE! | Q11: =IF(OR(A11="",F11=0),"",P11/F11) -> #VALUE! | R11: =IF(A11="","",IF(F11=0,"لا ينطبق",IF(P11=0,"لم يبدأ",IF(Q11>='الإعدادات والمستهدفات'!B7,"مستوفى بالكامل","قيد الاستيفاء")))) -> #VALUE!
A12: PSY-09 | B12: 1. الرعاية النفسية والإدمان المتخصصة | C12: إدارة الرعاية المزدوجة: اضطرابات النفسية المرافقة للإدمان | D12: رفع كفاءة تشخيص وعلاج الاضطراب المزدوج | E12: أطباء وأخصائيون نفسيون | F12: =IF(A12="","",IF(E12="جميع العاملين بالمنشأة",COUNTIF('سجل الموظفين والكفاءة'!G:G,"موظف قائم")+COUNTIF('سجل الموظفين والكفاءة'!G:G,"موظف جديد " & 'الإعدادات والمستهدفات'!B4),COUNTIF('سجل الموظفين والكفاءة'!E:E,E12))) -> 0 | G12: حلقة نقاش إكلينيكية | H12: تقييم حالة معقدة | I12: استشاري الطب النفسي | J12: 3 | K12: سنوي | L12: مايو | M12: مخطط | N12: =IF(A12="","",ROUNDUP(F12/'الإعدادات والمستهدفات'!B12,0)) -> 0 | O12: =IF(A12="","",F12*J12) -> 0 | P12: =IF(A12="","",COUNTIFS('[2]سجل الحضور والتنفيذ'!A:A,A12,'[2]سجل الحضور والتنفيذ'!H:H,"حاضر")) -> #VALUE! | Q12: =IF(OR(A12="",F12=0),"",P12/F12) | R12: =IF(A12="","",IF(F12=0,"لا ينطبق",IF(P12=0,"لم يبدأ",IF(Q12>='الإعدادات والمستهدفات'!B7,"مستوفى بالكامل","قيد الاستيفاء")))) -> لا ينطبق
A13: PSY-10 | B13: 1. الرعاية النفسية والإدمان المتخصصة | C13: البروتوكول الآمن لمنع هروب المرضى وتتبع عالي الخطر | D13: منع حالات الهروب والاستجابة الفورية لخطة البحث | E13: تمريض وأمن واستقبال | F13: =IF(A13="","",IF(E13="جميع العاملين بالمنشأة",COUNTIF('سجل الموظفين والكفاءة'!G:G,"موظف قائم")+COUNTIF('سجل الموظفين والكفاءة'!G:G,"موظف جديد " & 'الإعدادات والمستهدفات'!B4),COUNTIF('سجل الموظفين والكفاءة'!E:E,E13))) -> 0 | G13: تمرين عملي مفاجئ | H13: تقييم زمن الاستجابة | I13: مشرف الأمن والتمريض | J13: 3 | K13: نصف سنوي | L13: مايو | M13: مخطط | N13: =IF(A13="","",ROUNDUP(F13/'الإعدادات والمستهدفات'!B12,0)) -> 0 | O13: =IF(A13="","",F13*J13) -> 0 | P13: =IF(A13="","",COUNTIFS('[2]سجل الحضور والتنفيذ'!A:A,A13,'[2]سجل الحضور والتنفيذ'!H:H,"حاضر")) -> #VALUE! | Q13: =IF(OR(A13="",F13=0),"",P13/F13) | R13: =IF(A13="","",IF(F13=0,"لا ينطبق",IF(P13=0,"لم يبدأ",IF(Q13>='الإعدادات والمستهدفات'!B7,"مستوفى بالكامل","قيد الاستيفاء")))) -> لا ينطبق
A14: PSY-11 | B14: 1. الرعاية النفسية والإدمان المتخصصة | C14: المقابلة التحفيزية Motivational Interviewing في الإدمان | D14: رفع التزام المرضى ببرنامج التعافي لمنع الانتكاس | E14: أخصائيون وتمريض وأطباء | F14: =IF(A14="","",IF(E14="جميع العاملين بالمنشأة",COUNTIF('سجل الموظفين والكفاءة'!G:G,"موظف قائم")+COUNTIF('سجل الموظفين والكفاءة'!G:G,"موظف جديد " & 'الإعدادات والمستهدفات'!B4),COUNTIF('سجل الموظفين والكفاءة'!E:E,E14))) -> 0 | G14: تدريب تطبيقي مكثف | H14: تقييم تسجيل جلسة | I14: استشاري علاج الإدمان | J14: 4 | K14: سنوي | L14: يونيو | M14: مخطط | N14: =IF(A14="","",ROUNDUP(F14/'الإعدادات والمستهدفات'!B12,0)) -> 0 | O14: =IF(A14="","",F14*J14) -> 0 | P14: =IF(A14="","",COUNTIFS('[2]سجل الحضور والتنفيذ'!A:A,A14,'[2]سجل الحضور والتنفيذ'!H:H,"حاضر")) -> #VALUE! | Q14: =IF(OR(A14="",F14=0),"",P14/F14) | R14: =IF(A14="","",IF(F14=0,"لا ينطبق",IF(P14=0,"لم يبدأ",IF(Q14>='الإعدادات والمستهدفات'!B7,"مستوفى بالكامل","قيد الاستيفاء")))) -> لا ينطبق
A15: PSY-12 | B15: 1. الرعاية النفسية والإدمان المتخصصة | C15: العلاج المعرفي السلوكي CBT لاضطرابات القلق والإدمان | D15: تطبيق الفنيات الأساسية بمهارة معتمدة | E15: أخصائيون نفسيون ورعاة | F15: =IF(A15="","",IF(E15="جميع العاملين بالمنشأة",COUNTIF('سجل الموظفين والكفاءة'!G:G,"موظف قائم")+COUNTIF('سجل الموظفين والكفاءة'!G:G,"موظف جديد " & 'الإعدادات والمستهدفات'!B4),COUNTIF('سجل الموظفين والكفاءة'!E:E,E15))) -> 0 | G15: ورشة عمل تخصصية | H15: تقديم حالة علاجية | I15: خبير CBT معتمد | J15: 4 | K15: سنوي | L15: يوليو | M15: مخطط | N15: =IF(A15="","",ROUNDUP(F15/'الإعدادات والمستهدفات'!B12,0)) -> 0 | O15: =IF(A15="","",F15*J15) -> 0 | P15: =IF(A15="","",COUNTIFS('[2]سجل الحضور والتنفيذ'!A:A,A15,'[2]سجل الحضور والتنفيذ'!H:H,"حاضر")) -> #VALUE! | Q15: =IF(OR(A15="",F15=0),"",P15/F15) | R15: =IF(A15="","",IF(F15=0,"لا ينطبق",IF(P15=0,"لم يبدأ",IF(Q15>='الإعدادات والمستهدفات'!B7,"مستوفى بالكامل","قيد الاستيفاء")))) -> لا ينطبق
A16: PSY-13 | B16: 1. الرعاية النفسية والإدمان المتخصصة | C16: التسليم السريري المنظم SBAR والتواصل في الأزمات | D16: دقة تسليم الشفتات وتقليل أخطاء التواصل بنسبة 100% | E16: أطباء وتمريض | F16: =IF(A16="","",IF(E16="جميع العاملين بالمنشأة",COUNTIF('سجل الموظفين والكفاءة'!G:G,"موظف قائم")+COUNTIF('سجل الموظفين والكفاءة'!G:G,"موظف جديد " & 'الإعدادات والمستهدفات'!B4),COUNTIF('سجل الموظفين والكفاءة'!E:E,E16))) -> 0 | G16: محاكاة تسليم شفت | H16: قائمة مراجعة SBAR | I16: رئيس التمريض | J16: 2 | K16: سنوي | L16: أغسطس | M16: مخطط | N16: =IF(A16="","",ROUNDUP(F16/'الإعدادات والمستهدفات'!B12,0)) -> 0 | O16: =IF(A16="","",F16*J16) -> 0 | P16: =IF(A16="","",COUNTIFS('[2]سجل الحضور والتنفيذ'!A:A,A16,'[2]سجل الحضور والتنفيذ'!H:H,"حاضر")) -> #VALUE! | Q16: =IF(OR(A16="",F16=0),"",P16/F16) | R16: =IF(A16="","",IF(F16=0,"لا ينطبق",IF(P16=0,"لم يبدأ",IF(Q16>='الإعدادات والمستهدفات'!B7,"مستوفى بالكامل","قيد الاستيفاء")))) -> لا ينطبق
